Workbook

Sheet Dynamic Comparison
B2: All Equity Scenario | E2: LTV >0 Scenario (update assumptions as needed)
B4: LP Tusten | E4: LP Tusten
B5: Total Cash Outlay: | C5: ='Summary (All Equity)'!D33+SUM('Summary (All Equity)'!E34:H34) -> -14840000 | E5: Total Cash Outlay: | F5: =SUM('Summary (50% Equity)'!D37:H37) -> -14840000
B6: Total Cash Inflow: | C6: =SUM('Summary (All Equity)'!E35:O35) -> 39913660 | E6: Total Cash Inflow: | F6: =SUM('Summary (50% Equity)'!E41:O41) -> 32657836
B7: IRR: | C7: ='Summary (All Equity)'!D41 -> 0.34229387 | E7: IRR: | F7: ='Summary (50% Equity)'!D48 -> 0.29221804
B8: Payback: | C8: ='Summary (All Equity)'!D40 -> 2.102096 | E8: Payback: | F8: ='Summary (50% Equity)'!D49 -> 2.1100931
B9: MOIC: | C9: ='Summary (All Equity)'!D42 -> 2.6895997 | E9: MOIC: | F9: ='Summary (50% Equity)'!D50 -> 2.2006628
B11: GP Processing | E11: GP Processing
B12: ='Summary (All Equity)'!C45 -> Equity Distribution: | C12: ='Summary (All Equity)'!D45 -> 8003511.6 | E12: ='Summary (50% Equity)'!C53 -> Equity Distribution: | F12: ='Summary (50% Equity)'!D53 -> 15259335
B13: ='Summary (All Equity)'!C46 -> Management Fee: | C13: ='Summary (All Equity)'!D46 -> 0 | E13: ='Summary (50% Equity)'!C54 -> Management Fee: | F13: ='Summary (50% Equity)'!D54 -> 0
B14: ='Summary (All Equity)'!C47 -> Total Cash Flow: | C14: ='Summary (All Equity)'!D47 -> 8003511.6 | E14: ='Summary (50% Equity)'!C55 -> Total Cash Flow: | F14: ='Summary (50% Equity)'!D55 -> 15259335

Sheet Static Scenarios
C1: None | D1: 6 Months | E1: 12 Months | F1: 24 Months | G1: 36 Months | I1: All scenarios based on the following data:
A2: Deferred Purchase Price:
A3: 6 Months | C3: 0.0101 | D3: 0.0099 | E3: 0.0099 | F3: 0.0099 | G3: 0.0099 | I3: Initial Multiple | J3: 22
A4: 12 Months | C4: 0.0101 | D4: 0.0101 | E4: 0.0099 | F4: 0.0099 | G4: 0.0099 | I4: 6 Months | J4: 8
A5: 24 Months | C5: 0.0101 | D5: 0.0101 | E5: 0.0101 | F5: 0.0099 | G5: 0.0099 | I5: 12 Months | J5: 8
A6: 36 Months | C6: 0.0101 | D6: 0.0101 | E6: 0.0101 | F6: 0.0101 | G6: 0.0099 | I6: 24 Months | J6: 6
A7: After 36th Month | C7: 0.0101 | D7: 0.0101 | E7: 0.0101 | F7: 0.0101 | G7: 0.0101 | I7: Sales Multiple | J7: 6
A9: All Equity Scenario | C9: Best
A10: Total Cash Outlay: | C10: -14840000 | D10: -20200000 | E10: -25560000 | F10: -29580000 | G10: -32260000 | I10: Distribution:
A11: Total Cash Inflow: | C11: 39913660 | D11: 41359701 | E11: 43023181 | F11: 44205938 | G11: 45017753 | I11: Shareholder #1 (Tusten) | K11: =100%-K12 -> 0.75
A12: IRR: | C12: 0.34229387 | D12: 0.24030307 | E12: 0.17810774 | F12: 0.14234714 | G12: 0.12252099 | I12: Shareholder #2 (Processing) | K12: 0.25
A13: Payback: | C13: 2.102096 | D13: 2.9821198 | E13: 3.9860095 | F13: 4.8327062 | G13: 5.446959
A14: MOIC: | C14: 2.6895997 | D14: 2.4258559 | E14: 2.1767642 | F14: 1.9855753 | G14: 1.8596869
A16: 80% Equity Scenario (LTV-20%)
A17: Total Cash Outlay: | C17: -14840000 | D17: -19128000 | E17: -24488000 | F17: -28508000 | G17: -31188000
A18: Total Cash Inflow: | C18: 27092440 | D18: 28230677 | E18: 29388902 | F18: 30257950 | G18: 30842332 | I18: Distribution:
A19: IRR: | C19: 0.18242237 | D19: 0.11879947 | E19: 0.058068197 | F19: 0.019952923 | G19: -0.0039189083 | I19: Shareholder #1 (Tusten) | K19: =100%-K20 -> 0.5
A20: Payback: | C20: 3.5882918 | D20: 4.8828308 | E20: 7.0237209 | F20: 9.1019934 | I20: Shareholder #2 (Processing) | K20: 0.5
A21: MOIC: | C21: 1.8256361 | D21: 1.6133879 | E21: 1.4024867 | F21: 1.2443362 | G21: 1.1392407
A23: 70% Equity Scenario (LTV-30%)
A24: Total Cash Outlay: | C24: -14840000 | D24: -18592000 | E24: -23952000 | F24: -27972000 | G24: -30652000
A25: Total Cash Inflow: | C25: 28809046 | D25: 30664666 | E25: 32587654 | F25: 33948470 | G25: 34811806 | I25: Distribution:
A26: IRR: | C26: 0.21862132 | D26: 0.16930892 | E26: 0.11015831 | F26: 0.074260298 | G26: 0.051732128 | I26: Shareholder #1 (Tusten) | K26: =100%-K27 -> 0.5
A27: Payback: | C27: 2.9450714 | D27: 3.6563991 | E27: 5.1026604 | F27: 6.4429446 | G27: 7.4921314 | I27: Shareholder #2 (Processing) | K27: 0.5
A28: MOIC: | C28: 1.9413104 | D28: 1.813522 | E28: 1.6902731 | F28: 1.5923497 | G28: 1.5241109
A30: 60% Equity Scenario (LTV-40%)
A31: Total Cash Outlay: | C31: -14840000 | D31: -18056000 | E31: -23416000 | F31: -27436000 | G31: -30116000
A32: Total Cash Inflow: | C32: 30653437 | D32: 33386154 | E32: 36350428 | F32: 38576633 | G32: 40021549 | I32: Distribution:
A33: IRR: | C33: 0.25671564 | D33: 0.22330501 | E33: 0.16804122 | F33: 0.13700113 | G33: 0.11975919 | I33: Shareholder #1 (Tusten) | K33: =100%-K34 -> 0.5
A34: Payback: | C34: 2.3264623 | D34: 2.7088418 | E34: 3.6379541 | F34: 4.4374816 | G34: 4.9401903 | I34: Shareholder #2 (Processing) | K34: 0.5
A35: MOIC: | C35: 2.0655955 | D35: 2.0330292 | E35: 2.0160666 | F35: 2.0035467 | G35: 1.9925572
A37: 50% Equity Scenario (LTV-50%)
A38: Total Cash Outlay: | C38: -14840000 | D38: -17520000 | E38: -22880000
A39: Total Cash Inflow: | C39: 32657836 | D39: 36522239 | E39: 41117972 | I39: Distribution:
A40: IRR: | C40: 0.29221804 | D40: 0.27538723 | E40: 0.22102155 | I40: Shareholder #1 (Tusten) | K40: =100%-K41 -> 0.5
A41: Payback: | C41: 2.1100931 | D41: 2.5326836 | E41: 3.4794773 | I41: Shareholder #2 (Processing) | K41: 0.5
A42: MOIC: | C42: 2.2006628 | D42: 2.2804744 | E42: 2.4095669
A44: 40% Equity Scenario (LTV-60%)
A45: Total Cash Outlay: | C45: -14840000 | D45: -16984000
A46: Total Cash Inflow: | C46: 34870653 | D46: 40331471 | I46: Distribution:
...

Sheet Assumptions
D1: Instruction: fill out blue cells only
B3: All Equity Scenario | H3: 50% Equity Scenario
E4: P1 | F4: P2 | K4: P1 | L4: P2
B5: Residuals | H5: Residuals
C6: Residual Payment (Monthly) | E6: 600000 | F6: 70000 | I6: Residual Payment (Monthly) | K6: 600000 | L6: 70000
C7: Initial Multiple | E7: 22 | F7: 22 | I7: Initial Multiple | K7: 22 | L7: 22
B8: Deferred Purchase Price: | H8: Deferred Purchase Price:
C9: 6 Months | E9: 8 | F9: 8 | I9: 6 Months | K9: 8 | L9: 8
C10: 12 Months | E10: 8 | F10: 8 | I10: 12 Months | K10: 8 | L10: 8
C11: 24 Months | E11: 6 | F11: 6 | I11: 24 Months | K11: 6 | L11: 6
C12: 36 Months | E12: 4 | F12: 4 | I12: 36 Months | K12: 4 | L12: 4
B13: Merchant Attrition Threshold (Monthly) | E13: =12%/12 -> 0.01 | F13: =12%/12 -> 0.01 | H13: Merchant Attrition Threshold (Monthly) | K13: =12%/12 -> 0.01 | L13: =12%/12 -> 0.01
B14: Merchant Attrition Actual (Monthly) | H14: Merchant Attrition Actual (Monthly)
C15: 6 Months | E15: 0.0101 | F15: 0.0101 | I15: 6 Months | K15: 0.0101 | L15: 0.0101
C16: 12 Months | E16: 0.0101 | F16: 0.0101 | I16: 12 Months | K16: 0.0101 | L16: 0.0101
C17: 24 Months | E17: 0.0101 | F17: 0.0101 | I17: 24 Months | K17: 0.0101 | L17: 0.0101
C18: 36 Months | E18: 0.0101 | F18: 0.0101 | I18: 36 Months | K18: 0.0101 | L18: 0.0101
C19: After 36th Month | E19: 0.0101 | F19: 0.0101 | I19: After 36th Month | K19: 0.0101 | L19: 0.0101
B20: Initial Capital Investment | H20: Initial Capital Investment
C21: Note amount | E21: =E23*(E6*E7) -> 0 | F21: =F23*(F6*F7) -> 0 | I21: Note amount | K21: =K23*(K6*K7) -> 6600000 | L21: =L23*(L6*L7) -> 770000
C22: Note interest rate | E22: 0.14 | F22: 0.14 | I22: Note interest rate | K22: 0.14 | L22: 0.14
C23: LTV Ratio | E23: 0 | F23: 0 | I23: LTV Ratio | K23: 0.5 | L23: 0.5
C24: Equity (Tusten) | E24: =E6*(1-$E$23)*E7 -> 13200000 | F24: =F6*(1-$F$23)*F7 -> 1540000 | I24: Equity (Tusten) | K24: =K6*(1-$K$23)*K7 -> 6600000 | L24: =L6*(1-$L$23)*L7 -> 770000
D25: Hurdle rate (Annual) | E25: 0.08 | F25: 0.08
D26: Hurdle rate (Monthly) | E26: =POWER(1+E25,1/12)-1 -> 0.0064340301 | F26: =POWER(1+F25,1/12)-1 -> 0.0064340301 | K26: =POWER(1+K25,1/12)-1 -> 0 | L26: =POWER(1+L25,1/12)-1 -> 0
B27: Closing Costs | H27: Closing Costs
C28: Legal and Closing Costs | E28: 50000 | F28: 50000 | I28: Legal and Closing Costs | K28: 50000 | L28: 50000
B29: Expenses | H29: Expenses
C30: Management Fee | E30: 0 | F30: 0 | I30: Management Fee | K30: 0 | L30: 0
B31: Distributions | H31: Distributions
C32: Shareholder #1 (Tusten) | E32: =100%-E33 -> 0.75 | F32: =100%-F33 -> 0.75 | I32: Shareholder #1 (Tusten) | K32: =100%-K33 -> 0.5 | L32: =100%-L33 -> 0.5
C33: Shareholder #2 (Processing) | E33: 0.25 | F33: 0.25 | I33: Shareholder #2 (Processing) | K33: 0.5 | L33: 0.5
B34: Sale of Residuals at end of Term | H34: Sale of Residuals at end of Term
C35: Sales Multiple | E35: 6 | F35: 6 | I35: Sales Multiple | K35: 6 | L35: 6

Sheet All Equity Scenario
D2: 0 | E2: 1 | F2: 2 | G2: 3 | H2: 4 | I2: 5 | J2: 6 | K2: 7 | L2: 8 | M2: 9 | N2: 10 | O2: 11 | P2: 12 | Q2: 13 | R2: 14 | S2: 15 | T2: 16 | U2: 17 | V2: 18 | W2: 19 | X2: 20 | Y2: 21 | Z2: 22 | AA2: 23 | AB2: 24 | AC2: 25 | AD2: 26 | AE2: 27 | AF2: 28 | AG2: 29 | AH2: 30 | AI2: 31 | AJ2: 32 | AK2: 33 | AL2: 34 | AM2: 35 | AN2: 36 | AO2: 37 | AP2: 38 | AQ2: 39 | AR2: 40 | AS2: 41 | AT2: 42 | AU2: 43 | AV2: 44 | AW2: 45 | AX2: 46 | AY2: 47 | AZ2: 48 | BA2: 49 | BB2: 50 | BC2: 51 | BD2: 52 | BE2: 53 | BF2: 54 | BG2: 55 | BH2: 56 | BI2: 57 | BJ2: 58 | BK2: 59 | BL2: 60 | BM2: 61 | BN2: 62 | BO2: 63 | BP2: 64 | BQ2: 65 | BR2: 66 | BS2: 67 | BT2: 68 | BU2: 69 | BV2: 70 | BW2: 71 | BX2: 72 | BY2: 73 | BZ2: 74 | CA2: 75 | CB2: 76 | CC2: 77 | CD2: 78 | CE2: 79 | CF2: 80 | CG2: 81 | CH2: 82 | CI2: 83 | CJ2: 84 | CK2: 85 | CL2: 86 | CM2: 87 | CN2: 88 | CO2: 89 | CP2: 90 | CQ2: 91 | CR2: 92 | CS2: 93 | CT2: 94 | CU2: 95 | CV2: 96 | CW2: 97 | CX2: 98 | CY2: 99 | CZ2: 100 | DA2: 101 | DB2: 102 | DC2: 103 | DD2: 104 | DE2: 105 | DF2: 106 | DG2: 107 | DH2: 108 | DI2: 109 | DJ2: 110 | DK2: 111 | DL2: 112 | DM2: 113 | DN2: 114 | DO2: 115 | DP2: 116 | DQ2: 117 | DR2: 118 | DS2: 119 | DT2: 120 | DU2: 121
A4: x | B4: Uses
C5: Initial Purchase Price | D5: =-Assumptions!E6*Assumptions!E7+-Assumptions!F6*Assumptions!F7 -> -14740000
C6: Deferred Purchase Price | K6: =SUM(K7:K8) -> 0 | Q6: =SUM(Q7:Q8) -> 0 | AC6: =SUM(AC7:AC8) -> 0 | AO6: =SUM(AO7:AO8) -> 0
B7: =Assumptions!E6/SUM(Assumptions!E6:F6) -> 0.89552239 | C7: P1 | K7: =IF(Assumptions!E15>Assumptions!E13,0,-Assumptions!E6*Assumptions!E9) -> 0 | Q7: =IF(Assumptions!E16>Assumptions!E13,0,-Assumptions!E6*Assumptions!E10) -> 0 | AC7: =IF(Assumptions!E17>Assumptions!E13,0,-Assumptions!E6*Assumptions!E11) -> 0 | AO7: =IF(Assumptions!E18>Assumptions!E13,0,-Assumptions!E6*Assumptions!E12) -> 0
B8: =1-B7 -> 0.10447761 | C8: P2 | K8: =+IF(Assumptions!F15>Assumptions!F13,0,-Assumptions!F6*Assumptions!F9) -> 0 | Q8: =+IF(Assumptions!F16>Assumptions!F13,0,-Assumptions!F6*Assumptions!F10) -> 0 | AC8: =IF(Assumptions!F17>Assumptions!F13,0,-Assumptions!F6*Assumptions!F11) -> 0 | AO8: =+IF(Assumptions!F18>Assumptions!F13,0,-Assumptions!F6*Assumptions!F12) -> 0
C9: Legal and Closing Costs | D9: =-Assumptions!E28-Assumptions!F28 -> -100000
A10: x | B10: Total Uses: | D10: =SUM(D5:D9) -> -14840000 | E10: =E6+E5+E9 -> 0 | F10: =F6+F5+F9 -> 0 | G10: =G6+G5+G9 -> 0 | H10: =H6+H5+H9 -> 0 | I10: =I6+I5+I9 -> 0 | J10: =J6+J5+J9 -> 0 | K10: =K6+K5+K9 -> 0 | L10: =L6+L5+L9 -> 0 | ... DU10: =DU6+DU5+DU9 -> 0
B12: Revenue
C13: Residual Payment | E13: =SUM(E14:E15) -> 670000 | F13: =SUM(F14:F15) -> 663233 | G13: =SUM(G14:G15) -> 656534.35 | H13: =SUM(H14:H15) -> 649903.35 | I13: =SUM(I14:I15) -> 643339.33 | J13: =SUM(J14:J15) -> 636841.6 | K13: =SUM(K14:K15) -> 630409.5 | L13: =SUM(L14:L15) -> 624042.36 | ... DT13: =SUM(DT14:DT15) -> 200190
C14: P1 | E14: =Assumptions!E6 -> 600000 | F14: =E14*(1-Assumptions!$E$16) -> 593940 | G14: =F14*(1-Assumptions!$E$16) -> 587941.21 | H14: =G14*(1-Assumptions!$E$16) -> 582003 | I14: =H14*(1-Assumptions!$E$16) -> 576124.77 | J14: =I14*(1-Assumptions!$E$16) -> 570305.91 | K14: =J14*(1-Assumptions!$E$16) -> 564545.82 | L14: =K14*(1-Assumptions!$E$16) -> 558843.91 | M14: =L14*(1-Assumptions!$E$16) -> 553199.58 | ... P14: =O14*(1-Assumptions!$E$16) -> 536606.36 | Q14: =P14*(1-Assumptions!$E$17) -> 531186.64 | R14: =Q14*(1-Assumptions!$E$17) -> 525821.65 | S14: =R14*(1-Assumptions!$E$17) -> 520510.85 | T14: =S14*(1-Assumptions!$E$17) -> 515253.69 | U14: =T14*(1-Assumptions!$E$17) -> 510049.63 | V14: =U14*(1-Assumptions!$E$17) -> 504898.13 | W14: =V14*(1-Assumptions!$E$17) -> 499798.66 | X14: =W14*(1-Assumptions!$E$17) -> 494750.69 | ... AB14: =AA14*(1-Assumptions!$E$17) -> 475063.55 | AC14: =AB14*(1-Assumptions!$E$18) -> 470265.41 | AD14: =AC14*(1-Assumptions!$E$18) -> 465515.73 | AE14: =AD14*(1-Assumptions!$E$18) -> 460814.02 | AF14: =AE14*(1-Assumptions!$E$18) -> 456159.8 | AG14: =AF14*(1-Assumptions!$E$18) -> 451552.58 | AH14: =AG14*(1-Assumptions!$E$18) -> 446991.9 | AI14: =AH14*(1-Assumptions!$E$18) -> 442477.28 | AJ14: =AI14*(1-Assumptions!$E$18) -> 438008.26 | ... AN14: =AM14*(1-Assumptions!$E$18) -> 420579.01 | AO14: =AN14*(1-Assumptions!$E$19) -> 416331.17 | AP14: =AO14*(1-Assumptions!$E$19) -> 412126.22 | AQ14: =AP14*(1-Assumptions!$E$19) -> 407963.75 | AR14: =AQ14*(1-Assumptions!$E$19) -> 403843.31 | AS14: =AR14*(1-Assumptions!$E$19) -> 399764.5 | AT14: =AS14*(1-Assumptions!$E$19) -> 395726.87 | AU14: =AT14*(1-Assumptions!$E$19) -> 391730.03 | AV14: =AU14*(1-Assumptions!$E$19) -> 387773.56 | ... DT14: =DS14*(1-Assumptions!$E$19) -> 179274.63
C15: P2 | E15: =Assumptions!F6 -> 70000 | F15: =E15*(1-Assumptions!$F$16) -> 69293 | G15: =F15*(1-Assumptions!$F$16) -> 68593.141 | H15: =G15*(1-Assumptions!$F$16) -> 67900.35 | I15: =H15*(1-Assumptions!$F$16) -> 67214.556 | J15: =I15*(1-Assumptions!$F$16) -> 66535.689 | K15: =J15*(1-Assumptions!$F$16) -> 65863.679 | L15: =K15*(1-Assumptions!$F$16) -> 65198.456 | M15: =L15*(1-Assumptions!$F$16) -> 64539.951 | ... P15: =O15*(1-Assumptions!$F$16) -> 62604.076 | Q15: =P15*(1-Assumptions!$F$17) -> 61971.774 | R15: =Q15*(1-Assumptions!$F$17) -> 61345.859 | S15: =R15*(1-Assumptions!$F$17) -> 60726.266 | T15: =S15*(1-Assumptions!$F$17) -> 60112.931 | U15: =T15*(1-Assumptions!$F$17) -> 59505.79 | V15: =U15*(1-Assumptions!$F$17) -> 58904.782 | W15: =V15*(1-Assumptions!$F$17) -> 58309.844 | X15: =W15*(1-Assumptions!$F$17) -> 57720.914 | ... AB15: =AA15*(1-Assumptions!$F$17) -> 55424.081 | AC15: =AB15*(1-Assumptions!$F$18) -> 54864.297 | AD15: =AC15*(1-Assumptions!$F$18) -> 54310.168 | AE15: =AD15*(1-Assumptions!$F$18) -> 53761.635 | AF15: =AE15*(1-Assumptions!$F$18) -> 53218.643 | AG15: =AF15*(1-Assumptions!$F$18) -> 52681.135 | AH15: =AG15*(1-Assumptions!$F$18) -> 52149.055 | AI15: =AH15*(1-Assumptions!$F$18) -> 51622.35 | AJ15: =AI15*(1-Assumptions!$F$18) -> 51100.964 | ... AN15: =AM15*(1-Assumptions!$F$18) -> 49067.552 | AO15: =AN15*(1-Assumptions!$F$19) -> 48571.969 | AP15: =AO15*(1-Assumptions!$F$19) -> 48081.393 | AQ15: =AP15*(1-Assumptions!$F$19) -> 47595.77 | AR15: =AQ15*(1-Assumptions!$F$19) -> 47115.053 | AS15: =AR15*(1-Assumptions!$F$19) -> 46639.191 | AT15: =AS15*(1-Assumptions!$F$19) -> 46168.135 | AU15: =AT15*(1-Assumptions!$F$19) -> 45701.837 | AV15: =AU15*(1-Assumptions!$F$19) -> 45240.249 | ... DT15: =DS15*(1-Assumptions!$F$19) -> 20915.374
C16: Sale of Residuals | E16: =SUM(E17:E18) -> 0 | F16: =SUM(F17:F18) -> 0 | G16: =SUM(G17:G18) -> 0 | H16: =SUM(H17:H18) -> 0 | I16: =SUM(I17:I18) -> 0 | J16: =SUM(J17:J18) -> 0 | K16: =SUM(K17:K18) -> 0 | L16: =SUM(L17:L18) -> 0 | ... DU16: =SUM(DU17:DU18) -> 1201140
C17: P1 | DU17: =DT14*Assumptions!E35 -> 1075647.8
C18: P2 | DU18: =DT15*Assumptions!F35 -> 125492.24
A19: x | E19: =E16+E13 -> 670000 | F19: =F16+F13 -> 663233 | G19: =G16+G13 -> 656534.35 | H19: =H16+H13 -> 649903.35 | I19: =I16+I13 -> 643339.33 | J19: =J16+J13 -> 636841.6 | K19: =K16+K13 -> 630409.5 | L19: =L16+L13 -> 624042.36 | ... DU19: =DU16+DU13 -> 1201140
A21: x | B21: Waterfall Flow of Funds | F21: =F19+F22+F25 -> 663233
C22: Management Fee | E22: =SUM(E23:E24) -> 0 | F22: =SUM(F23:F24) -> 0 | G22: =SUM(G23:G24) -> 0 | H22: =SUM(H23:H24) -> 0 | I22: =SUM(I23:I24) -> 0 | J22: =SUM(J23:J24) -> 0 | K22: =SUM(K23:K24) -> 0 | L22: =SUM(L23:L24) -> 0 | ... DU22: =SUM(DU23:DU24) -> 0
C23: P1 | E23: =-(E14+E17)*Assumptions!$E$30 -> 0 | F23: =-(F14+F17)*Assumptions!$E$30 -> 0 | G23: =-(G14+G17)*Assumptions!$E$30 -> 0 | H23: =-(H14+H17)*Assumptions!$E$30 -> 0 | I23: =-(I14+I17)*Assumptions!$E$30 -> 0 | J23: =-(J14+J17)*Assumptions!$E$30 -> 0 | K23: =-(K14+K17)*Assumptions!$E$30 -> 0 | L23: =-(L14+L17)*Assumptions!$E$30 -> 0 | ... DU23: =-(DU14+DU17)*Assumptions!$E$30 -> 0
C24: P2 | E24: =-(E15+E18)*Assumptions!$F$30 -> 0 | F24: =-(F15+F18)*Assumptions!$F$30 -> 0 | G24: =-(G15+G18)*Assumptions!$F$30 -> 0 | H24: =-(H15+H18)*Assumptions!$F$30 -> 0 | I24: =-(I15+I18)*Assumptions!$F$30 -> 0 | J24: =-(J15+J18)*Assumptions!$F$30 -> 0 | K24: =-(K15+K18)*Assumptions!$F$30 -> 0 | L24: =-(L15+L18)*Assumptions!$F$30 -> 0 | ... DU24: =-(DU15+DU18)*Assumptions!$F$30 -> 0
C25: Interest Payment | E25: =SUM(E26:E27) -> 0 | F25: =SUM(F26:F27) -> 0 | G25: =SUM(G26:G27) -> 0 | H25: =SUM(H26:H27) -> 0 | I25: =SUM(I26:I27) -> 0 | J25: =SUM(J26:J27) -> 0 | K25: =SUM(K26:K27) -> 0 | L25: =SUM(L26:L27) -> 0 | ... DU25: =SUM(DU26:DU27) -> 0
C26: P1 | E26: =-D69*(Assumptions!$E$22/12) -> 0 | F26: =-E69*(Assumptions!$E$22/12) -> 0 | G26: =-F69*(Assumptions!$E$22/12) -> 0 | H26: =-G69*(Assumptions!$E$22/12) -> 0 | I26: =-H69*(Assumptions!$E$22/12) -> 0 | J26: =-I69*(Assumptions!$E$22/12) -> 0 | K26: =-J69*(Assumptions!$E$22/12) -> 0 | L26: =-K69*(Assumptions!$E$22/12) -> 0 | ... DU26: =-DT69*(Assumptions!$E$22/12) -> 0
C27: P2 | E27: =-D70*(Assumptions!$F$22/12) -> 0 | F27: =-E70*(Assumptions!$F$22/12) -> 0 | G27: =-F70*(Assumptions!$F$22/12) -> 0 | H27: =-G70*(Assumptions!$F$22/12) -> 0 | I27: =-H70*(Assumptions!$F$22/12) -> 0 | J27: =-I70*(Assumptions!$F$22/12) -> 0 | K27: =-J70*(Assumptions!$F$22/12) -> 0 | L27: =-K70*(Assumptions!$F$22/12) -> 0 | ... DU27: =-DT70*(Assumptions!$F$22/12) -> 0
C28: Debt Principal Payment | E28: =SUM(E29:E30) -> 0 | F28: =SUM(F29:F30) -> 0 | G28: =SUM(G29:G30) -> 0 | H28: =SUM(H29:H30) -> 0 | I28: =SUM(I29:I30) -> 0 | J28: =SUM(J29:J30) -> 0 | K28: =SUM(K29:K30) -> 0 | L28: =SUM(L29:L30) -> 0 | ... DU28: =SUM(DU29:DU30) -> 0
C29: 5 | E29: =MAX(-D69,-(E14+E17+E26+E23)) -> 0 | F29: =MAX(-E69,-(F14+F17+F26+F23)) -> 0 | G29: =MAX(-F69,-(G14+G17+G26+G23)) -> 0 | H29: =MAX(-G69,-(H14+H17+H26+H23)) -> 0 | I29: =MAX(-H69,-(I14+I17+I26+I23)) -> 0 | J29: =MAX(-I69,-(J14+J17+J26+J23)) -> 0 | K29: =MAX(-J69,-(K14+K17+K26+K23)) -> 0 | L29: =MAX(-K69,-(L14+L17+L26+L23)) -> 0 | ... DU29: =MAX(-DT69,-(DU14+DU17+DU26+DU23)) -> 0
C30: P2 | E30: =MAX(-D70,-(E15+E18+E27+E24)) -> 0 | F30: =MAX(-E70,-(F15+F18+F27+F24)) -> 0 | G30: =MAX(-F70,-(G15+G18+G27+G24)) -> 0 | H30: =MAX(-G70,-(H15+H18+H27+H24)) -> 0 | I30: =MAX(-H70,-(I15+I18+I27+I24)) -> 0 | J30: =MAX(-I70,-(J15+J18+J27+J24)) -> 0 | K30: =MAX(-J70,-(K15+K18+K27+K24)) -> 0 | L30: =MAX(-K70,-(L15+L18+L27+L24)) -> 0 | ... DU30: =MAX(-DT70,-(DU15+DU18+DU27+DU24)) -> 0
B31: Cash Available for Equity Investors | E31: =SUM(E32:E33) -> 670000 | F31: =SUM(F32:F33) -> 663233 | G31: =SUM(G32:G33) -> 656534.35 | H31: =SUM(H32:H33) -> 649903.35 | I31: =SUM(I32:I33) -> 643339.33 | J31: =SUM(J32:J33) -> 636841.6 | K31: =SUM(K32:K33) -> 630409.5 | L31: =SUM(L32:L33) -> 624042.36 | ... DU31: =SUM(DU32:DU33) -> 1201140
C32: P1 | E32: =IF(E68>0,0,MAX(0,E14+E17+E23+E26+E29)) -> 600000 | F32: =IF(F68>0,0,MAX(0,F14+F17+F23+F26+F29)) -> 593940 | G32: =IF(G68>0,0,MAX(0,G14+G17+G23+G26+G29)) -> 587941.21 | H32: =IF(H68>0,0,MAX(0,H14+H17+H23+H26+H29)) -> 582003 | I32: =IF(I68>0,0,MAX(0,I14+I17+I23+I26+I29)) -> 576124.77 | J32: =IF(J68>0,0,MAX(0,J14+J17+J23+J26+J29)) -> 570305.91 | K32: =IF(K68>0,0,MAX(0,K14+K17+K23+K26+K29)) -> 564545.82 | L32: =IF(L68>0,0,MAX(0,L14+L17+L23+L26+L29)) -> 558843.91 | ... DU32: =IF(DU68>0,0,MAX(0,DU14+DU17+DU23+DU26+DU29)) -> 1075647.8
C33: P2 | E33: =IF(E68>0,0,MAX(0,E15+E18+E24+E27+E30)) -> 70000 | F33: =IF(F68>0,0,MAX(0,F15+F18+F24+F27+F30)) -> 69293 | G33: =IF(G68>0,0,MAX(0,G15+G18+G24+G27+G30)) -> 68593.141 | H33: =IF(H68>0,0,MAX(0,H15+H18+H24+H27+H30)) -> 67900.35 | I33: =IF(I68>0,0,MAX(0,I15+I18+I24+I27+I30)) -> 67214.556 | J33: =IF(J68>0,0,MAX(0,J15+J18+J24+J27+J30)) -> 66535.689 | K33: =IF(K68>0,0,MAX(0,K15+K18+K24+K27+K30)) -> 65863.679 | L33: =IF(L68>0,0,MAX(0,L15+L18+L24+L27+L30)) -> 65198.456 | ... DU33: =IF(DU68>0,0,MAX(0,DU15+DU18+DU24+DU27+DU30)) -> 125492.24
B35: LP | C35: Tusten_Entitlement_ToDate | D35: =SUM(D36:D37) -> 14840000 | E35: =SUM(E36:E37) -> 14935481 | F35: =SUM(F36:F37) -> 14361576 | G35: =SUM(G36:G37) -> 13790746 | H35: =SUM(H36:H37) -> 13222942 | I35: =SUM(I36:I37) -> 12658115 | J35: =SUM(J36:J37) -> 12096219 | K35: =SUM(K36:K37) -> 11537205 | ... DU35: =SUM(DU36:DU37) -> -32267177
C36: P1 | D36: =Assumptions!E24+Assumptions!E28 -> 13250000 | E36: =D36*(1+Assumptions!$E$26)-E7*(1-Assumptions!$E$23)-D53 -> 13335251 | F36: =E36*(1+Assumptions!$E$26)-F7*(1-Assumptions!$E$23)-E53 -> 12821050 | G36: =F36*(1+Assumptions!$E$26)-G7*(1-Assumptions!$E$23)-F53 -> 12309601 | H36: =G36*(1+Assumptions!$E$26)-H7*(1-Assumptions!$E$23)-G53 -> 11800860 | I36: =H36*(1+Assumptions!$E$26)-I7*(1-Assumptions!$E$23)-H53 -> 11294785 | J36: =I36*(1+Assumptions!$E$26)-J7*(1-Assumptions!$E$23)-I53 -> 10791331 | K36: =J36*(1+Assumptions!$E$26)-K7*(1-Assumptions!$E$23)-J53 -> 10290457 | L36: =K36*(1+Assumptions!$E$26)-L7*(1-Assumptions!$E$23)-K53 -> 9792119.9 | ... DU36: =DT36*(1+Assumptions!$E$26)-DU7*(1-Assumptions!$E$23)-DT53 -> -28981920
C37: P2 | D37: =+Assumptions!F24+Assumptions!F28 -> 1590000 | E37: =D37*(1+Assumptions!$F$26)-E8*(1-Assumptions!$F$23)-D54 -> 1600230.1 | F37: =E37*(1+Assumptions!$F$26)-F8*(1-Assumptions!$F$23)-E54 -> 1540526 | G37: =F37*(1+Assumptions!$F$26)-G8*(1-Assumptions!$F$23)-F54 -> 1481144.8 | H37: =G37*(1+Assumptions!$F$26)-H8*(1-Assumptions!$F$23)-G54 -> 1422081.4 | I37: =H37*(1+Assumptions!$F$26)-I8*(1-Assumptions!$F$23)-H54 -> 1363330.8 | J37: =I37*(1+Assumptions!$F$26)-J8*(1-Assumptions!$F$23)-I54 -> 1304887.9 | K37: =J37*(1+Assumptions!$F$26)-K8*(1-Assumptions!$F$23)-J54 -> 1246747.9 | L37: =K37*(1+Assumptions!$F$26)-L8*(1-Assumptions!$F$23)-K54 -> 1188905.9 | ... DU37: =DT37*(1+Assumptions!$F$26)-DU8*(1-Assumptions!$F$23)-DT54 -> -3285257.9
A38: x | B38: LP | C38: Tusten_CatchUp_Paid | E38: =SUM(E39:E40) -> 670000 | F38: =SUM(F39:F40) -> 663233 | G38: =SUM(G39:G40) -> 656534.35 | H38: =SUM(H39:H40) -> 649903.35 | I38: =SUM(I39:I40) -> 643339.33 | J38: =SUM(J39:J40) -> 636841.6 | K38: =SUM(K39:K40) -> 630409.5 | L38: =SUM(L39:L40) -> 624042.36 | ... DU38: =SUM(DU39:DU40) -> 0
C39: P1 | E39: =IF(D35>D60,E32,0) -> 600000 | F39: =IF(E35>E60,F32,0) -> 593940 | G39: =IF(F35>F60,G32,0) -> 587941.21 | H39: =IF(G35>G60,H32,0) -> 582003 | I39: =IF(H35>H60,I32,0) -> 576124.77 | J39: =IF(I35>I60,J32,0) -> 570305.91 | K39: =IF(J35>J60,K32,0) -> 564545.82 | L39: =IF(K35>K60,L32,0) -> 558843.91 | ... DU39: =IF(DT35>DT60,DU32,0) -> 0
C40: P2 | E40: =IF(D35>D60,E33,0) -> 70000 | F40: =IF(E35>E60,F33,0) -> 69293 | G40: =IF(F35>F60,G33,0) -> 68593.141 | H40: =IF(G35>G60,H33,0) -> 67900.35 | I40: =IF(H35>H60,I33,0) -> 67214.556 | J40: =IF(I35>I60,J33,0) -> 66535.689 | K40: =IF(J35>J60,K33,0) -> 65863.679 | L40: =IF(K35>K60,L33,0) -> 65198.456 | ... DU40: =IF(DT35>DT60,DU33,0) -> 0
A41: x | C41: Remainder_for_Split | E41: =SUM(E42:E43) -> 0 | F41: =SUM(F42:F43) -> 0 | G41: =SUM(G42:G43) -> 0 | H41: =SUM(H42:H43) -> 0 | I41: =SUM(I42:I43) -> 0 | J41: =SUM(J42:J43) -> 0 | K41: =SUM(K42:K43) -> 0 | L41: =SUM(L42:L43) -> 0 | ... DU41: =SUM(DU42:DU43) -> 1201140
C42: P1 | E42: =IF(E68>0,0,E32-E39) -> 0 | F42: =IF(F68>0,0,F32-F39) -> 0 | G42: =IF(G68>0,0,G32-G39) -> 0 | H42: =IF(H68>0,0,H32-H39) -> 0 | I42: =IF(I68>0,0,I32-I39) -> 0 | J42: =IF(J68>0,0,J32-J39) -> 0 | K42: =IF(K68>0,0,K32-K39) -> 0 | L42: =IF(L68>0,0,L32-L39) -> 0 | ... DU42: =IF(DU68>0,0,DU32-DU39) -> 1075647.8
C43: P2 | E43: =IF(E68>0,0,E33-E40) -> 0 | F43: =IF(F68>0,0,F33-F40) -> 0 | G43: =IF(G68>0,0,G33-G40) -> 0 | H43: =IF(H68>0,0,H33-H40) -> 0 | I43: =IF(I68>0,0,I33-I40) -> 0 | J43: =IF(J68>0,0,J33-J40) -> 0 | K43: =IF(K68>0,0,K33-K40) -> 0 | L43: =IF(L68>0,0,L33-L40) -> 0 | ... DU43: =IF(DU68>0,0,DU33-DU40) -> 125492.24
A44: x | C44: LP_Share_75% | E44: =SUM(E45:E46) -> 0 | F44: =SUM(F45:F46) -> 0 | G44: =SUM(G45:G46) -> 0 | H44: =SUM(H45:H46) -> 0 | I44: =SUM(I45:I46) -> 0 | J44: =SUM(J45:J46) -> 0 | K44: =SUM(K45:K46) -> 0 | L44: =SUM(L45:L46) -> 0 | ... DU44: =SUM(DU45:DU46) -> 900855.02
C45: P1 | E45: =IF(AND(E68>0,D60<D35),0,E42*Assumptions!$E$32) -> 0 | F45: =IF(AND(F68>0,E60<E35),0,F42*Assumptions!$E$32) -> 0 | G45: =IF(AND(G68>0,F60<F35),0,G42*Assumptions!$E$32) -> 0 | H45: =IF(AND(H68>0,G60<G35),0,H42*Assumptions!$E$32) -> 0 | I45: =IF(AND(I68>0,H60<H35),0,I42*Assumptions!$E$32) -> 0 | J45: =IF(AND(J68>0,I60<I35),0,J42*Assumptions!$E$32) -> 0 | K45: =IF(AND(K68>0,J60<J35),0,K42*Assumptions!$E$32) -> 0 | L45: =IF(AND(L68>0,K60<K35),0,L42*Assumptions!$E$32) -> 0 | ... DU45: =IF(AND(DU68>0,DT60<DT35),0,DU42*Assumptions!$E$32) -> 806735.84
...

Sheet Summary (All Equity)
E2: Year 1 | F2: Year 2 | G2: Year 3 | H2: Year 4 | I2: Year 5 | J2: Year 6 | K2: Year 7 | L2: Year 8 | M2: Year 9 | N2: Year 10 | O2: Sale of Investment
E3: Months 1-12 | F3: Months 13-24 | G3: Months 25-36 | H3: Months 37-48 | I3: Months 49-60 | J3: Months 61-72 | K3: Months 73-84 | L3: Months 85-96 | M3: Months 97-108 | N3: Months 109-120 | O3: Month 121
B4: Uses
C5: Initial Purchase Price | D5: ='All Equity Scenario'!D5 -> -14740000 | E5: =SUM('All Equity Scenario'!E5:P5) -> 0 | F5: =SUM('All Equity Scenario'!Q5:AB5) -> 0 | G5: =SUM('All Equity Scenario'!AC5:AN5) -> 0 | H5: =SUM('All Equity Scenario'!AO5:AZ5) -> 0 | I5: =SUM('All Equity Scenario'!BA5:BL5) -> 0 | J5: =SUM('All Equity Scenario'!BM5:BX5) -> 0 | K5: =SUM('All Equity Scenario'!BY5:CJ5) -> 0 | L5: =SUM('All Equity Scenario'!CK5:CV5) -> 0 | M5: =SUM('All Equity Scenario'!CW5:DH5) -> 0 | N5: =SUM('All Equity Scenario'!DI5:DT5) -> 0 | O5: ='All Equity Scenario'!DU5 -> 0
C6: Deferred Purchase Price | D6: ='All Equity Scenario'!D6 -> 0 | E6: =SUM('All Equity Scenario'!E6:P6) -> 0 | F6: =SUM('All Equity Scenario'!Q6:AB6) -> 0 | G6: =SUM('All Equity Scenario'!AC6:AN6) -> 0 | H6: =SUM('All Equity Scenario'!AO6:AZ6) -> 0 | I6: =SUM('All Equity Scenario'!BA6:BL6) -> 0 | J6: =SUM('All Equity Scenario'!BM6:BX6) -> 0 | K6: =SUM('All Equity Scenario'!BY6:CJ6) -> 0 | L6: =SUM('All Equity Scenario'!CK6:CV6) -> 0 | M6: =SUM('All Equity Scenario'!CW6:DH6) -> 0 | N6: =SUM('All Equity Scenario'!DI6:DT6) -> 0 | O6: ='All Equity Scenario'!DU6 -> 0
C7: Legal and Accounting | D7: ='All Equity Scenario'!D9 -> -100000 | E7: =SUM('All Equity Scenario'!E9:P9) -> 0 | F7: =SUM('All Equity Scenario'!Q9:AB9) -> 0 | G7: =SUM('All Equity Scenario'!AC9:AN9) -> 0 | H7: =SUM('All Equity Scenario'!AO9:AZ9) -> 0 | I7: =SUM('All Equity Scenario'!BA9:BL9) -> 0 | J7: =SUM('All Equity Scenario'!BM9:BX9) -> 0 | K7: =SUM('All Equity Scenario'!BY9:CJ9) -> 0 | L7: =SUM('All Equity Scenario'!CK9:CV9) -> 0 | M7: =SUM('All Equity Scenario'!CW9:DH9) -> 0 | N7: =SUM('All Equity Scenario'!DI9:DT9) -> 0 | O7: ='All Equity Scenario'!DU9 -> 0
A8: x | B8: Total Uses: | D8: =SUM(D5:D7) -> -14840000 | E8: =SUM(E5:E7) -> 0 | F8: =SUM(F5:F7) -> 0 | G8: =SUM(G5:G7) -> 0 | H8: =SUM(H5:H7) -> 0 | I8: =SUM(I5:I7) -> 0 | J8: =SUM(J5:J7) -> 0 | K8: =SUM(K5:K7) -> 0 | ... O8: =SUM(O5:O7) -> 0 | Q8: =SUM(Q5:Q7) -> 0 | R8: =SUM(R5:R7) -> 0
F9: =SUM('All Equity Scenario'!Q11:AB11) -> 0 | G9: =SUM('All Equity Scenario'!AC11:AN11) -> 0 | H9: =SUM('All Equity Scenario'!AO11:AZ11) -> 0 | I9: =SUM('All Equity Scenario'!BA11:BL11) -> 0 | J9: =SUM('All Equity Scenario'!BM11:BX11) -> 0 | K9: =SUM('All Equity Scenario'!BY11:CJ11) -> 0 | L9: =SUM('All Equity Scenario'!CK11:CV11) -> 0 | M9: =SUM('All Equity Scenario'!CW11:DH11) -> 0 | N9: =SUM('All Equity Scenario'!DI11:DT11) -> 0 | O9: ='All Equity Scenario'!DU11 -> 0
B10: Revenue | F10: =SUM('All Equity Scenario'!Q12:AB12) -> 0 | G10: =SUM('All Equity Scenario'!AC12:AN12) -> 0 | H10: =SUM('All Equity Scenario'!AO12:AZ12) -> 0 | I10: =SUM('All Equity Scenario'!BA12:BL12) -> 0 | J10: =SUM('All Equity Scenario'!BM12:BX12) -> 0 | K10: =SUM('All Equity Scenario'!BY12:CJ12) -> 0 | L10: =SUM('All Equity Scenario'!CK12:CV12) -> 0 | M10: =SUM('All Equity Scenario'!CW12:DH12) -> 0 | N10: =SUM('All Equity Scenario'!DI12:DT12) -> 0 | O10: ='All Equity Scenario'!DU12 -> 0
C11: Residual Payment | E11: =SUM('All Equity Scenario'!E13:P13) -> 7608078 | F11: =SUM('All Equity Scenario'!Q13:AB13) -> 6735515.6 | G11: =SUM('All Equity Scenario'!AC13:AN13) -> 5963026.5 | H11: =SUM('All Equity Scenario'!AO13:AZ13) -> 5279133.3 | I11: =SUM('All Equity Scenario'!BA13:BL13) -> 4673675.1 | J11: =SUM('All Equity Scenario'!BM13:BX13) -> 4137656.3 | K11: =SUM('All Equity Scenario'!BY13:CJ13) -> 3663112.9 | L11: =SUM('All Equity Scenario'!CK13:CV13) -> 3242994.4 | M11: =SUM('All Equity Scenario'!CW13:DH13) -> 2871058.8 | N11: =SUM('All Equity Scenario'!DI13:DT13) -> 2541780.1 | O11: ='All Equity Scenario'!DU13 -> 0
C12: Sale of Residuals | E12: =SUM('All Equity Scenario'!E16:P16) -> 0 | F12: =SUM('All Equity Scenario'!Q16:AB16) -> 0 | G12: =SUM('All Equity Scenario'!AC16:AN16) -> 0 | H12: =SUM('All Equity Scenario'!AO16:AZ16) -> 0 | I12: =SUM('All Equity Scenario'!BA16:BL16) -> 0 | J12: =SUM('All Equity Scenario'!BM16:BX16) -> 0 | K12: =SUM('All Equity Scenario'!BY16:CJ16) -> 0 | L12: =SUM('All Equity Scenario'!CK16:CV16) -> 0 | M12: =SUM('All Equity Scenario'!CW16:DH16) -> 0 | N12: =SUM('All Equity Scenario'!DI16:DT16) -> 0 | O12: ='All Equity Scenario'!DU16 -> 1201140
A13: x | B13: Total Revenue: | E13: =SUM(E11:E12) -> 7608078 | F13: =SUM(F11:F12) -> 6735515.6 | G13: =SUM(G11:G12) -> 5963026.5 | H13: =SUM(H11:H12) -> 5279133.3 | I13: =SUM(I11:I12) -> 4673675.1 | J13: =SUM(J11:J12) -> 4137656.3 | K13: =SUM(K11:K12) -> 3663112.9 | L13: =SUM(L11:L12) -> 3242994.4 | ... O13: =SUM(O11:O12) -> 1201140
B15: Waterfall Flow of Funds
C16: Management Fee | E16: =SUM('All Equity Scenario'!E22:P22) -> 0 | F16: =SUM('All Equity Scenario'!Q22:AB22) -> 0 | G16: =SUM('All Equity Scenario'!AC22:AN22) -> 0 | H16: =SUM('All Equity Scenario'!AO22:AZ22) -> 0 | I16: =SUM('All Equity Scenario'!BA22:BL22) -> 0 | J16: =SUM('All Equity Scenario'!BM22:BX22) -> 0 | K16: =SUM('All Equity Scenario'!BY22:CJ22) -> 0 | L16: =SUM('All Equity Scenario'!CK22:CV22) -> 0 | M16: =SUM('All Equity Scenario'!CW22:DH22) -> 0 | N16: =SUM('All Equity Scenario'!DI22:DT22) -> 0 | O16: ='All Equity Scenario'!DU22 -> 0
C17: Interest | E17: =SUM('All Equity Scenario'!E25:P25) -> 0 | F17: =SUM('All Equity Scenario'!Q25:AB25) -> 0 | G17: =SUM('All Equity Scenario'!AC25:AN25) -> 0 | H17: =SUM('All Equity Scenario'!AO25:AZ25) -> 0 | I17: =SUM('All Equity Scenario'!BA25:BL25) -> 0 | J17: =SUM('All Equity Scenario'!BM25:BX25) -> 0 | K17: =SUM('All Equity Scenario'!BY25:CJ25) -> 0 | L17: =SUM('All Equity Scenario'!CK25:CV25) -> 0 | M17: =SUM('All Equity Scenario'!CW25:DH25) -> 0 | N17: =SUM('All Equity Scenario'!DI25:DT25) -> 0 | O17: ='All Equity Scenario'!DU25 -> 0
C18: Debt Principal Payment | E18: =SUM('All Equity Scenario'!E28:P28) -> 0 | F18: =SUM('All Equity Scenario'!Q28:AB28) -> 0 | G18: =SUM('All Equity Scenario'!AC28:AN28) -> 0 | H18: =SUM('All Equity Scenario'!AO28:AZ28) -> 0 | I18: =SUM('All Equity Scenario'!BA28:BL28) -> 0 | J18: =SUM('All Equity Scenario'!BM28:BX28) -> 0 | K18: =SUM('All Equity Scenario'!BY28:CJ28) -> 0 | L18: =SUM('All Equity Scenario'!CK28:CV28) -> 0 | M18: =SUM('All Equity Scenario'!CW28:DH28) -> 0 | N18: =SUM('All Equity Scenario'!DI28:DT28) -> 0 | O18: ='All Equity Scenario'!DU28 -> 0
B20: Equity Distribution:
B21: LP | C21: Tusten | E21: =(SUM('All Equity Scenario'!E52:P52))*-1 -> -7608078 | F21: =(SUM('All Equity Scenario'!Q52:AB52))*-1 -> -6735515.6 | G21: =(SUM('All Equity Scenario'!AC52:AN52))*-1 -> -4862152.7 | H21: =(SUM('All Equity Scenario'!AO52:AZ52))*-1 -> -3959350 | I21: =(SUM('All Equity Scenario'!BA52:BL52))*-1 -> -3505256.4 | J21: =(SUM('All Equity Scenario'!BM52:BX52))*-1 -> -3103242.2 | K21: =(SUM('All Equity Scenario'!BY52:CJ52))*-1 -> -2747334.7 | L21: =(SUM('All Equity Scenario'!CK52:CV52))*-1 -> -2432245.8 | M21: =(SUM('All Equity Scenario'!CW52:DH52))*-1 -> -2153294.1 | N21: =(SUM('All Equity Scenario'!DI52:DT52))*-1 -> -1906335.1 | O21: =('All Equity Scenario'!DU52)*-1 -> -900855.02
B22: GP | C22: Processing | E22: =(SUM('All Equity Scenario'!E55:P55))*-1 -> 0 | F22: =(SUM('All Equity Scenario'!Q55:AB55))*-1 -> 0 | G22: =(SUM('All Equity Scenario'!AC55:AN55))*-1 -> -1100873.8 | H22: =(SUM('All Equity Scenario'!AO55:AZ55))*-1 -> -1319783.3 | I22: =(SUM('All Equity Scenario'!BA55:BL55))*-1 -> -1168418.8 | J22: =(SUM('All Equity Scenario'!BM55:BX55))*-1 -> -1034414.1 | K22: =(SUM('All Equity Scenario'!BY55:CJ55))*-1 -> -915778.23 | L22: =(SUM('All Equity Scenario'!CK55:CV55))*-1 -> -810748.59 | M22: =(SUM('All Equity Scenario'!CW55:DH55))*-1 -> -717764.7 | N22: =(SUM('All Equity Scenario'!DI55:DT55))*-1 -> -635445.03 | O22: =('All Equity Scenario'!DU55)*-1 -> -300285.01
E23: =SUM('All Equity Scenario'!E59:P59) -> 0 | F23: =SUM('All Equity Scenario'!Q59:AB59) -> 0 | G23: =SUM('All Equity Scenario'!AC59:AN59) -> 0 | H23: =SUM('All Equity Scenario'!AO59:AZ59) -> 0 | I23: =SUM('All Equity Scenario'!BA59:BL59) -> 0 | J23: =SUM('All Equity Scenario'!BM59:BX59) -> 0 | K23: =SUM('All Equity Scenario'!BY59:CJ59) -> 0 | L23: =SUM('All Equity Scenario'!CK59:CV59) -> 0 | M23: =SUM('All Equity Scenario'!CW59:DH59) -> 0 | N23: =SUM('All Equity Scenario'!DI59:DT59) -> 0 | O23: ='All Equity Scenario'!DU59 -> 0
A24: x | B24: Investment Balances | E24: =SUM('All Equity Scenario'!E67:P67) -> 0 | F24: =SUM('All Equity Scenario'!Q67:AB67) -> 0 | G24: =SUM('All Equity Scenario'!AC67:AN67) -> 0 | H24: =SUM('All Equity Scenario'!AO67:AZ67) -> 0 | I24: =SUM('All Equity Scenario'!BA67:BL67) -> 0 | J24: =SUM('All Equity Scenario'!BM67:BX67) -> 0 | K24: =SUM('All Equity Scenario'!BY67:CJ67) -> 0 | L24: =SUM('All Equity Scenario'!CK67:CV67) -> 0 | M24: =SUM('All Equity Scenario'!CW67:DH67) -> 0 | N24: =SUM('All Equity Scenario'!DI67:DT67) -> 0 | O24: ='All Equity Scenario'!DU67 -> 0
C25: Debt | E25: =MAX('All Equity Scenario'!D68:P68) -> 0 | F25: =MAX('All Equity Scenario'!Q68:AB68) -> 0 | G25: =MAX('All Equity Scenario'!AC68:AN68) -> 0 | H25: =MAX('All Equity Scenario'!AO68:AZ68) -> 0 | I25: =MAX('All Equity Scenario'!BA68:BL68) -> 0 | J25: =SUM('All Equity Scenario'!BM68:BX68) -> 0 | K25: =SUM('All Equity Scenario'!BY68:CJ68) -> 0 | L25: =SUM('All Equity Scenario'!CK68:CV68) -> 0 | M25: =SUM('All Equity Scenario'!CW68:DH68) -> 0 | N25: =SUM('All Equity Scenario'!DI68:DT68) -> 0 | O25: ='All Equity Scenario'!DU68 -> 0
B27: LP | C27: Cash Flow (Cumulative Actual) | E27: ='All Equity Scenario'!P60 -> -7231922 | F27: ='All Equity Scenario'!AB60 -> -496406.32 | G27: ='All Equity Scenario'!AN60 -> 4365746.4 | H27: ='All Equity Scenario'!AZ60 -> 8325096.4 | I27: ='All Equity Scenario'!BL60 -> 11830353 | J27: ='All Equity Scenario'!BX60 -> 14933595 | K27: ='All Equity Scenario'!CJ60 -> 17680930 | L27: ='All Equity Scenario'!CV60 -> 20113175 | M27: ='All Equity Scenario'!DH60 -> 22266470 | N27: ='All Equity Scenario'!DT60 -> 24172805 | O27: ='All Equity Scenario'!DU60 -> 25073660
B28: GP | C28: Equity Cash Flow (Cumulative actual) | E28: ='All Equity Scenario'!P63 -> 0 | F28: ='All Equity Scenario'!AB63 -> 0 | G28: ='All Equity Scenario'!AN63 -> 1100873.8 | H28: ='All Equity Scenario'!AZ63 -> 2420657.2 | I28: ='All Equity Scenario'!BL63 -> 3589075.9 | J28: ='All Equity Scenario'!BX63 -> 4623490 | K28: ='All Equity Scenario'!CJ63 -> 5539268.2 | L28: ='All Equity Scenario'!CV63 -> 6350016.8 | M28: ='All Equity Scenario'!DH63 -> 7067781.5 | N28: ='All Equity Scenario'!DT63 -> 7703226.6 | O28: ='All Equity Scenario'!DU63 -> 8003511.6
D30: 0 | E30: =D30+1 -> 1 | F30: =E30+1 -> 2 | G30: =F30+1 -> 3 | H30: =G30+1 -> 4 | I30: =H30+1 -> 5 | J30: =I30+1 -> 6 | K30: =J30+1 -> 7 | L30: =K30+1 -> 8 | ... O30: =N30+1 -> 11
C31: LP Tusten | E31: Year 1 | F31: Year 2 | G31: Year 3 | H31: Year 4 | I31: Year 5 | J31: Year 6 | K31: Year 7 | L31: Year 8 | M31: Year 9 | N31: Year 10 | O31: Sale of Investment
C33: Initial Cash Flow: | D33: =-'All Equity Scenario'!D35 -> -14840000
C34: Deferred Purchase Price: | E34: ='All Equity Scenario'!K7*(1-Assumptions!$E$23)+'All Equity Scenario'!K8*(1-Assumptions!$F$23) -> 0 | F34: ='All Equity Scenario'!Q7*(1-Assumptions!$E$23)+'All Equity Scenario'!Q8*(1-Assumptions!$F$23) -> 0 | G34: ='All Equity Scenario'!AC7*(1-Assumptions!$E$23)+'All Equity Scenario'!AC8*(1-Assumptions!$F$23) -> 0 | H34: ='All Equity Scenario'!AO7*(1-Assumptions!$E$23)+'All Equity Scenario'!AO8*(1-Assumptions!$F$23) -> 0
C35: Cash Flows: | E35: =-E21 -> 7608078 | F35: =-F21 -> 6735515.6 | G35: =-G21 -> 4862152.7 | H35: =-H21 -> 3959350 | I35: =-I21 -> 3505256.4 | J35: =-J21 -> 3103242.2 | K35: =-K21 -> 2747334.7 | L35: =-L21 -> 2432245.8 | ... O35: =-O21 -> 900855.02
C36: Total Cash Flow: | D36: =SUM(D33:D35) -> -14840000 | E36: =SUM(E34:E35) -> 7608078 | F36: =SUM(F34:F35) -> 6735515.6 | G36: =SUM(G34:G35) -> 4862152.7 | H36: =SUM(H34:H35) -> 3959350 | I36: =SUM(I34:I35) -> 3505256.4 | J36: =SUM(J34:J35) -> 3103242.2 | K36: =SUM(K34:K35) -> 2747334.7 | L36: =SUM(L34:L35) -> 2432245.8 | ... O36: =SUM(O34:O35) -> 900855.02
C38: LP Tusten
C39: Equity Distribution: | D39: =O27 -> 25073660
C40: Payback: | D40: =LOOKUP(0,D50:O50,D30:O30-D50:O50/E36:O36) -> 2.102096
C41: IRR: | D41: =IRR(D36:O36) -> 0.34229387
C42: MOIC: | D42: =(O27-D36)/-D33 -> 2.6895997
C44: GP Processing
C45: Equity Distribution: | D45: =O28 -> 8003511.6
C46: Management Fee: | D46: =-SUM(E16:O16) -> 0
C47: Total Cash Flow: | D47: =SUM(D45:D46) -> 8003511.6
C50: Cumulatice cash flows: | D50: =D36 -> -14840000 | E50: =D50+E36 -> -7231922 | F50: =E50+F36 -> -496406.32 | G50: =F50+G36 -> 4365746.4 | H50: =G50+H36 -> 8325096.4 | I50: =H50+I36 -> 11830353 | J50: =I50+J36 -> 14933595 | K50: =J50+K36 -> 17680930 | L50: =K50+L36 -> 20113175 | ... O50: =N50+O36 -> 25073660
...

Sheet 50% Equity Scenario
D2: 0 | E2: 1 | F2: 2 | G2: 3 | H2: 4 | I2: 5 | J2: 6 | K2: 7 | L2: 8 | M2: 9 | N2: 10 | O2: 11 | P2: 12 | Q2: 13 | R2: 14 | S2: 15 | T2: 16 | U2: 17 | V2: 18 | W2: 19 | X2: 20 | Y2: 21 | Z2: 22 | AA2: 23 | AB2: 24 | AC2: 25 | AD2: 26 | AE2: 27 | AF2: 28 | AG2: 29 | AH2: 30 | AI2: 31 | AJ2: 32 | AK2: 33 | AL2: 34 | AM2: 35 | AN2: 36 | AO2: 37 | AP2: 38 | AQ2: 39 | AR2: 40 | AS2: 41 | AT2: 42 | AU2: 43 | AV2: 44 | AW2: 45 | AX2: 46 | AY2: 47 | AZ2: 48 | BA2: 49 | BB2: 50 | BC2: 51 | BD2: 52 | BE2: 53 | BF2: 54 | BG2: 55 | BH2: 56 | BI2: 57 | BJ2: 58 | BK2: 59 | BL2: 60 | BM2: 61 | BN2: 62 | BO2: 63 | BP2: 64 | BQ2: 65 | BR2: 66 | BS2: 67 | BT2: 68 | BU2: 69 | BV2: 70 | BW2: 71 | BX2: 72 | BY2: 73 | BZ2: 74 | CA2: 75 | CB2: 76 | CC2: 77 | CD2: 78 | CE2: 79 | CF2: 80 | CG2: 81 | CH2: 82 | CI2: 83 | CJ2: 84 | CK2: 85 | CL2: 86 | CM2: 87 | CN2: 88 | CO2: 89 | CP2: 90 | CQ2: 91 | CR2: 92 | CS2: 93 | CT2: 94 | CU2: 95 | CV2: 96 | CW2: 97 | CX2: 98 | CY2: 99 | CZ2: 100 | DA2: 101 | DB2: 102 | DC2: 103 | DD2: 104 | DE2: 105 | DF2: 106 | DG2: 107 | DH2: 108 | DI2: 109 | DJ2: 110 | DK2: 111 | DL2: 112 | DM2: 113 | DN2: 114 | DO2: 115 | DP2: 116 | DQ2: 117 | DR2: 118 | DS2: 119 | DT2: 120 | DU2: 121
A4: x | B4: Uses
C5: Initial Purchase Price | D5: =-Assumptions!K6*Assumptions!K7+-Assumptions!L6*Assumptions!L7 -> -14740000
C6: Deferred Purchase Price | K6: =SUM(K7:K8) -> 0 | Q6: =SUM(Q7:Q8) -> 0 | AC6: =SUM(AC7:AC8) -> 0 | AO6: =SUM(AO7:AO8) -> 0
B7: =Assumptions!K6/SUM(Assumptions!K6:L6) -> 0.89552239 | C7: P1 | K7: =IF(Assumptions!K15>Assumptions!K13,0,-Assumptions!K6*Assumptions!K9) -> 0 | Q7: =IF(Assumptions!K16>Assumptions!K13,0,-Assumptions!K6*Assumptions!K10) -> 0 | AC7: =IF(Assumptions!K17>Assumptions!K13,0,-Assumptions!K6*Assumptions!K11) -> 0 | AO7: =IF(Assumptions!K18>Assumptions!K13,0,-Assumptions!K6*Assumptions!K12) -> 0
B8: =1-B7 -> 0.10447761 | C8: P2 | K8: =+IF(Assumptions!L15>Assumptions!L13,0,-Assumptions!L6*Assumptions!L9) -> 0 | Q8: =+IF(Assumptions!L16>Assumptions!L13,0,-Assumptions!L6*Assumptions!L10) -> 0 | AC8: =IF(Assumptions!L17>Assumptions!L13,0,-Assumptions!L6*Assumptions!L11) -> 0 | AO8: =+IF(Assumptions!L18>Assumptions!L13,0,-Assumptions!L6*Assumptions!L12) -> 0
C9: Legal and Closing Costs | D9: =-Assumptions!K28-Assumptions!L28 -> -100000
A10: x | B10: Total Uses: | D10: =SUM(D5:D9) -> -14840000 | E10: =E6+E5+E9 -> 0 | F10: =F6+F5+F9 -> 0 | G10: =G6+G5+G9 -> 0 | H10: =H6+H5+H9 -> 0 | I10: =I6+I5+I9 -> 0 | J10: =J6+J5+J9 -> 0 | K10: =K6+K5+K9 -> 0 | L10: =L6+L5+L9 -> 0 | ... DU10: =DU6+DU5+DU9 -> 0
B12: Revenue
C13: Residual Payment | E13: =SUM(E14:E15) -> 670000 | F13: =SUM(F14:F15) -> 663233 | G13: =SUM(G14:G15) -> 656534.35 | H13: =SUM(H14:H15) -> 649903.35 | I13: =SUM(I14:I15) -> 643339.33 | J13: =SUM(J14:J15) -> 636841.6 | K13: =SUM(K14:K15) -> 630409.5 | L13: =SUM(L14:L15) -> 624042.36 | ... DT13: =SUM(DT14:DT15) -> 200190
C14: P1 | E14: =Assumptions!K6 -> 600000 | F14: =E14*(1-Assumptions!$K$16) -> 593940 | G14: =F14*(1-Assumptions!$K$16) -> 587941.21 | H14: =G14*(1-Assumptions!$K$16) -> 582003 | I14: =H14*(1-Assumptions!$K$16) -> 576124.77 | J14: =I14*(1-Assumptions!$K$16) -> 570305.91 | K14: =J14*(1-Assumptions!$K$16) -> 564545.82 | L14: =K14*(1-Assumptions!$K$16) -> 558843.91 | M14: =L14*(1-Assumptions!$K$16) -> 553199.58 | ... P14: =O14*(1-Assumptions!$K$16) -> 536606.36 | Q14: =P14*(1-Assumptions!$K$17) -> 531186.64 | R14: =Q14*(1-Assumptions!$K$17) -> 525821.65 | S14: =R14*(1-Assumptions!$K$17) -> 520510.85 | T14: =S14*(1-Assumptions!$K$17) -> 515253.69 | U14: =T14*(1-Assumptions!$K$17) -> 510049.63 | V14: =U14*(1-Assumptions!$K$17) -> 504898.13 | W14: =V14*(1-Assumptions!$K$17) -> 499798.66 | X14: =W14*(1-Assumptions!$K$17) -> 494750.69 | ... AB14: =AA14*(1-Assumptions!$K$17) -> 475063.55 | AC14: =AB14*(1-Assumptions!$K$18) -> 470265.41 | AD14: =AC14*(1-Assumptions!$K$18) -> 465515.73 | AE14: =AD14*(1-Assumptions!$K$18) -> 460814.02 | AF14: =AE14*(1-Assumptions!$K$18) -> 456159.8 | AG14: =AF14*(1-Assumptions!$K$18) -> 451552.58 | AH14: =AG14*(1-Assumptions!$K$18) -> 446991.9 | AI14: =AH14*(1-Assumptions!$K$18) -> 442477.28 | AJ14: =AI14*(1-Assumptions!$K$18) -> 438008.26 | ... AN14: =AM14*(1-Assumptions!$K$18) -> 420579.01 | AO14: =AN14*(1-Assumptions!$K$19) -> 416331.17 | AP14: =AO14*(1-Assumptions!$K$19) -> 412126.22 | AQ14: =AP14*(1-Assumptions!$K$19) -> 407963.75 | AR14: =AQ14*(1-Assumptions!$K$19) -> 403843.31 | AS14: =AR14*(1-Assumptions!$K$19) -> 399764.5 | AT14: =AS14*(1-Assumptions!$K$19) -> 395726.87 | AU14: =AT14*(1-Assumptions!$K$19) -> 391730.03 | AV14: =AU14*(1-Assumptions!$K$19) -> 387773.56 | ... DT14: =DS14*(1-Assumptions!$K$19) -> 179274.63
C15: P2 | E15: =Assumptions!L6 -> 70000 | F15: =E15*(1-Assumptions!$L$16) -> 69293 | G15: =F15*(1-Assumptions!$L$16) -> 68593.141 | H15: =G15*(1-Assumptions!$L$16) -> 67900.35 | I15: =H15*(1-Assumptions!$L$16) -> 67214.556 | J15: =I15*(1-Assumptions!$L$16) -> 66535.689 | K15: =J15*(1-Assumptions!$L$16) -> 65863.679 | L15: =K15*(1-Assumptions!$L$16) -> 65198.456 | M15: =L15*(1-Assumptions!$L$16) -> 64539.951 | ... P15: =O15*(1-Assumptions!$L$16) -> 62604.076 | Q15: =P15*(1-Assumptions!$L$17) -> 61971.774 | R15: =Q15*(1-Assumptions!$L$17) -> 61345.859 | S15: =R15*(1-Assumptions!$L$17) -> 60726.266 | T15: =S15*(1-Assumptions!$L$17) -> 60112.931 | U15: =T15*(1-Assumptions!$L$17) -> 59505.79 | V15: =U15*(1-Assumptions!$L$17) -> 58904.782 | W15: =V15*(1-Assumptions!$L$17) -> 58309.844 | X15: =W15*(1-Assumptions!$L$17) -> 57720.914 | ... AB15: =AA15*(1-Assumptions!$L$17) -> 55424.081 | AC15: =AB15*(1-Assumptions!$L$18) -> 54864.297 | AD15: =AC15*(1-Assumptions!$L$18) -> 54310.168 | AE15: =AD15*(1-Assumptions!$L$18) -> 53761.635 | AF15: =AE15*(1-Assumptions!$L$18) -> 53218.643 | AG15: =AF15*(1-Assumptions!$L$18) -> 52681.135 | AH15: =AG15*(1-Assumptions!$L$18) -> 52149.055 | AI15: =AH15*(1-Assumptions!$L$18) -> 51622.35 | AJ15: =AI15*(1-Assumptions!$L$18) -> 51100.964 | ... AN15: =AM15*(1-Assumptions!$L$18) -> 49067.552 | AO15: =AN15*(1-Assumptions!$L$19) -> 48571.969 | AP15: =AO15*(1-Assumptions!$L$19) -> 48081.393 | AQ15: =AP15*(1-Assumptions!$L$19) -> 47595.77 | AR15: =AQ15*(1-Assumptions!$L$19) -> 47115.053 | AS15: =AR15*(1-Assumptions!$L$19) -> 46639.191 | AT15: =AS15*(1-Assumptions!$L$19) -> 46168.135 | AU15: =AT15*(1-Assumptions!$L$19) -> 45701.837 | AV15: =AU15*(1-Assumptions!$L$19) -> 45240.249 | ... DT15: =DS15*(1-Assumptions!$L$19) -> 20915.374
C16: Sale of Residuals | E16: =SUM(E17:E18) -> 0 | F16: =SUM(F17:F18) -> 0 | G16: =SUM(G17:G18) -> 0 | H16: =SUM(H17:H18) -> 0 | I16: =SUM(I17:I18) -> 0 | J16: =SUM(J17:J18) -> 0 | K16: =SUM(K17:K18) -> 0 | L16: =SUM(L17:L18) -> 0 | ... DU16: =SUM(DU17:DU18) -> 1201140
C17: P1 | DU17: =DT14*Assumptions!K35 -> 1075647.8
C18: P2 | DU18: =DT15*Assumptions!L35 -> 125492.24
A19: x | E19: =E16+E13 -> 670000 | F19: =F16+F13 -> 663233 | G19: =G16+G13 -> 656534.35 | H19: =H16+H13 -> 649903.35 | I19: =I16+I13 -> 643339.33 | J19: =J16+J13 -> 636841.6 | K19: =K16+K13 -> 630409.5 | L19: =L16+L13 -> 624042.36 | ... DU19: =DU16+DU13 -> 1201140
A21: x | B21: Waterfall Flow of Funds
C22: Management Fee | E22: =SUM(E23:E24) -> 0 | F22: =SUM(F23:F24) -> 0 | G22: =SUM(G23:G24) -> 0 | H22: =SUM(H23:H24) -> 0 | I22: =SUM(I23:I24) -> 0 | J22: =SUM(J23:J24) -> 0 | K22: =SUM(K23:K24) -> 0 | L22: =SUM(L23:L24) -> 0 | ... DU22: =SUM(DU23:DU24) -> 0
C23: P1 | E23: =-(E14+E17)*Assumptions!$K$30 -> 0 | F23: =-(F14+F17)*Assumptions!$K$30 -> 0 | G23: =-(G14+G17)*Assumptions!$K$30 -> 0 | H23: =-(H14+H17)*Assumptions!$K$30 -> 0 | I23: =-(I14+I17)*Assumptions!$K$30 -> 0 | J23: =-(J14+J17)*Assumptions!$K$30 -> 0 | K23: =-(K14+K17)*Assumptions!$K$30 -> 0 | L23: =-(L14+L17)*Assumptions!$K$30 -> 0 | ... DU23: =-(DU14+DU17)*Assumptions!$K$30 -> 0
C24: P2 | E24: =-(E15+E18)*Assumptions!$L$30 -> 0 | F24: =-(F15+F18)*Assumptions!$L$30 -> 0 | G24: =-(G15+G18)*Assumptions!$L$30 -> 0 | H24: =-(H15+H18)*Assumptions!$L$30 -> 0 | I24: =-(I15+I18)*Assumptions!$L$30 -> 0 | J24: =-(J15+J18)*Assumptions!$L$30 -> 0 | K24: =-(K15+K18)*Assumptions!$L$30 -> 0 | L24: =-(L15+L18)*Assumptions!$L$30 -> 0 | ... DU24: =-(DU15+DU18)*Assumptions!$L$30 -> 0
B25: Cash Available for Equity Investors | E25: =SUM(E26:E27) -> 670000 | F25: =SUM(F26:F27) -> 663233 | G25: =SUM(G26:G27) -> 656534.35 | H25: =SUM(H26:H27) -> 649903.35 | I25: =SUM(I26:I27) -> 643339.33 | J25: =SUM(J26:J27) -> 636841.6 | K25: =SUM(K26:K27) -> 630409.5 | L25: =SUM(L26:L27) -> 624042.36 | ... DU25: =SUM(DU26:DU27) -> 1201140
C26: P1 | E26: =E14+E17+E23 -> 600000 | F26: =F14+F17+F23 -> 593940 | G26: =G14+G17+G23 -> 587941.21 | H26: =H14+H17+H23 -> 582003 | I26: =I14+I17+I23 -> 576124.77 | J26: =J14+J17+J23 -> 570305.91 | K26: =K14+K17+K23 -> 564545.82 | L26: =L14+L17+L23 -> 558843.91 | ... DU26: =DU14+DU17+DU23 -> 1075647.8
C27: P2 | E27: =E15+E18+E24 -> 70000 | F27: =F15+F18+F24 -> 69293 | G27: =G15+G18+G24 -> 68593.141 | H27: =H15+H18+H24 -> 67900.35 | I27: =I15+I18+I24 -> 67214.556 | J27: =J15+J18+J24 -> 66535.689 | K27: =K15+K18+K24 -> 65863.679 | L27: =L15+L18+L24 -> 65198.456 | ... DU27: =DU15+DU18+DU24 -> 125492.24
B28: LP Share (% of total cash) | E28: =E26*Assumptions!$K$32+E27*Assumptions!$L$32 -> 335000 | F28: =F26*Assumptions!$K$32+F27*Assumptions!$L$32 -> 331616.5 | G28: =G26*Assumptions!$K$32+G27*Assumptions!$L$32 -> 328267.17 | H28: =H26*Assumptions!$K$32+H27*Assumptions!$L$32 -> 324951.67 | I28: =I26*Assumptions!$K$32+I27*Assumptions!$L$32 -> 321669.66 | J28: =J26*Assumptions!$K$32+J27*Assumptions!$L$32 -> 318420.8 | K28: =K26*Assumptions!$K$32+K27*Assumptions!$L$32 -> 315204.75 | L28: =L26*Assumptions!$K$32+L27*Assumptions!$L$32 -> 312021.18 | ... DU28: =DU26*Assumptions!$K$32+DU27*Assumptions!$L$32 -> 600570.01
B29: GP Share before Debt Sweep (% of total cash) | E29: =E26*Assumptions!$K$33+'50% Equity Scenario'!E27*Assumptions!$L$33 -> 335000 | F29: =F26*Assumptions!$K$33+'50% Equity Scenario'!F27*Assumptions!$L$33 -> 331616.5 | G29: =G26*Assumptions!$K$33+'50% Equity Scenario'!G27*Assumptions!$L$33 -> 328267.17 | H29: =H26*Assumptions!$K$33+'50% Equity Scenario'!H27*Assumptions!$L$33 -> 324951.67 | I29: =I26*Assumptions!$K$33+'50% Equity Scenario'!I27*Assumptions!$L$33 -> 321669.66 | J29: =J26*Assumptions!$K$33+'50% Equity Scenario'!J27*Assumptions!$L$33 -> 318420.8 | K29: =K26*Assumptions!$K$33+'50% Equity Scenario'!K27*Assumptions!$L$33 -> 315204.75 | L29: =L26*Assumptions!$K$33+'50% Equity Scenario'!L27*Assumptions!$L$33 -> 312021.18 | ... DU29: =DU26*Assumptions!$K$33+'50% Equity Scenario'!DU27*Assumptions!$L$33 -> 600570.01
B31: Interest Paid from GP Pool (cap at pool) | E31: =-MIN(-E43,E29) -> -85983.333 | F31: =-MIN(-F43,F29) -> -83078.139 | G31: =-MIN(-G43,G29) -> -80178.525 | H31: =-MIN(-H43,H29) -> -77284.157 | I31: =-MIN(-I43,I29) -> -74394.703 | J31: =-MIN(-J43,J29) -> -71509.828 | K31: =-MIN(-K43,K29) -> -68629.2 | L31: =-MIN(-L43,L29) -> -65752.485 | ... DU31: =-MIN(-DU43,DU29) -> 0
B32: Interest Paid to P1 (pro‑rata) | E32: =IF(E$31=0,0,E$31*E44/E43) -> -77000 | F32: =IF(F$31=0,0,F$31*F44/F43) -> -74398.333 | G32: =IF(G$31=0,0,G$31*G44/G43) -> -71801.664 | H32: =IF(H$31=0,0,H$31*H44/H43) -> -69209.693 | I32: =IF(I$31=0,0,I$31*I44/I43) -> -66622.122 | J32: =IF(J$31=0,0,J$31*J44/J43) -> -64038.652 | K32: =IF(K$31=0,0,K$31*K44/K43) -> -61458.985 | L32: =IF(L$31=0,0,L$31*L44/L43) -> -58882.823 | ... DU32: =IF(DU$31=0,0,DU$31*DU44/DU43) -> 0
B33: Interest Paid to P2 (pro‑rata) | E33: =IF(E$31=0,0,E$31*E45/E43) -> -8983.3333 | F33: =IF(F$31=0,0,F$31*F45/F43) -> -8679.8056 | G33: =IF(G$31=0,0,G$31*G45/G43) -> -8376.8608 | H33: =IF(H$31=0,0,H$31*H45/H43) -> -8074.4642 | I33: =IF(I$31=0,0,I$31*I45/I43) -> -7772.5809 | J33: =IF(J$31=0,0,J$31*J45/J43) -> -7471.1761 | K33: =IF(K$31=0,0,K$31*K45/K43) -> -7170.2149 | L33: =IF(L$31=0,0,L$31*L45/L43) -> -6869.6627 | ... DU33: =IF(DU$31=0,0,DU$31*DU45/DU43) -> 0
B34: Pool After Interest | E34: =E29+E31 -> 249016.67 | F34: =F29+F31 -> 248538.36 | G34: =G29+G31 -> 248088.65 | H34: =H29+H31 -> 247667.52 | I34: =I29+I31 -> 247274.96 | J34: =J29+J31 -> 246910.97 | K34: =K29+K31 -> 246575.55 | L34: =L29+L31 -> 246268.7 | ... DU34: =DU29+DU31 -> 600570.01
B35: Scheduled Principal Paid from Pool | E35: =-MIN(E34,-E46) -> -249016.67 | F35: =-MIN(F34,-F46) -> -248538.36 | G35: =-MIN(G34,-G46) -> -248088.65 | H35: =-MIN(H34,-H46) -> -247667.52 | I35: =-MIN(I34,-I46) -> -247274.96 | J35: =-MIN(J34,-J46) -> -246910.97 | K35: =-MIN(K34,-K46) -> -246575.55 | L35: =-MIN(L34,-L46) -> -246268.7 | ... DU35: =-MIN(DU34,-DU46) -> 0
B36: P1 Scheduled Principal Paid (pro‑rata) | E36: =IF(E46=0,0,E$35*E47/E$46) -> -223000 | F36: =IF(F46=0,0,F$35*F47/F$46) -> -222571.67 | G36: =IF(G46=0,0,G$35*G47/G$46) -> -222168.94 | H36: =IF(H46=0,0,H$35*H47/H$46) -> -221791.81 | I36: =IF(I46=0,0,I$35*I47/I$46) -> -221440.26 | J36: =IF(J46=0,0,J$35*J47/J$46) -> -221114.3 | K36: =IF(K46=0,0,K$35*K47/K$46) -> -220813.92 | L36: =IF(L46=0,0,L$35*L47/L$46) -> -220539.13 | ... DU36: =IF(DU46=0,0,DU$35*DU47/DU$46) -> 0
B37: P2 Scheduled Principal Paid (pro‑rata) | E37: =IF(E47=0,0,E$35*E48/E$46) -> -26016.667 | F37: =IF(F47=0,0,F$35*F48/F$46) -> -25966.694 | G37: =IF(G47=0,0,G$35*G48/G$46) -> -25919.71 | H37: =IF(H47=0,0,H$35*H48/H$46) -> -25875.711 | I37: =IF(I47=0,0,I$35*I48/I$46) -> -25834.697 | J37: =IF(J47=0,0,J$35*J48/J$46) -> -25796.669 | K37: =IF(K47=0,0,K$35*K48/K$46) -> -25761.625 | L37: =IF(L47=0,0,L$35*L48/L$46) -> -25729.565 | ... DU37: =IF(DU47=0,0,DU$35*DU48/DU$46) -> 0
B38: Pool After Sch. Principal | E38: =E34+E35 -> 0 | F38: =F34+F35 -> 0 | G38: =G34+G35 -> 0 | H38: =H34+H35 -> 0 | I38: =I34+I35 -> 0 | J38: =J34+J35 -> 0 | K38: =K34+K35 -> 0 | L38: =L34+L35 -> 0 | ... DU38: =DU34+DU35 -> 600570.01
B39: Extra Prepayment to P1 | E39: =IF(MAX(E67+E36,0)>=MAX(E68+E37,0), MIN(E38,MAX(E67+E36,0)), MAX(E38-MAX(E68+E37,0),0)) -> 0 | F39: =IF(MAX(F67+F36,0)>=MAX(F68+F37,0), MIN(F38,MAX(F67+F36,0)), MAX(F38-MAX(F68+F37,0),0)) -> 0 | G39: =IF(MAX(G67+G36,0)>=MAX(G68+G37,0), MIN(G38,MAX(G67+G36,0)), MAX(G38-MAX(G68+G37,0),0)) -> 0 | H39: =IF(MAX(H67+H36,0)>=MAX(H68+H37,0), MIN(H38,MAX(H67+H36,0)), MAX(H38-MAX(H68+H37,0),0)) -> 0 | I39: =IF(MAX(I67+I36,0)>=MAX(I68+I37,0), MIN(I38,MAX(I67+I36,0)), MAX(I38-MAX(I68+I37,0),0)) -> 0 | J39: =IF(MAX(J67+J36,0)>=MAX(J68+J37,0), MIN(J38,MAX(J67+J36,0)), MAX(J38-MAX(J68+J37,0),0)) -> 0 | K39: =IF(MAX(K67+K36,0)>=MAX(K68+K37,0), MIN(K38,MAX(K67+K36,0)), MAX(K38-MAX(K68+K37,0),0)) -> 0 | L39: =IF(MAX(L67+L36,0)>=MAX(L68+L37,0), MIN(L38,MAX(L67+L36,0)), MAX(L38-MAX(L68+L37,0),0)) -> 0 | ... DU39: =IF(MAX(DU67+DU36,0)>=MAX(DU68+DU37,0), MIN(DU38,MAX(DU67+DU36,0)), MAX(DU38-MAX(DU68+DU37,0),0)) -> 0
B40: Extra Prepayment to P2 | E40: =IF(MAX(E68+E37,0)>=MAX(E67+E36,0), MIN(E38,MAX(E68+E37,0)), MAX(E38-MAX(E67+E36,0),0)) -> 0 | F40: =IF(MAX(F68+F37,0)>=MAX(F67+F36,0), MIN(F38,MAX(F68+F37,0)), MAX(F38-MAX(F67+F36,0),0)) -> 0 | G40: =IF(MAX(G68+G37,0)>=MAX(G67+G36,0), MIN(G38,MAX(G68+G37,0)), MAX(G38-MAX(G67+G36,0),0)) -> 0 | H40: =IF(MAX(H68+H37,0)>=MAX(H67+H36,0), MIN(H38,MAX(H68+H37,0)), MAX(H38-MAX(H67+H36,0),0)) -> 0 | I40: =IF(MAX(I68+I37,0)>=MAX(I67+I36,0), MIN(I38,MAX(I68+I37,0)), MAX(I38-MAX(I67+I36,0),0)) -> 0 | J40: =IF(MAX(J68+J37,0)>=MAX(J67+J36,0), MIN(J38,MAX(J68+J37,0)), MAX(J38-MAX(J67+J36,0),0)) -> 0 | K40: =IF(MAX(K68+K37,0)>=MAX(K67+K36,0), MIN(K38,MAX(K68+K37,0)), MAX(K38-MAX(K67+K36,0),0)) -> 0 | L40: =IF(MAX(L68+L37,0)>=MAX(L67+L36,0), MIN(L38,MAX(L68+L37,0)), MAX(L38-MAX(L67+L36,0),0)) -> 0 | ... DU40: =IF(MAX(DU68+DU37,0)>=MAX(DU67+DU36,0), MIN(DU38,MAX(DU68+DU37,0)), MAX(DU38-MAX(DU67+DU36,0),0)) -> 0
B42: Debt Service:
C43: Interest Payment Due | E43: =SUM(E44:E45) -> -85983.333 | F43: =SUM(F44:F45) -> -83078.139 | G43: =SUM(G44:G45) -> -80178.525 | H43: =SUM(H44:H45) -> -77284.157 | I43: =SUM(I44:I45) -> -74394.703 | J43: =SUM(J44:J45) -> -71509.828 | K43: =SUM(K44:K45) -> -68629.2 | L43: =SUM(L44:L45) -> -65752.485 | ... DU43: =SUM(DU44:DU45) -> 0
C44: P1 | E44: =-D67*(Assumptions!$K$22/12) -> -77000 | F44: =-E67*(Assumptions!$K$22/12) -> -74398.333 | G44: =-F67*(Assumptions!$K$22/12) -> -71801.664 | H44: =-G67*(Assumptions!$K$22/12) -> -69209.693 | I44: =-H67*(Assumptions!$K$22/12) -> -66622.122 | J44: =-I67*(Assumptions!$K$22/12) -> -64038.652 | K44: =-J67*(Assumptions!$K$22/12) -> -61458.985 | L44: =-K67*(Assumptions!$K$22/12) -> -58882.823 | ... DU44: =-DT67*(Assumptions!$K$22/12) -> 0
C45: P2 | E45: =-D68*(Assumptions!$L$22/12) -> -8983.3333 | F45: =-E68*(Assumptions!$L$22/12) -> -8679.8056 | G45: =-F68*(Assumptions!$L$22/12) -> -8376.8608 | H45: =-G68*(Assumptions!$L$22/12) -> -8074.4642 | I45: =-H68*(Assumptions!$L$22/12) -> -7772.5809 | J45: =-I68*(Assumptions!$L$22/12) -> -7471.1761 | K45: =-J68*(Assumptions!$L$22/12) -> -7170.2149 | L45: =-K68*(Assumptions!$L$22/12) -> -6869.6627 | ... DU45: =-DT68*(Assumptions!$L$22/12) -> 0
C46: Debt Principal Payment Due | E46: =SUM(E47:E48) -> -249016.67 | F46: =SUM(F47:F48) -> -248538.36 | G46: =SUM(G47:G48) -> -248088.65 | H46: =SUM(H47:H48) -> -247667.52 | I46: =SUM(I47:I48) -> -247274.96 | J46: =SUM(J47:J48) -> -246910.97 | K46: =SUM(K47:K48) -> -246575.55 | L46: =SUM(L47:L48) -> -246268.7 | ... DU46: =SUM(DU47:DU48) -> 0
...

Sheet Summary (50% Equity)
E2: Year 1 | F2: Year 2 | G2: Year 3 | H2: Year 4 | I2: Year 5 | J2: Year 6 | K2: Year 7 | L2: Year 8 | M2: Year 9 | N2: Year 10 | O2: Sale of Investment
E3: Months 1-12 | F3: Months 13-24 | G3: Months 25-36 | H3: Months 37-48 | I3: Months 49-60 | J3: Months 61-72 | K3: Months 73-84 | L3: Months 85-96 | M3: Months 97-108 | N3: Months 109-120 | O3: Month 121
B4: Uses
C5: Initial Purchase Price | D5: ='50% Equity Scenario'!D5 -> -14740000 | E5: =SUM('50% Equity Scenario'!E5:P5) -> 0 | F5: =SUM('50% Equity Scenario'!Q5:AB5) -> 0 | G5: =SUM('50% Equity Scenario'!AC5:AN5) -> 0 | H5: =SUM('50% Equity Scenario'!AO5:AZ5) -> 0 | I5: =SUM('50% Equity Scenario'!BA5:BL5) -> 0 | J5: =SUM('50% Equity Scenario'!BM5:BX5) -> 0 | K5: =SUM('50% Equity Scenario'!BY5:CJ5) -> 0 | L5: =SUM('50% Equity Scenario'!CK5:CV5) -> 0 | M5: =SUM('50% Equity Scenario'!CW5:DH5) -> 0 | N5: =SUM('50% Equity Scenario'!DI5:DT5) -> 0 | O5: ='50% Equity Scenario'!DU5 -> 0
C6: Deferred Purchase Price | D6: ='50% Equity Scenario'!D6 -> 0 | E6: =SUM('50% Equity Scenario'!E6:P6) -> 0 | F6: =SUM('50% Equity Scenario'!Q6:AB6) -> 0 | G6: =SUM('50% Equity Scenario'!AC6:AN6) -> 0 | H6: =SUM('50% Equity Scenario'!AO6:AZ6) -> 0 | I6: =SUM('50% Equity Scenario'!BA6:BL6) -> 0 | J6: =SUM('50% Equity Scenario'!BM6:BX6) -> 0 | K6: =SUM('50% Equity Scenario'!BY6:CJ6) -> 0 | L6: =SUM('50% Equity Scenario'!CK6:CV6) -> 0 | M6: =SUM('50% Equity Scenario'!CW6:DH6) -> 0 | N6: =SUM('50% Equity Scenario'!DI6:DT6) -> 0 | O6: ='50% Equity Scenario'!DU6 -> 0
C7: Legal and Accounting | D7: ='50% Equity Scenario'!D9 -> -100000 | E7: =SUM('50% Equity Scenario'!E9:P9) -> 0 | F7: =SUM('50% Equity Scenario'!Q9:AB9) -> 0 | G7: =SUM('50% Equity Scenario'!AC9:AN9) -> 0 | H7: =SUM('50% Equity Scenario'!AO9:AZ9) -> 0 | I7: =SUM('50% Equity Scenario'!BA9:BL9) -> 0 | J7: =SUM('50% Equity Scenario'!BM9:BX9) -> 0 | K7: =SUM('50% Equity Scenario'!BY9:CJ9) -> 0 | L7: =SUM('50% Equity Scenario'!CK9:CV9) -> 0 | M7: =SUM('50% Equity Scenario'!CW9:DH9) -> 0 | N7: =SUM('50% Equity Scenario'!DI9:DT9) -> 0 | O7: ='50% Equity Scenario'!DU9 -> 0
A8: x | B8: Total Uses: | D8: =SUM(D5:D7) -> -14840000 | E8: =SUM(E5:E7) -> 0 | F8: =SUM(F5:F7) -> 0 | G8: =SUM(G5:G7) -> 0 | H8: =SUM(H5:H7) -> 0 | I8: =SUM(I5:I7) -> 0 | J8: =SUM(J5:J7) -> 0 | K8: =SUM(K5:K7) -> 0 | ... O8: =SUM(O5:O7) -> 0 | Q8: =SUM(Q5:Q7) -> 0 | R8: =SUM(R5:R7) -> 0
F9: =SUM('50% Equity Scenario'!Q11:AB11) -> 0 | G9: =SUM('50% Equity Scenario'!AC11:AN11) -> 0 | H9: =SUM('50% Equity Scenario'!AO11:AZ11) -> 0 | I9: =SUM('50% Equity Scenario'!BA11:BL11) -> 0 | J9: =SUM('50% Equity Scenario'!BM11:BX11) -> 0 | K9: =SUM('50% Equity Scenario'!BY11:CJ11) -> 0 | L9: =SUM('50% Equity Scenario'!CK11:CV11) -> 0 | M9: =SUM('50% Equity Scenario'!CW11:DH11) -> 0 | N9: =SUM('50% Equity Scenario'!DI11:DT11) -> 0 | O9: ='50% Equity Scenario'!DU11 -> 0
B10: Revenue | F10: =SUM('50% Equity Scenario'!Q12:AB12) -> 0 | G10: =SUM('50% Equity Scenario'!AC12:AN12) -> 0 | H10: =SUM('50% Equity Scenario'!AO12:AZ12) -> 0 | I10: =SUM('50% Equity Scenario'!BA12:BL12) -> 0 | J10: =SUM('50% Equity Scenario'!BM12:BX12) -> 0 | K10: =SUM('50% Equity Scenario'!BY12:CJ12) -> 0 | L10: =SUM('50% Equity Scenario'!CK12:CV12) -> 0 | M10: =SUM('50% Equity Scenario'!CW12:DH12) -> 0 | N10: =SUM('50% Equity Scenario'!DI12:DT12) -> 0 | O10: ='50% Equity Scenario'!DU12 -> 0
C11: Residual Payment | E11: =SUM('50% Equity Scenario'!E13:P13) -> 7608078 | F11: =SUM('50% Equity Scenario'!Q13:AB13) -> 6735515.6 | G11: =SUM('50% Equity Scenario'!AC13:AN13) -> 5963026.5 | H11: =SUM('50% Equity Scenario'!AO13:AZ13) -> 5279133.3 | I11: =SUM('50% Equity Scenario'!BA13:BL13) -> 4673675.1 | J11: =SUM('50% Equity Scenario'!BM13:BX13) -> 4137656.3 | K11: =SUM('50% Equity Scenario'!BY13:CJ13) -> 3663112.9 | L11: =SUM('50% Equity Scenario'!CK13:CV13) -> 3242994.4 | M11: =SUM('50% Equity Scenario'!CW13:DH13) -> 2871058.8 | N11: =SUM('50% Equity Scenario'!DI13:DT13) -> 2541780.1 | O11: ='50% Equity Scenario'!DU13 -> 0
C12: Sale of Residuals | E12: =SUM('50% Equity Scenario'!E16:P16) -> 0 | F12: =SUM('50% Equity Scenario'!Q16:AB16) -> 0 | G12: =SUM('50% Equity Scenario'!AC16:AN16) -> 0 | H12: =SUM('50% Equity Scenario'!AO16:AZ16) -> 0 | I12: =SUM('50% Equity Scenario'!BA16:BL16) -> 0 | J12: =SUM('50% Equity Scenario'!BM16:BX16) -> 0 | K12: =SUM('50% Equity Scenario'!BY16:CJ16) -> 0 | L12: =SUM('50% Equity Scenario'!CK16:CV16) -> 0 | M12: =SUM('50% Equity Scenario'!CW16:DH16) -> 0 | N12: =SUM('50% Equity Scenario'!DI16:DT16) -> 0 | O12: ='50% Equity Scenario'!DU16 -> 1201140
