Workbook
Name AA.AlternatePriceSourceStartPeriod: "Q1-2018"
Name AA.CIK: "887596"
Name AA.ColorizerVersion: "2.0.4.0"
Name AA.CompareQuarters.LatestMRQ: "Q3-2018"
Name AA.CSIN: "B1ICH30103"
Name AA.CurationVersion: "2023.11.1.0"
Name AA.DBMacroVersion: "1.0.13.0"
Name AA.FreeCashFlow: "TRUE"
Name AA.HardcodeChecker.LatestMRQ: "Q3-2019"
Name AA.ModelChecks.LatestMRQ: "Q3-2021"
Name AA.ModelChecks.LatestVersionNumber: "2.38.22.0"
Name AA.ModelColorScheme: "Classic"
Name AA.ModelVersion: "FY2023.23"
Name AA.NonLibraryWideCurationVersion: "5"
Name AA.PartialUpdate.BsAvailable: "FALSE"
Name AA.PartialUpdate.CfsAvailable: "FALSE"
Name AA.PartialUpdate.IsAvailable: "TRUE"
Name AA.PeriodLayout: "QFY"
Name AA.PersonalMacro.VersionNumber: "1.5.3.0"
Name AA.RowNameEnforcerVersion: "2023.11.1.0"
Name AA.SessionToUploadId: ""
Name AA.StartWorkModelVersion: "FY2023.22"
Name AA.StartWorkType: ""
Name AA.SubyearType: "Q"
Name AA.TemplateUpgradeAttempted: "TRUE"
Name AA.TemplateVersion: "7.4.8.0"
Name AA.UpdateType: "Regular"
Name AA.VerifyUnitsAtModelVersion: "Q1-2018.24"
Name HP.MRFX: Historicals!$B$934
Name HP.ReportCurrency: Historicals!$B$933
Name HP.Ticker: Historicals!$A$2
Name HP.TradeCurrency: Historicals!$B$931
Name HP.TradeCurrency.HardCoded: Historicals!$B$932
Name IQ_CH: 110000
Name IQ_CQ: 5000
Name IQ_CY: 10000
Name IQ_DAILY: 500000
Name IQ_FH: 100000
Name IQ_FQ: 500
Name IQ_FY: 1000
Name IQ_LTM: 2000
Name IQ_MONTH: 15000
Name IQ_NTM: 6000
Name IQ_WEEK: 50000
Name IQ_YTD: 3000
Name MO_AN_NI_NONGAAP_Diluted: Historicals!$377:$377
Name MO_BS_AP: Historicals!$764:$764
Name MO_BS_AR: Historicals!$746:$746
Name MO_BS_CA: Historicals!$751:$751
Name MO_BS_Cash: Historicals!$743:$743
Name MO_BS_CL: Historicals!$769:$769
Name MO_BS_CommonStock: Historicals!$784:$784
Name MO_BS_ContributedSurplus: Historicals!$785:$785
Name MO_BS_Intangibles: Historicals!$755:$755
Name MO_BS_INV: Historicals!$748:$748
Name MO_BS_NCA: Historicals!$760:$760
Name MO_BS_NCI: Historicals!$790:$790
Name MO_BS_NCL: Historicals!$780:$780
Name MO_BS_OCI: Historicals!$787:$787
Name MO_BS_OL_Current: Historicals!$767:$767

Sheet Cover
C16: Cheesecake Factory LBO Analysis
C19: To toggle between cases, please refer to 'Forecast Assumptions'
C21: Operating Model Build
C23: Forecast Assumptions
C24: Consolidated IS Build
C25: Consolidated BS Build
C26: BS Link
C27: CFS Link
C28: Revenue Build -- CK F.
C29: Revenue Build -- North Italia
C30: Revenue Build -- FRC & Others
C31: Revenue Build -- Franchising
... C42: Historicals (Publicly Available Raw Data)
AQ208: -

Sheet Transaction
B3: $ in millions
B5: 2023 EBITDA | E5: ='Consolidated IS Build'!BG27 -> 267.874 | H5: Share Price | J5: 34
B6: Entry Purchase Multiple | E6: =E7/E5 -> 10.148877 | H6: Total Shares outstanding | J6: 50.97
B7: Enterprise Value | E7: =E10-E9-E8 -> 2718.6204 | H7: Purchase Premium | J7: 0.33
B8: (-Debt) | E8: =-'Balance Sheet Link'!AV42 -> -470.047 | H8: Purchase Price per Share | J8: =J5*(1+J7) -> 45.22
B9: (+Cash) | E9: ='Balance Sheet Link'!AV9 -> 56.29
B10: Purchase Equity Value | E10: =J8*J6 -> 2304.8634
B11: (+Transaction Costs) | E11: =0.05*E7 -> 135.93102
B16: Sources | E16: Amount | F16: Interest Rate | G16: Capita/EBITDA | H16: % Capital
B17: Revolver | E17: 100 | F17: 0.0175 | G17: =E17/$E$5 -> 0.37330984 | H17: =E17/$E$23 -> 0.034354328
B18: Senior Secured TL (S + 175) | E18: =2.7*E5 -> 723.25981 | F18: =0.0532+0.0175 -> 0.0707 | G18: =E18/$E$5 -> 2.7 | H18: =E18/$E$23 -> 0.24847104 | J18: Senior Secured TL interest rate determined from S&P credit rating data for cumulative 5.3x Capital/EBITDA tranche
B19: 7.500% Senior Unsecured Notes | E19: =0.51*E23-(E17+E18) -> 661.26932 | F19: 0.075 | G19: =E19/$E$5 -> 2.4685834 | H19: =E19/$E$23 -> 0.22717463 | J19: Senior Secured TL interest rate determined from S&P credit rating data for cumulative 5.6x Capital/EBITDA tranche
B20: Cash | E20: =E9 -> 56.29 | G20: =E20/$E$5 -> 0.21013611 | H20: =E20/$E$23 -> 0.019338051
B21: Existing Roark Equity | E21: =0.05*E10 -> 115.24317 | G21: =E21/$E$5 -> 0.43021409 | H21: =E21/$E$23 -> 0.039591016 | J21: 57% Debt/Capital Buyout Financing
B22: New Roark Equity | E22: =E23-SUM(E17:E21) -> 1254.7791 | G22: =E22/$E$5 -> 4.6842139 | H22: =E22/$E$23 -> 0.43107093
B23: Total | E23: =E29 -> 2910.8414 | G23: =E23/$E$5 -> 10.866457 | H23: =E23/$E$23 -> 1
B25: Uses
B26: Refinance Old Debt | E26: =-E8 -> 470.047 | G26: =E26/$E$5 -> 1.7547317 | H26: =E26/$E$23 -> 0.16148149
B27: Equity Purchase | E27: =E10 -> 2304.8634 | G27: =E27/$E$5 -> 8.6042818 | H27: =E27/$E$23 -> 0.79182033
B28: Transaction Fees | E28: =E11 -> 135.93102 | G28: =E28/$E$5 -> 0.50744387 | H28: =E28/$E$23 -> 0.046698188
B29: Total | E29: =SUM(E26:E28) -> 2910.8414 | G29: =E29/$E$5 -> 10.866457 | H29: =E29/$E$23 -> 1
B32: 2028 Exit | E32: Returns Analysis and Value Bridge
B33: EBITDA | C33: =LBO!N40 -> 616.09628
B34: EV/EBITDA (entry) | C34: =E6 -> 10.148877 | E34: Source of Returns | F34: Entry Value | G34: Exit Value | H34: Attributed Returns
B35: EV/EBITDA (exit) | C35: 8.2 | E35: Entry Equity | H35: =E21+E22 -> 1370.0223
B36: Enterprise Value | C36: =C33*C35 -> 5051.9895 | E36: EBITDA Expansion | F36: =E5 -> 267.874 | G36: =C33 -> 616.09628 | H36: =H44*F45 -> 3534.0652
B37: (-) Outstanding debt | C37: =LBO!N42 -> 799.14797 | E37: Multiple Re-Rate | F37: =C34 -> 10.148877 | G37: =C35 -> 8.2 | H37: =G44*H45 -> -1200.6961
B38: (+) Cash | C38: ='Valuation and Cash Flow'!H31 -> 0 | E38: Fees | F38: =E11 -> 135.93102 | H38: =-F38 -> -135.93102
B39: Equity Value | C39: =C36-C37+C38 -> 4252.8415 | E39: Debt Paydown | F39: =SUM(E17:E19) -> 1484.5291 | G39: =LBO!N43 -> 799.14797 | H39: =H40-SUM(H36:H38) -> 685.38115
E40: Exit Equity | F40: =C41 -> 1370.0223 | G40: =C39 -> 4252.8415 | H40: =G40-F40 -> 2882.8192
B41: Equity Investment | C41: =E21+E22 -> 1370.0223
B42: MOIC | C42: =C39/C41 -> 3.1042134
B43: Holding Period (yrs) | C43: 5 | F43: Entry Value | G43: Exit Value | H43: Growth
E44: EBITDA | F44: =E5 -> 267.874 | G44: =C33 -> 616.09628 | H44: =G44-F44 -> 348.22228
B45: IRR | C45: =C42^(1/C43)-1 -> 0.25426792 | E45: EV/EBITDA | F45: =E6 -> 10.148877 | G45: =C35 -> 8.2 | H45: =G45-F45 -> -1.9488774
E47: LBO Value Creation
E49: Source of Returns | F49: Attributed Returns | G49: % Return
E50: EBITDA Expansion | F50: =H36 -> 3534.0652 | G50: =F50/F54 -> 1.2259059
E51: Multiple Re-Rate | F51: =H37 -> -1200.6961 | G51: =F51/F54 -> -0.41650065
E52: Debt Paydown | F52: =H39 -> 685.38115 | G52: =F52/F54 -> 0.23774684
...

Sheet Valuation and Cash Flow
B2: FCF Build
J3: Tax Rate | K3: 0.21
B4: $ in millions | D4: 2024E | E4: 2025E | F4: 2026E | G4: 2027E | H4: 2028E
B5: EBIT | D5: ='Consolidated IS Build'!BH22 -> 254.936 | E5: ='Consolidated IS Build'!BI22 -> 282.91409 | F5: ='Consolidated IS Build'!BJ22 -> 356.36516 | G5: ='Consolidated IS Build'!BK22 -> 424.36341 | H5: ='Consolidated IS Build'!BL22 -> 490.44355 | L5: UFCF Build
B6: (-) Interest Expense | D6: =LBO!J44 -> 102.47967 | E6: =LBO!K44 -> 98.828925 | F6: =LBO!L44 -> 90.053149 | G6: =LBO!M44 -> 77.448072 | H6: =LBO!N44 -> 59.34322 | L6: $ in millions | N6: 2024E | O6: 2025E | P6: 2026E | Q6: 2027E | R6: 2028E
L7: EBIT | N7: =D5 -> 254.936 | O7: =E5 -> 282.91409 | P7: =F5 -> 356.36516 | Q7: =G5 -> 424.36341 | R7: =H5 -> 490.44355
B8: EBT | D8: =D5-D6 -> 152.45634 | E8: =E5-E6 -> 184.08516 | F8: =F5-F6 -> 266.31201 | G8: =G5-G6 -> 346.91534 | H8: =H5-H6 -> 431.10033
B9: Tax Rate | D9: =$K$3 -> 0.21 | E9: =$K$3 -> 0.21 | F9: =$K$3 -> 0.21 | G9: =$K$3 -> 0.21 | H9: =$K$3 -> 0.21 | L9: (-) Taxes on EBIT | N9: =N7*$K$3 -> 53.536561 | O9: =O7*$K$3 -> 59.411958 | P9: =P7*$K$3 -> 74.836683 | Q9: =Q7*$K$3 -> 89.116316 | R9: =R7*$K$3 -> 102.99315
B10: (-) Tax Expense | D10: =D8*D9 -> 32.01583 | E10: =E8*E9 -> 38.657884 | F10: =F8*F9 -> 55.925522 | G10: =G8*G9 -> 72.852221 | H10: =H8*H9 -> 90.53107 | L10: (+) D&A | N10: =D16 -> 93.136 | O10: =E16 -> 100.01489 | P10: =F16 -> 110.25205 | Q10: =G16 -> 117.94024 | R10: =H16 -> 125.65273
B11: Net Income | D11: =D8-D10 -> 120.44051 | E11: =E8-E10 -> 145.42728 | F11: =F8-F10 -> 210.38649 | G11: =G8-G10 -> 274.06312 | H11: =H8-H10 -> 340.56926 | L11: (+/-) Changes in NWC | N11: =D18 -> 65.000886 | O11: =E18 -> 13.51059 | P11: =F18 -> 0.1402224 | Q11: =G18 -> 23.384323 | R11: =H18 -> 32.419836
L12: (-) CapEx | N12: =L24 -> 180.09 | O12: =M24 -> 165.318 | P12: =N24 -> 175.7616 | Q12: =O24 -> 195.19392 | R12: =P24 -> 193.9217
B13: $ in millions | D13: 2024E | E13: 2025E | F13: 2026E | G13: 2027E | H13: 2027E | L13: UFCF | N13: =N7-N9+N10+N11-N12 -> 179.44633 | O13: =O7-O9+O10+O11-O12 -> 171.70961 | P13: =P7-P9+P10+P11-P12 -> 216.15915 | Q13: =Q7-Q9+Q10+Q11-Q12 -> 281.37774 | R13: =R7-R9+R10+R11-R12 -> 351.60127
B15: Net Income | D15: =D11 -> 120.44051 | E15: =E11 -> 145.42728 | F15: =F11 -> 210.38649 | G15: =G11 -> 274.06312 | H15: =H11 -> 340.56926
B16: (+) D&A | D16: ='Consolidated IS Build'!BH25 -> 93.136 | E16: ='Consolidated IS Build'!BI25 -> 100.01489 | F16: ='Consolidated IS Build'!BJ25 -> 110.25205 | G16: ='Consolidated IS Build'!BK25 -> 117.94024 | H16: ='Consolidated IS Build'!BL25 -> 125.65273
B17: (+) SBC | D17: ='Consolidated IS Build'!BH26 -> 28.397224 | E17: ='Consolidated IS Build'!BI26 -> 30.492194 | F17: ='Consolidated IS Build'!BJ26 -> 33.272473 | G17: ='Consolidated IS Build'!BK26 -> 35.886188 | H17: ='Consolidated IS Build'!BL26 -> 38.658514
B18: (+/-) Changes in NWC | D18: ='Consolidated BS Build'!AX18 -> 65.000886 | E18: ='Consolidated BS Build'!AY18 -> 13.51059 | F18: ='Consolidated BS Build'!AZ18 -> 0.1402224 | G18: ='Consolidated BS Build'!BA18 -> 23.384323 | H18: ='Consolidated BS Build'!BB18 -> 32.419836
B19: Cash Flow from Operations | D19: =D15+D16+D17+D18 -> 306.97461 | E19: =E15+E16+E17+E18 -> 289.44495 | F19: =F15+F16+F17+F18 -> 354.05124 | G19: =G15+G16+G17+G18 -> 451.27387 | H19: =H15+H16+H17+H18 -> 537.30034 | L19: 2024 | M19: 2025 | N19: 2026 | O19: 2027 | P19: 2028
J20: Cumulative Owned Stores | L20: ='Consolidated IS Build'!BH15 -> 345.6 | M20: ='Consolidated IS Build'!BI15 -> 361.12 | N20: ='Consolidated IS Build'!BJ15 -> 373.744 | O20: ='Consolidated IS Build'!BK15 -> 389.2928 | P20: ='Consolidated IS Build'!BL15 -> 404.75136
B21: (-) CapEx | D21: =L24 -> 180.09 | E21: =M24 -> 165.318 | F21: =N24 -> 175.7616 | G21: =O24 -> 195.19392 | H21: =P24 -> 193.9217 | J21: New Store Openings | L21: ='Forecast Assumptions'!G9+'Forecast Assumptions'!G10+'Forecast Assumptions'!G11 -> 15 | M21: ='Forecast Assumptions'!H9+'Forecast Assumptions'!H10+'Forecast Assumptions'!H11 -> 13 | N21: ='Forecast Assumptions'!I9+'Forecast Assumptions'!I10+'Forecast Assumptions'!I11 -> 14 | O21: ='Forecast Assumptions'!J9+'Forecast Assumptions'!J10+'Forecast Assumptions'!J11 -> 16 | P21: ='Forecast Assumptions'!K9+'Forecast Assumptions'!K10+'Forecast Assumptions'!K11 -> 15.58
B22: Cash Flow from Investing | D22: =D19-D21 -> 126.88461 | E22: =E19-E21 -> 124.12695 | F22: =F19-F21 -> 178.28964 | G22: =G19-G21 -> 256.07995 | H22: =H19-H21 -> 343.37864 | J22: Per Store Upront CapEx (mn) | L22: 8.55 | M22: 8.55 | N22: 8.55 | O22: 8.55 | P22: 8.55
J23: Maintenance CapEx/Store | L23: 0.15 | M23: 0.15 | N23: 0.15 | O23: 0.15 | P23: 0.15
B24: (-) Revolver Repayment | D24: =LBO!J13 -> 100 | E24: =LBO!K13 -> 0 | F24: =LBO!L13 -> 0 | G24: =LBO!M13 -> 0 | H24: =LBO!N13 -> 0 | J24: Total CapEx | L24: =(L20*L23+L21*L22) -> 180.09 | M24: =(M20*M23+M21*M22) -> 165.318 | N24: =(N20*N23+N21*N22) -> 175.7616 | O24: =(O20*O23+O21*O22) -> 195.19392 | P24: =(P20*P23+P21*P22) -> 193.9217
B25: (-) TL Repayment | D25: =LBO!J24 -> 26.884615 | E25: =LBO!K24 -> 124.12695 | F25: =LBO!L24 -> 178.28964 | G25: =LBO!M24 -> 256.07995 | H25: =LBO!N24 -> 137.87865
B26: (-) Notes Repayment | D26: =LBO!J32 -> 0 | E26: =LBO!K32 -> 0 | F26: =LBO!L32 -> 0 | G26: =LBO!M32 -> 0 | H26: =LBO!N32 -> 205.49999
B27: Cash Flow from Financing | D27: =D22-D24-D25-D26 -> 0 | E27: =E22-E24-E25-E26 -> 0 | F27: =F22-F24-F25-F26 -> 0 | G27: =G22-G24-G25-G26 -> 0 | H27: =H22-H24-H25-H26 -> 0
B29: Beginning Cash | D29: 0 | E29: =D31 -> 0 | F29: =E31 -> 0 | G29: =F31 -> 0 | H29: =G31 -> 0
B30: Change in Cash | D30: =D27 -> 0 | E30: =E27 -> 0 | F30: =F27 -> 0 | G30: =G27 -> 0 | H30: =H27 -> 0
B31: Ending Cash | D31: =D29+D30 -> 0 | E31: =E29+E30 -> 0 | F31: =F29+F30 -> 0 | G31: =G29+G30 -> 0 | H31: =H29+H30 -> 0

Sheet Forecast Assumptions
D2: Active Assumptions
F4: 2023A | G4: 2024E | H4: 2025E | I4: 2026E | J4: 2027E | K4: 2028E | N4: Case Toggle: | O4: Base Case
D5: AlcBev Spend/Customer | F5: {=_xlfn.XLOOKUP($O$4,$D$19:$D$21,F19:K21)} -> 3.3594 | G5: 4 | H5: 4.5 | I5: 4.9 | J5: 5.2 | K5: 5.5
D6: Food Spend/Customer | F6: {=_xlfn.XLOOKUP(O4,D24:D26,F24:K26)} -> 21.9888 | G6: 22.868352 | H6: 23.783086 | I6: 24.73441 | J6: 25.723786 | K6: 26.752737 | O6: Bear Case
D7: Dessert Spend/Customer | F7: {=_xlfn.XLOOKUP(O4,D29:D31,F29:K31)} -> 5.1918 | G7: 5.347554 | H7: 5.5079806 | I7: 5.67322 | J7: 5.8434166 | K7: 6.0187191 | O7: Base Case
D8: Table Turnover Rate | F8: {=_xlfn.XLOOKUP(O4,D36:D38,F36:K38)} -> 0.38465779 | G8: 0.39 | H8: 0.395 | I8: 0.4 | J8: 0.405 | K8: 0.41 | O8: Bull Case
D9: New Stores - CK F. | F9: {=_xlfn.XLOOKUP(O4,D43:D45,F43:K45)} -> 6 | G9: 4 | H9: 5 | I9: 5 | J9: 6 | K9: 6
D10: New Stores - North Italia | F10: {=_xlfn.XLOOKUP(O4,D48:D50,F48:K50)} -> 3 | G10: 4 | H10: 4 | I10: 4 | J10: 5 | K10: 5
D11: New Stores - FRC & Others | F11: {=_xlfn.XLOOKUP(O4,D53:D55,F53:K55)} -> 7 | G11: 7 | H11: 4 | I11: 5 | J11: 5 | K11: 4.58
D12: New Franchises - South America | F12: {=_xlfn.XLOOKUP(O4,D60:D62,F60:K62)} -> 0 | G12: 4 | H12: 2 | I12: 2 | J12: 1 | K12: 0
D13: =D64 -> SSS Growth, Franchise | F13: {=_xlfn.XLOOKUP(O4,D65:D67,F65:K67)} -> 0 | G13: 0.045 | H13: 0.045 | I13: 0.045 | J13: 0.045 | K13: 0.045
D14: =D70 -> SSS Growth, North Italia | F14: {=_xlfn.XLOOKUP(O4,D71:D73,F71:K73)} -> 0 | G14: 0.04 | H14: 0.04 | I14: 0.04 | J14: 0.04 | K14: 0.04
D15: =D75 -> SSS Growth, FRC & Others | F15: {=_xlfn.XLOOKUP(O4,D76:D78,F76:K78)} -> 0 | G15: 0.05 | H15: 0.05 | I15: 0.05 | J15: 0.05 | K15: 0.05
D18: AlcBev Spend/Customer | F18: 2023A | G18: 2024E | H18: 2025E | I18: 2026E | J18: 2027E | K18: 2028E
D19: Bear Case | F19: ='Revenue Build - CK F.'!BG33 -> 3.3594 | G19: =F19*(1.04) -> 3.493776 | H19: =G19*(1.04) -> 3.633527 | I19: =H19*(1.03) -> 3.7425329 | J19: =I19*(1.03) -> 3.8548088 | K19: =J19*(1.03) -> 3.9704531
D20: Base Case | F20: ='Revenue Build - CK F.'!BG33 -> 3.3594 | G20: 4 | H20: 4.5 | I20: 4.9 | J20: 5.2 | K20: 5.5
D21: Bull Case | F21: ='Revenue Build - CK F.'!BG33 -> 3.3594 | G21: 4.5 | H21: 5 | I21: 5.5 | J21: 5.9 | K21: 6.3
D23: Food Spend/Customer | F23: 2023A | G23: 2024E | H23: 2025E | I23: 2026E | J23: 2027E | K23: 2028E
D24: Bear Case | F24: ='Revenue Build - CK F.'!BG37 -> 21.9888 | G24: =F24*(1.03) -> 22.648464 | H24: =G24*(1.03) -> 23.327918 | I24: =H24*(1.03) -> 24.027755 | J24: =I24*(1.03) -> 24.748588 | K24: =J24*(1.03) -> 25.491046 | M24: inability to pass on COGS escalation to customers
D25: Base Case | F25: ='Revenue Build - CK F.'!BG37 -> 21.9888 | G25: =F25*(1.04) -> 22.868352 | H25: =G25*(1.04) -> 23.783086 | I25: =H25*(1.04) -> 24.73441 | J25: =I25*(1.04) -> 25.723786 | K25: =J25*(1.04) -> 26.752737
D26: Bull Case | F26: ='Revenue Build - CK F.'!BG37 -> 21.9888 | G26: =F26*(1.06) -> 23.308128 | H26: =G26*(1.06) -> 24.706616 | I26: =H26*(1.06) -> 26.189013 | J26: =I26*(1.06) -> 27.760353 | K26: =J26*(1.06) -> 29.425975
D28: Dessert Spend/Customer | F28: 2023A | G28: 2024E | H28: 2025E | I28: 2026E | J28: 2027E | K28: 2028E
D29: Bear Case | F29: ='Revenue Build - CK F.'!BG35 -> 5.1918 | G29: =F29*(0.99) -> 5.139882 | H29: =G29*(0.99) -> 5.0884832 | I29: =H29*(0.99) -> 5.0375983 | J29: =I29*(0.99) -> 4.9872224 | K29: =J29*(0.99) -> 4.9373501
D30: Base Case | F30: ='Revenue Build - CK F.'!BG35 -> 5.1918 | G30: =F30*(1.03) -> 5.347554 | H30: =G30*(1.03) -> 5.5079806 | I30: =H30*(1.03) -> 5.67322 | J30: =I30*(1.03) -> 5.8434166 | K30: =J30*(1.03) -> 6.0187191
D31: Bull Case | F31: ='Revenue Build - CK F.'!BG35 -> 5.1918 | G31: =F31*(1.05) -> 5.45139 | H31: =G31*(1.05) -> 5.7239595 | I31: =H31*(1.05) -> 6.0101575 | J31: =I31*(1.05) -> 6.3106653 | K31: =J31*(1.05) -> 6.6261986
D35: Table Turnover Rate | F35: 2023A | G35: 2024E | H35: 2025E | I35: 2026E | J35: 2027E | K35: 2028E
D36: Bear Case | F36: ='Revenue Build - CK F.'!BG28 -> 0.38465779 | G36: =$F$36+0.01 -> 0.39465779 | H36: =$F$36+0.01 -> 0.39465779 | I36: =$F$36+0.02 -> 0.40465779 | J36: =$F$36+0.02 -> 0.40465779 | K36: =$F$36+0.02 -> 0.40465779
D37: Base Case | F37: ='Revenue Build - CK F.'!BG28 -> 0.38465779 | G37: 0.39 | H37: 0.395 | I37: 0.4 | J37: 0.405 | K37: 0.41 | L37: Olive Garden
D38: Bull Case | F38: ='Revenue Build - CK F.'!BG28 -> 0.38465779 | G38: 0.4 | H38: 0.41 | I38: 0.42 | J38: 0.42 | K38: 0.43 | L38: Bloomin' Brands
D42: New Stores - CK F. | F42: 2023A | G42: 2024E | H42: 2025E | I42: 2026E | J42: 2027E | K42: 2028E
D43: Bear Case | F43: ='Revenue Build - CK F.'!BG10 -> 6 | G43: =2 -> 2 | H43: =G43+1 -> 3 | I43: =H43 -> 3 | J43: =I43 -> 3 | K43: =J43 -> 3
D44: Base Case | F44: ='Revenue Build - CK F.'!BG10 -> 6 | G44: 4 | H44: 5 | I44: 5 | J44: 6 | K44: 6
D45: Bull Case | F45: ='Revenue Build - CK F.'!BG10 -> 6 | G45: 6 | H45: 6 | I45: 7 | J45: 7 | K45: 8
D47: New Stores - North Italia | F47: 2023A | G47: 2024E | H47: 2025E | I47: 2026E | J47: 2027E | K47: 2028E
D48: Bear Case | F48: ='Revenue Build - North Italia'!BC10 -> 3 | G48: 2 | H48: 2 | I48: 2 | J48: 2 | K48: 2
D49: Base Case | F49: ='Revenue Build - North Italia'!BC10 -> 3 | G49: 4 | H49: 4 | I49: 4 | J49: 5 | K49: 5
D50: Bull Case | F50: ='Revenue Build - North Italia'!BC10 -> 3 | G50: 5 | H50: 5 | I50: 6 | J50: 6 | K50: 7
D52: New Stores - FRC & Others | F52: 2023A | G52: 2024E | H52: 2025E | I52: 2026E | J52: 2027E | K52: 2028E
D53: Bear Case | F53: ='Revenue Build - FRC & Others'!BG10+'Revenue Build - FRC & Others'!BG42 -> 7 | G53: 5 | H53: 4 | I53: 4 | J53: 4 | K53: 3
D54: Base Case | F54: ='Revenue Build - FRC & Others'!BG10+'Revenue Build - FRC & Others'!BG42 -> 7 | G54: 7 | H54: 4 | I54: 5 | J54: 5 | K54: 4.58
...

Sheet LBO
B2: $ in millions | J2: 2024E | K2: 2025E | L2: 2026E | M2: 2027E | N2: 2028E
B4: Cash Beginning Balance: | J4: ='Valuation and Cash Flow'!D29 -> 0 | K4: ='Valuation and Cash Flow'!E29 -> 0 | L4: ='Valuation and Cash Flow'!F29 -> 0 | M4: ='Valuation and Cash Flow'!G29 -> 0 | N4: ='Valuation and Cash Flow'!H29 -> 0
B5: (+) Free Cash Flow | J5: ='Valuation and Cash Flow'!D22 -> 126.88461 | K5: ='Valuation and Cash Flow'!E22 -> 124.12695 | L5: ='Valuation and Cash Flow'!F22 -> 178.28964 | M5: ='Valuation and Cash Flow'!G22 -> 256.07995 | N5: ='Valuation and Cash Flow'!H22 -> 343.37864
B7: Cash Availble for Repayment of Debt | J7: =J4+J5 -> 126.88461 | K7: =K4+K5 -> 124.12695 | L7: =L4+L5 -> 178.28964 | M7: =M4+M5 -> 256.07995 | N7: =N4+N5 -> 343.37864
B10: Revolver (Max: $100)
B12: Beginning Balance | J12: =I16 -> 100 | K12: =J16 -> 0 | L12: =K16 -> 0 | M12: =L16 -> 0 | N12: =M16 -> 0
B13: Repayment | J13: =IF(J7>J12,J12,J7) -> 100 | K13: =IF(K7>K12,K12,K7) -> 0 | L13: =IF(L7>L12,L12,L7) -> 0 | M13: =IF(M7>M12,M12,M7) -> 0 | N13: =IF(N7>N12,N12,N7) -> 0
B14: Interest Expense | C14: Rate | D14: =Transaction!F17 -> 0.0175 | J14: =J12*$D$14 -> 1.75 | K14: =K12*$D$14 -> 0 | L14: =L12*$D$14 -> 0 | M14: =M12*$D$14 -> 0 | N14: =N12*$D$14 -> 0
B16: Ending Balance | I16: =Transaction!E17 -> 100 | J16: =J12-J13 -> 0 | K16: =K12-K13 -> 0 | L16: =L12-L13 -> 0 | M16: =M12-M13 -> 0 | N16: =N12-N13 -> 0
B18: Revolver Capacity | F18: Within Capacity?
B21: Senior Secured TL
B23: Beginning Balance | J23: =I27 -> 723.25981 | K23: =J27 -> 696.37519 | L23: =K27 -> 572.24824 | M23: =L27 -> 393.9586 | N23: =M27 -> 137.87865
B24: Principal Repayment | J24: =IF(J7-J13>0,MIN(J23,J7-J13),0) -> 26.884615 | K24: =IF(K7-K13>0,MIN(K23,K7-K13),0) -> 124.12695 | L24: =IF(L7-L13>0,MIN(L23,L7-L13),0) -> 178.28964 | M24: =IF(M7-M13>0,MIN(M23,M7-M13),0) -> 256.07995 | N24: =IF(N7-N13>0,MIN(N23,N7-N13),0) -> 137.87865
B25: Interest Expense | C25: Rate | D25: =Transaction!F18 -> 0.0707 | J25: =J23*$D$25 -> 51.134468 | K25: =K23*$D$25 -> 49.233726 | L25: =L23*$D$25 -> 40.45795 | M25: =M23*$D$25 -> 27.852873 | N25: =N23*$D$25 -> 9.7480207
B27: Ending Balance | I27: =Transaction!E18 -> 723.25981 | J27: =J23-J24 -> 696.37519 | K27: =K23-K24 -> 572.24824 | L27: =L23-L24 -> 393.9586 | M27: =M23-M24 -> 137.87865 | N27: =N23-N24 -> 0
B30: Senior Unsecured Notes
B31: Beginning Balance | J31: =I35 -> 661.26932 | K31: =J35 -> 661.26932 | L31: =K35 -> 661.26932 | M31: =L35 -> 661.26932 | N31: =M35 -> 661.26932
B32: Principal Repayment | J32: =IF(J7-J13-J24>0,MIN(J31,J7-J13-J24),0) -> 0 | K32: =IF(K7-K13-K24>0,MIN(K31,K7-K13-K24),0) -> 0 | L32: =IF(L7-L13-L24>0,MIN(L31,L7-L13-L24),0) -> 0 | M32: =IF(M7-M13-M24>0,MIN(M31,M7-M13-M24),0) -> 0 | N32: =IF(N7-N13-N24>0,MIN(N31,N7-N13-N24),0) -> 205.49999
B33: Interest Expense | C33: Rate | D33: =Transaction!F19 -> 0.075 | J33: =J31*$D$33 -> 49.595199 | K33: =K31*$D$33 -> 49.595199 | L33: =L31*$D$33 -> 49.595199 | M33: =M31*$D$33 -> 49.595199 | N33: =N31*$D$33 -> 49.595199
B35: Ending Balance | I35: =Transaction!E19 -> 661.26932 | J35: =J31-J32 -> 661.26932 | K35: =K31-K32 -> 661.26932 | L35: =L31-L32 -> 661.26932 | M35: =M31-M32 -> 661.26932 | N35: =N31-N32 -> 455.76933
B38: Leverage Calculations
B40: EBITDA | J40: ='Valuation and Cash Flow'!D5+'Valuation and Cash Flow'!D16 -> 348.072 | K40: ='Valuation and Cash Flow'!E5+'Valuation and Cash Flow'!E16 -> 382.92898 | L40: ='Valuation and Cash Flow'!F5+'Valuation and Cash Flow'!F16 -> 466.61721 | M40: ='Valuation and Cash Flow'!G5+'Valuation and Cash Flow'!G16 -> 542.30365 | N40: ='Valuation and Cash Flow'!H5+'Valuation and Cash Flow'!H16 -> 616.09628
B42: Total Beginning Debt | J42: =J12+J23+J31 -> 1484.5291 | K42: =K12+K23+K31 -> 1357.6445 | L42: =L12+L23+L31 -> 1233.5176 | M42: =M12+M23+M31 -> 1055.2279 | N42: =N12+N23+N31 -> 799.14797
B43: Beginning Net Debt | J43: =J42-J4 -> 1484.5291 | K43: =K42-K4 -> 1357.6445 | L43: =L42-L4 -> 1233.5176 | M43: =M42-M4 -> 1055.2279 | N43: =N42-N4 -> 799.14797
B44: Total Interest Expense | J44: =J33+J25+J14 -> 102.47967 | K44: =K33+K25+K14 -> 98.828925 | L44: =L33+L25+L14 -> 90.053149 | M44: =M33+M25+M14 -> 77.448072 | N44: =N33+N25+N14 -> 59.34322
B46: Leverage (Debt/EBITDA) | J46: =J42/J40 -> 4.2650058 | K46: =K42/K40 -> 3.5454212 | L46: =L42/L40 -> 2.643532 | M46: =M42/M40 -> 1.9458248 | N46: =N42/N40 -> 1.2971154
B47: Interest Coverage (EBITDA/Interest) | J47: =J40/J44 -> 3.3964982 | K47: =K40/K44 -> 3.874665 | L47: =L40/L44 -> 5.1815757 | M47: =M40/M44 -> 7.0021582 | N47: =IFERROR(N40/N44,0) -> 10.381915

Sheet Consolidated IS Build
B1: Period Ended | J1: 41730 | K1: 41821 | L1: 41912 | M1: 42003 | N1: 42003 | O1: 42094 | P1: 42185 | Q1: 42276 | R1: 42367 | S1: 42367 | T1: 42458 | U1: 42549 | V1: 42640 | W1: 42738 | X1: 42738 | Y1: 42829 | Z1: 42920 | AA1: 43011 | AB1: 43102 | AC1: 43102 | AD1: 43193 | AE1: 43284 | AF1: 43375 | AG1: 43466 | AH1: 43466 | AI1: 43557 | AJ1: 43648 | AK1: 43739 | AL1: 43830 | AM1: 43830 | AN1: 43921 | AO1: 44012 | AP1: 44103 | AQ1: 44194 | AR1: 44194 | AS1: 44285 | AT1: 44376 | AU1: 44467 | AV1: 44558 | AW1: 44558 | AX1: 44649 | AY1: 44740 | AZ1: 44831 | BA1: 44929 | BB1: 44929 | BC1: 45019 | BD1: 45111 | BE1: 45202 | BF1: 45293 | BG1: 45293 | BH1: Projected
J2: Q1-2014 | K2: Q2-2014 | L2: Q3-2014 | M2: Q4-2014 | N2: FY2014 | O2: Q1-2015 | P2: Q2-2015 | Q2: Q3-2015 | R2: Q4-2015 | S2: FY2015 | T2: Q1-2016 | U2: Q2-2016 | V2: Q3-2016 | W2: Q4-2016 | X2: FY2016 | Y2: Q1-2017 | Z2: Q2-2017 | AA2: Q3-2017 | AB2: Q4-2017 | AC2: FY2017 | AD2: Q1-2018 | AE2: Q2-2018 | AF2: Q3-2018 | AG2: Q4-2018 | AH2: FY2018 | AI2: Q1-2019 | AJ2: Q2-2019 | AK2: Q3-2019 | AL2: Q4-2019 | AM2: FY2019 | AN2: Q1-2020 | AO2: Q2-2020 | AP2: Q3-2020 | AQ2: Q4-2020 | AR2: FY2020 | AS2: Q1-2021 | AT2: Q2-2021 | AU2: Q3-2021 | AV2: Q4-2021 | AW2: FY2021 | AX2: Q1-2022 | AY2: Q2-2022 | AZ2: Q3-2022 | BA2: Q4-2022 | BB2: FY2022 | BC2: Q1-2023 | BD2: Q2-2023 | BE2: Q3-2023 | BF2: Q4-2023 | BG2: FY2023 | BH2: FY2024E | BI2: FY2025E | BJ2: FY2026E | BK2: FY2027E | BL2: FY2028E
B4: Restaurant-level revenue | J4: =J5+J6+J7 -> 481.431 | K4: =K5+K6+K7 -> 496.406 | L4: =L5+L6+L7 -> 499.114 | M4: =M5+M6+M7 -> 499.673 | N4: =N5+N6+N7 -> 1792.796 | O4: =O5+O6+O7 -> 472.817 | P4: =P5+P6+P7 -> 483.285 | Q4: =Q5+Q6+Q7 -> 481.076 | ... BG4: =BG5+BG6+BG7 -> 3339.3629 | BH4: =BH5+BH7+BH6 -> 3668.0853 | BI4: =BI5+BI7+BI6 -> 3974.6378 | BJ4: =BJ5+BJ7+BJ6 -> 4301.9083 | BK4: =BK5+BK7+BK6 -> 4650.2874 | BL4: =BL5+BL7+BL6 -> 5018.012
B5: Cheesecake Factory | J5: ='Revenue Build - CK F.'!J53 -> 436.606 | K5: ='Revenue Build - CK F.'!K53 -> 451.454 | L5: ='Revenue Build - CK F.'!L53 -> 454.271 | M5: ='Revenue Build - CK F.'!M53 -> 450.465 | N5: ='Revenue Build - CK F.'!N53 -> 1792.796 | O5: ='Revenue Build - CK F.'!O53 -> 472.817 | P5: ='Revenue Build - CK F.'!P53 -> 483.285 | Q5: ='Revenue Build - CK F.'!Q53 -> 481.076 | ... BG5: ='Revenue Build - CK F.'!BG53 -> 2595.066 | BH5: {='Revenue Build - CK F.'!BH53:BL53} -> 2861.822 | BI5: 3098.5756 | BJ5: 3351.6877 | BK5: 3616.9345 | BL5: 3891.7756
B6: North Italia | J6: 0 | K6: 0 | L6: 0 | M6: 0 | N6: 0 | O6: 0 | P6: 0 | Q6: 0 | R6: 0 | S6: 0 | T6: 0 | U6: 0 | V6: 0 | W6: 0 | X6: 0 | Y6: 0 | Z6: 0 | AA6: 0 | AB6: 0 | AC6: 0 | AD6: 0 | AE6: 0 | AF6: 0 | AG6: 0 | AH6: 0 | AI6: 0 | AJ6: 0 | AK6: 0 | AL6: ='Revenue Build - North Italia'!AH24 -> 35.268 | AM6: ='Revenue Build - North Italia'!AI24 -> 35.268 | AN6: ='Revenue Build - North Italia'!AJ24 -> 30.512 | AO6: ='Revenue Build - North Italia'!AK24 -> 13.759 | AP6: ='Revenue Build - North Italia'!AL24 -> 27.99 | AQ6: ='Revenue Build - North Italia'!AM24 -> 30.324 | AR6: ='Revenue Build - North Italia'!AN24 -> 102.585 | AS6: ='Revenue Build - North Italia'!AO24 -> 32.823 | ... BL6: ='Revenue Build - North Italia'!BH24 -> 506.70519
B7: FRC & all other restaurant | J7: ='Revenue Build - FRC & Others'!J47 -> 44.825 | K7: ='Revenue Build - FRC & Others'!K47 -> 44.952 | L7: ='Revenue Build - FRC & Others'!L47 -> 44.843 | M7: ='Revenue Build - FRC & Others'!M47 -> 49.208 | S7: ='Revenue Build - FRC & Others'!S49 -> 125.96444 | T7: ='Revenue Build - FRC & Others'!T49 -> 47.377 | U7: ='Revenue Build - FRC & Others'!U49 -> 46.944 | V7: ='Revenue Build - FRC & Others'!V49 -> 47.978 | W7: ='Revenue Build - FRC & Others'!W49 -> 55.337 | X7: ='Revenue Build - FRC & Others'!X49 -> 132.80961 | Y7: ='Revenue Build - FRC & Others'!Y49 -> 48.192 | Z7: ='Revenue Build - FRC & Others'!Z49 -> 49.641 | ... BL7: ='Revenue Build - FRC & Others'!BL49 -> 619.53116
B8: Bakery revenue | N8: 53.2 | S8: 52.8 | X8: 53.6 | AC8: 55.1 | AH8: 54.4 | AM8: 58.4 | AR8: 66.6 | AW8: 66.2 | BB8: 68.186 | BG8: 70.23158 | BH8: =BH9*(BH5+BH10) -> 77.524554 | BI8: =BI9*(BI5+BI10) -> 83.94897 | BJ8: =BJ9*(BJ5+BJ10) -> 90.790903 | BK8: =BK9*(BK5+BK10) -> 98.009003 | BL8: =BL9*(BL5+BL10) -> 105.39054
B9: Bakery % of CKF & Franchise | S9: =S8/(S5+S10) -> 0.027473606 | T9: =T8/(T5+T10) -> 0 | U9: =U8/(U5+U10) -> 0 | V9: =V8/(V5+V10) -> 0 | W9: =W8/(W5+W10) -> 0 | X9: =X8/(X5+X10) -> 0.02565441 | Y9: =Y8/(Y5+Y10) -> 0 | Z9: =Z8/(Z5+Z10) -> 0 | ... BG9: =BG8/(BG5+BG10) -> 0.026755147 | BH9: =$BG$9 -> 0.026755147 | BI9: =$BG$9 -> 0.026755147 | BJ9: =$BG$9 -> 0.026755147 | BK9: =$BG$9 -> 0.026755147 | BL9: =$BG$9 -> 0.026755147
B10: Franchise revenue | S10: ='Revenue Build - Franchising'!L36 -> 8.0865596 | T10: ='Revenue Build - Franchising'!M36 -> 2.377773 | U10: ='Revenue Build - Franchising'!N36 -> 2.609778 | V10: ='Revenue Build - Franchising'!O36 -> 2.8175746 | W10: ='Revenue Build - Franchising'!P36 -> 3.4212607 | X10: ='Revenue Build - Franchising'!Q36 -> 11.226386 | Y10: ='Revenue Build - Franchising'!R36 -> 3.3994821 | Z10: ='Revenue Build - Franchising'!S36 -> 3.4392507 | ... BL10: ='Revenue Build - Franchising'!BE36 -> 47.299832
B11: Total Revenue | N11: =N4+N8+N10 -> 1845.996 | O11: =O4+O8+O10 -> 472.817 | P11: =P4+P8+P10 -> 483.285 | Q11: =Q4+Q8+Q10 -> 481.076 | R11: =R4+R8+R10 -> 476.58 | S11: =S4+S8+S10 -> 2100.609 | T11: =T4+T8+T10 -> 556.07077 | U11: =U4+U8+U10 -> 561.47178 | ... BL11: =BL4+BL8+BL10 -> 5170.7023
B12: year-on-year growth (%) | BH12: =BH11/BG11-1 -> 0.099386872 | BI12: =BI11/BH11-1 -> 0.083658681 | BJ12: =BJ11/BI11-1 -> 0.082174247 | BK12: =BK11/BJ11-1 -> 0.081213463 | BL12: =BL11/BK11-1 -> 0.078455287
B14: Restaurant-level operating expenses
B15: Total number of restaurants (non franchise) | N15: ='Revenue Build - CK F.'!N12+'Revenue Build - FRC & Others'!N52 -> 177 | O15: ='Revenue Build - CK F.'!O12+'Revenue Build - FRC & Others'!O52 -> 177 | P15: ='Revenue Build - CK F.'!P12+'Revenue Build - FRC & Others'!P52 -> 179 | Q15: ='Revenue Build - CK F.'!Q12+'Revenue Build - FRC & Others'!Q52 -> 181 | R15: ='Revenue Build - CK F.'!R12+'Revenue Build - FRC & Others'!R52 -> 187 | S15: ='Revenue Build - CK F.'!S12+'Revenue Build - FRC & Others'!S52 -> 188 | T15: ='Revenue Build - CK F.'!T12+'Revenue Build - FRC & Others'!T52 -> 189 | U15: ='Revenue Build - CK F.'!U12+'Revenue Build - FRC & Others'!U52 -> 190 | ... AC15: ='Revenue Build - CK F.'!AC12+'Revenue Build - FRC & Others'!AC52 -> 213 | AH15: ='Revenue Build - CK F.'!AH12+'Revenue Build - North Italia'!AD12+'Revenue Build - FRC & Others'!AH52 -> 218 | AI15: ='Revenue Build - CK F.'!AI12+'Revenue Build - North Italia'!AE12+'Revenue Build - FRC & Others'!AI52 -> 218 | AJ15: ='Revenue Build - CK F.'!AJ12+'Revenue Build - North Italia'!AF12+'Revenue Build - FRC & Others'!AJ52 -> 219 | AK15: ='Revenue Build - CK F.'!AK12+'Revenue Build - North Italia'!AG12+'Revenue Build - FRC & Others'!AK52 -> 266 | AL15: ='Revenue Build - CK F.'!AL12+'Revenue Build - North Italia'!AH12+'Revenue Build - FRC & Others'!AL52 -> 292 | AM15: ='Revenue Build - CK F.'!AM12+'Revenue Build - North Italia'!AI12+'Revenue Build - FRC & Others'!AM52 -> 292 | AN15: ='Revenue Build - CK F.'!AN12+'Revenue Build - North Italia'!AJ12+'Revenue Build - FRC & Others'!AN52 -> 294 | AO15: ='Revenue Build - CK F.'!AO12+'Revenue Build - North Italia'!AK12+'Revenue Build - FRC & Others'!AO52 -> 294 | ... BL15: ='Revenue Build - CK F.'!BL12+'Revenue Build - North Italia'!BH12+'Revenue Build - FRC & Others'!BL52 -> 404.75136
B16: Labor expenses | J16: ='Cost Build - Aggregate'!J21 -> 0 | K16: ='Cost Build - Aggregate'!K21 -> 0 | L16: ='Cost Build - Aggregate'!L21 -> 0 | M16: ='Cost Build - Aggregate'!M21 -> 0 | N16: ='Cost Build - Aggregate'!N21 -> 646.102 | O16: ='Cost Build - Aggregate'!O21 -> 171.169 | P16: ='Cost Build - Aggregate'!P21 -> 168.495 | Q16: ='Cost Build - Aggregate'!Q21 -> 172.101 | ... BG16: ='Cost Build - Aggregate'!BG21 -> 1227.895 | BH16: =BH11*BH17 -> 1361.284 | BI16: =BI11*BI17 -> 1475.1672 | BJ16: =BJ11*BJ17 -> 1596.388 | BK16: =BK11*BK17 -> 1726.0362 | BL16: =BL11*BL17 -> 1861.4528
B17: Labor as % revenue | N17: =N16/N11 -> 0.35000184 | O17: =O16/O11 -> 0.36201956 | P17: =P16/P11 -> 0.34864521 | Q17: =Q16/Q11 -> 0.35774181 | R17: =R16/R11 -> 0.36311427 | S17: =S16/S11 -> 0.32600927 | T17: =T16/T11 -> 0.33387477 | U17: =U16/U11 -> 0.32986698 | ... BG17: =BG16/BG11 -> 0.3569978 | BH17: 0.36 | BI17: 0.36 | BJ17: 0.36 | BK17: 0.36 | BL17: 0.36
B18: F&B Cost of Sales | J18: ='Cost Build - Aggregate'!J20 -> 0 | K18: ='Cost Build - Aggregate'!K20 -> 0 | L18: ='Cost Build - Aggregate'!L20 -> 0 | M18: ='Cost Build - Aggregate'!M20 -> 0 | N18: ='Cost Build - Aggregate'!N20 -> 490.306 | O18: ='Cost Build - Aggregate'!O20 -> 126.612 | P18: ='Cost Build - Aggregate'!P20 -> 126.623 | Q18: ='Cost Build - Aggregate'!Q20 -> 125.605 | ... BG18: ='Cost Build - Aggregate'!BG20 -> 803.5 | BH18: =AVERAGE((AW18/AW15),(BB18/BB15),(BG18/BG15))*BH15 -> 817.70526 | BI18: =AVERAGE((BB18/BB15),(BG18/BG15),(BH18/BH15))*BI15 -> 883.97596 | BJ18: =AVERAGE((BG18/BG15),(BH18/BH15),(BI18/BI15))*BJ15 -> 902.14463 | BK18: =AVERAGE((BH18/BH15),(BI18/BI15),(BJ18/BJ15))*BK15 -> 937.90006 | BL18: =AVERAGE((BI18/BI15),(BJ18/BJ15),(BK18/BK15))*BL15 -> 980.97125
B19: G&A | N19: ='Cost Build - Aggregate'!N23 -> 119.094 | O19: ='Cost Build - Aggregate'!O23 -> 33.075 | P19: ='Cost Build - Aggregate'!P23 -> 35.345 | Q19: ='Cost Build - Aggregate'!Q23 -> 33.277 | R19: ='Cost Build - Aggregate'!R23 -> 35.705 | S19: ='Cost Build - Aggregate'!S23 -> 137.402 | T19: ='Cost Build - Aggregate'!T23 -> 35.337 | U19: ='Cost Build - Aggregate'!U23 -> 35.785 | ... BG19: ='Cost Build - Aggregate'!BG23 -> 217.449 | BH19: =AVERAGE((AW19/AW11),(BB19/BB11),(BG19/BG11))*BH11 -> 238.34054 | BI19: =AVERAGE((BB19/BB11),(BG19/BG11),(BH19/BH11))*BI11 -> 257.52801 | BJ19: =AVERAGE((BG19/BG11),(BH19/BH11),(BI19/BI11))*BJ11 -> 279.51402 | BK19: =AVERAGE((BH19/BH11),(BI19/BI11),(BJ19/BJ11))*BK11 -> 301.9137 | BL19: =AVERAGE((BI19/BI11),(BJ19/BJ11),(BK19/BK11))*BL11 -> 325.49636
B20: D&A | N20: ='Cost Build - Aggregate'!N24 -> 82.835 | O20: ='Cost Build - Aggregate'!O24 -> 21.177 | P20: ='Cost Build - Aggregate'!P24 -> 21.158 | Q20: ='Cost Build - Aggregate'!Q24 -> 21.317 | R20: ='Cost Build - Aggregate'!R24 -> 21.911 | S20: ='Cost Build - Aggregate'!S24 -> 85.563 | T20: ='Cost Build - Aggregate'!T24 -> 21.464 | U20: ='Cost Build - Aggregate'!U24 -> 21.461 | ... BG20: ='Cost Build - Aggregate'!BG24 -> 93.136 | BH20: ='Consolidated BS Build'!AX23 -> 93.136 | BI20: ='Consolidated BS Build'!AY23 -> 100.01489 | BJ20: ='Consolidated BS Build'!AZ23 -> 110.25205 | BK20: ='Consolidated BS Build'!BA23 -> 117.94024 | BL20: ='Consolidated BS Build'!BB23 -> 125.65273
B21: Other operating expense | N21: 478.504 | S21: 500.64 | X21: 540.365 | AC21: 552.791 | AH21: 566.825 | AM21: 631.613 | AR21: 616.069 | AW21: 792.311 | BB21: 881.627 | BG21: 922.428 | BH21: =AVERAGE((AW21/AW11),(BB21/BB11),(BG21/BG11))*BH11 -> 1015.5826 | BI21: =AVERAGE((BB21/BB11),(BG21/BG11),(BH21/BH11))*BI11 -> 1097.7266 | BJ21: =AVERAGE((BG21/BG11),(BH21/BH11),(BI21/BI11))*BJ11 -> 1189.3872 | BK21: =AVERAGE((BH21/BH11),(BI21/BI11),(BJ21/BJ11))*BK11 -> 1286.0313 | BL21: =AVERAGE((BI21/BI11),(BJ21/BJ11),(BK21/BK11))*BL11 -> 1386.3256
B22: EBIT | N22: =N11-SUM(N16:N21) -> 28.804998 | O22: =O11-SUM(O16:O21) -> 120.42198 | P22: =P11-SUM(P16:P21) -> 131.31535 | Q22: =Q11-SUM(Q16:Q21) -> 128.41826 | R22: =R11-SUM(R16:R21) -> 120.35689 | S22: =S11-SUM(S16:S21) -> 187.82899 | T22: =T11-SUM(T16:T21) -> 182.5049 | U22: =U11-SUM(U16:U21) -> 191.75191 | ... BL22: =BL11-SUM(BL16:BL21) -> 490.44355
B23: Adjusted EBIT (No Adjustments)
B25: Add back: D&A | N25: =N20 -> 82.835 | O25: =O20 -> 21.177 | P25: =P20 -> 21.158 | Q25: =Q20 -> 21.317 | R25: =R20 -> 21.911 | S25: =S20 -> 85.563 | T25: =T20 -> 21.464 | U25: =U20 -> 21.461 | ... BL25: =BL20 -> 125.65273
B26: Add back: SBC | N26: =Historicals!P639 -> 16.817 | O26: =Historicals!Q639 -> 4.731 | P26: =Historicals!R639 -> 4.946 | Q26: =Historicals!S639 -> 4.872 | R26: =Historicals!T639 -> 5.504 | S26: =Historicals!U639 -> 20.053 | T26: =Historicals!V639 -> 5.185 | U26: =Historicals!W639 -> 6.119 | ... BG26: =Historicals!BI639 -> 25.781 | BH26: =AVERAGE((AW26/AW16),(BB26/BB16),(BG26/BG16))*BH16 -> 28.397224 | BI26: =AVERAGE((BB26/BB16),(BG26/BG16),(BH26/BH16))*BI16 -> 30.492194 | BJ26: =AVERAGE((BG26/BG16),(BH26/BH16),(BI26/BI16))*BJ16 -> 33.272473 | BK26: =AVERAGE((BH26/BH16),(BI26/BI16),(BJ26/BJ16))*BK16 -> 35.886188 | BL26: =AVERAGE((BI26/BI16),(BJ26/BJ16),(BK26/BK16))*BL16 -> 38.658514
B27: EBITDA | N27: =N22+N25 -> 111.64 | O27: =O22+O25 -> 141.59898 | P27: =P22+P25 -> 152.47335 | Q27: =Q22+Q25 -> 149.73526 | R27: =R22+R25 -> 142.26789 | S27: =S22+S25 -> 273.39199 | T27: =T22+T25 -> 203.9689 | U27: =U22+U25 -> 213.21291 | ... BL27: =BL22+BL25 -> 616.09628
B28: Adjusted EBITDA (No Adjustments)
B30: Interest expense | N30: 6.187 | O30: 1.895 | P30: 1.432 | Q30: 0.722 | R30: 1.845 | S30: 5.894 | T30: 2.304 | U30: 2.181 | V30: 2.477 | W30: 2.263 | X30: 9.225 | Y30: 1.256 | Z30: 1.57 | AA30: 1.6 | AB30: 1.953 | AC30: 6.379 | AD30: 1.506 | AE30: 2.908 | AF30: 3.29 | AG30: 1.765 | AH30: 6.783 | AI30: -0.002 | AJ30: 0.025 | AK30: -0.006 | AL30: 2.48 | AM30: 2.497 | AN30: 1.518 | AO30: 2.566 | AP30: 2.935 | AQ30: 1.58 | AR30: 8.599 | AS30: 2.694 | AT30: 4.706 | AU30: 1.794 | AV30: 1.504 | AW30: 10.698 | AX30: 1.461 | AY30: 1.13 | AZ30: 1.315 | BA30: 2.137 | BB30: 6.043 | BC30: 1.88 | BD30: 2.162 | BE30: 2.027 | BF30: 2.483 | BG30: 8.552
B31: EBT | N31: =N22-N30 -> 22.617998 | O31: =O22-O30 -> 118.52698 | P31: =P22-P30 -> 129.88335 | Q31: =Q22-Q30 -> 127.69626 | R31: =R22-R30 -> 118.51189 | S31: =S22-S30 -> 181.93499 | T31: =T22-T30 -> 180.2009 | U31: =U22-U30 -> 189.57091 | ... BG31: =BG22-BG30 -> 166.186
B33: Current tax | N33: 37.064 | O33: 9.521 | P33: 13.666 | Q33: 9.217 | R33: 9.241 | S33: 41.645 | T33: 9.175 | U33: 16.372 | V33: 13.661 | W33: 14.071 | X33: 53.279 | Y33: 4.078 | Z33: 11.404 | AA33: 7.397 | AB33: -8.625 | AC33: 14.254 | AD33: 2.859 | AE33: 3.634 | AF33: 1.619 | AG33: 5.774 | AH33: 13.886 | AI33: -0.076 | AJ33: 7.001 | AK33: 0.886 | AL33: 7.427 | AM33: 15.238 | AN33: -44.182 | AO33: -29.795 | AP33: 32.359 | AQ33: 6.175 | AR33: -35.443 | AS33: 3.79 | AT33: 4.084 | AU33: -0.765 | AV33: 12.987 | AW33: 20.096 | AX33: -0.172 | AY33: 4.746 | AZ33: 1.79 | BA33: 2.051 | BB33: 8.415 | BC33: 0.804 | BD33: 3.357 | BE33: -0.086 | BF33: 10.303 | BG33: 14.378
B34: Net Income to Common Shareholders | N34: =N31-N33 -> -14.446002 | O34: =O31-O33 -> 109.00598 | P34: =P31-P33 -> 116.21735 | Q34: =Q31-Q33 -> 118.47926 | R34: =R31-R33 -> 109.27089 | S34: =S31-S33 -> 140.28999 | T34: =T31-T33 -> 171.0259 | U34: =U31-U33 -> 173.19891 | ... BG34: =BG31-BG33 -> 151.808

Sheet Consolidated BS Build
D2: FY2014 | E2: Q1-2015 | F2: Q2-2015 | G2: Q3-2015 | H2: Q4-2015 | I2: FY2015 | J2: Q1-2016 | K2: Q2-2016 | L2: Q3-2016 | M2: Q4-2016 | N2: FY2016 | O2: Q1-2017 | P2: Q2-2017 | Q2: Q3-2017 | R2: Q4-2017 | S2: FY2017 | T2: Q1-2018 | U2: Q2-2018 | V2: Q3-2018 | W2: Q4-2018 | X2: FY2018 | Y2: Q1-2019 | Z2: Q2-2019 | AA2: Q3-2019 | AB2: Q4-2019 | AC2: FY2019 | AD2: Q1-2020 | AE2: Q2-2020 | AF2: Q3-2020 | AG2: Q4-2020 | AH2: FY2020 | AI2: Q1-2021 | AJ2: Q2-2021 | AK2: Q3-2021 | AL2: Q4-2021 | AM2: FY2021 | AN2: Q1-2022 | AO2: Q2-2022 | AP2: Q3-2022 | AQ2: Q4-2022 | AR2: FY2022 | AS2: Q1-2023 | AT2: Q2-2023 | AU2: Q3-2023 | AV2: Q4-2023 | AW2: FY2023 | AX2: FY2024E | AY2: FY2025E | AZ2: FY2026E | BA2: FY2027E | BB2: FY2028E
B5: Net Working Capital
B6: Accounts Receivable | D6: 77.497 | E6: 42.335 | F6: 42.224 | G6: 45.87 | H6: 86.817 | I6: 86.817 | J6: 43.667 | K6: 41.618 | L6: 44.715 | M6: 80.224 | N6: 80.224 | O6: 44.788 | P6: 48.815 | Q6: 47.092 | R6: 87.383 | S6: 87.383 | T6: 42.724 | U6: 49.621 | V6: 50.901 | W6: 89.121 | X6: 89.121 | Y6: 46.188 | Z6: 47.671 | AA6: 47.801 | AB6: 90.302 | AC6: 90.302 | AD6: 50.145 | AE6: 48.584 | AF6: 51.733 | AG6: 75.787 | AH6: 75.787 | AI6: 57.815 | AJ6: 57.934 | AK6: 66.663 | AL6: 100.504 | AM6: 100.504 | AN6: 66.451 | AO6: 71.338 | AP6: 67.661 | AQ6: 105.511 | AR6: 105.511 | AS6: 68.456 | AT6: 71.366 | AU6: 70.236 | AV6: 103.094 | AW6: 103.094 | AX6: ='Consolidated IS Build'!BH11*'Consolidated BS Build'!AX7 -> 129.19581 | AY6: ='Consolidated IS Build'!BI11*'Consolidated BS Build'!AY7 -> 138.19627 | AZ6: ='Consolidated IS Build'!BJ11*'Consolidated BS Build'!AZ7 -> 145.5716 | BA6: ='Consolidated IS Build'!BK11*'Consolidated BS Build'!BA7 -> 155.95292 | BB6: ='Consolidated IS Build'!BL11*'Consolidated BS Build'!BB7 -> 168.79288
B7: % Revenue | D7: =D6/'Consolidated IS Build'!$N$11 -> 0.041981131 | H7: =H6/'Consolidated IS Build'!N11 -> 0.047029896 | I7: =I6/'Consolidated IS Build'!$S$11 -> 0.041329443 | N7: =N6/'Consolidated IS Build'!$X$11 -> 0.035252155 | S7: =S6/'Consolidated IS Build'!$AC$11 -> 0.038656458 | X7: =X6/'Consolidated IS Build'!$AH$11 -> 0.038211129 | AC7: =AC6/'Consolidated IS Build'!$AM$11 -> 0.036372615 | AH7: =AH6/'Consolidated IS Build'!$AR$11 -> 0.03821402 | AM7: =AM6/'Consolidated IS Build'!$AW$11 -> 0.03433053 | AR7: =AR6/'Consolidated IS Build'!$BB$11 -> 0.031942482 | AW7: =AW6/'Consolidated IS Build'!$BG$11 -> 0.029973517 | AX7: =AVERAGE(AC7,AH7,AM7,AR7,AW7) -> 0.034166633 | AY7: =AVERAGE(AX7,AW7,AR7,AM7,AH7) -> 0.033725436 | AZ7: =AVERAGE(AY7,AX7,AW7,AR7,AM7) -> 0.032827719 | BA7: =AVERAGE(AZ7,AY7,AX7,AW7,AR7) -> 0.032527157 | BB7: =AVERAGE(BA7,AZ7,AY7,AX7,AW7) -> 0.032644092
B8: Inventory | D8: 33.255 | E8: 32.525 | F8: 36.466 | G8: 36.742 | H8: 34.01 | I8: 34.01 | J8: 35.543 | K8: 34.571 | L8: 35.541 | M8: 34.926 | N8: 34.926 | O8: 38.541 | P8: 40.246 | Q8: 44.195 | R8: 42.56 | S8: 42.56 | T8: 40.959 | U8: 34.691 | V8: 39.769 | W8: 38.886 | X8: 38.886 | Y8: 42.028 | Z8: 46.011 | AA8: 47.778 | AB8: 47.225 | AC8: 47.225 | AD8: 47.822 | AE8: 40.511 | AF8: 37.727 | AG8: 39.288 | AH8: 39.288 | AI8: 38.955 | AJ8: 41.868 | AK8: 43.27 | AL8: 42.839 | AM8: 42.839 | AN8: 46.68 | AO8: 52.286 | AP8: 62.275 | AQ8: 55.559 | AR8: 55.559 | AS8: 58.989 | AT8: 60.868 | AU8: 58.672 | AV8: 57.654 | AW8: 57.654 | AX8: ='Consolidated IS Build'!BH11*AX9 -> 65.831115 | AY8: ='Consolidated IS Build'!BI11*AY9 -> 70.017165 | AZ8: ='Consolidated IS Build'!BJ11*AZ9 -> 73.35565 | BA8: ='Consolidated IS Build'!BK11*BA9 -> 81.143924 | BB8: ='Consolidated IS Build'!BL11*BB9 -> 87.617896
B9: % Revenue | D9: =D8/'Consolidated IS Build'!$N$11 -> 0.018014665 | H9: =H8/'Consolidated IS Build'!N11 -> 0.018423659 | I9: =I8/'Consolidated IS Build'!$S$11 -> 0.016190543 | N9: =N8/'Consolidated IS Build'!$X$11 -> 0.015347238 | S9: =S8/'Consolidated IS Build'!$AC$11 -> 0.018827676 | X9: =X8/'Consolidated IS Build'!$AH$11 -> 0.016672591 | AC9: =AC8/'Consolidated IS Build'!$AM$11 -> 0.019021691 | AH9: =AH8/'Consolidated IS Build'!$AR$11 -> 0.019810158 | AM9: =AM8/'Consolidated IS Build'!$AW$11 -> 0.014633105 | AR9: =AR8/'Consolidated IS Build'!$BB$11 -> 0.016819975 | AW9: =AW8/'Consolidated IS Build'!$BG$11 -> 0.016762305 | AX9: =AVERAGE(AC9,AH9,AM9,AR9,AW9) -> 0.017409447 | AY9: =AVERAGE(AX9,AW9,AR9,AM9,AH9) -> 0.017086998 | AZ9: =AVERAGE(AY9,AX9,AW9,AR9,AM9) -> 0.016542366 | BA9: =AVERAGE(AZ9,AY9,AX9,AW9,AR9) -> 0.016924218 | BB9: =AVERAGE(BA9,AZ9,AY9,AX9,AW9) -> 0.016945067
B10: Accounts Payable | D10: 57.325 | E10: 54.152 | F10: 52.171 | G10: 44.208 | H10: 47.77 | I10: 47.77 | J10: 38.363 | K10: 38.573 | L10: 38.906 | M10: 41.564 | N10: 41.564 | O10: 34.937 | P10: 46.219 | Q10: 46.572 | R10: 50.984 | S10: 50.984 | T10: 38.805 | U10: 38.312 | V10: 39.13 | W10: 49.071 | X10: 49.071 | Y10: 36.394 | Z10: 35.96 | AA10: 36.095 | AB10: 61.946 | AC10: 61.946 | AD10: 55.894 | AE10: 57.532 | AF10: 61.549 | AG10: 58.432 | AH10: 58.432 | AI10: 56.047 | AJ10: 55.377 | AK10: 52.89 | AL10: 54.086 | AM10: 54.086 | AN10: 61.741 | AO10: 58.927 | AP10: 59.03 | AQ10: 66.638 | AR10: 66.638 | AS10: 57.001 | AT10: 72.682 | AU10: 53.392 | AV10: 63.152 | AW10: 63.152 | AX10: ='Consolidated IS Build'!BH11*AX11 -> 84.266499 | AY10: ='Consolidated IS Build'!BI11*AY11 -> 89.130955 | AZ10: ='Consolidated IS Build'!BJ11*AZ11 -> 89.615951 | BA10: ='Consolidated IS Build'!BK11*BA11 -> 98.557022 | BB10: ='Consolidated IS Build'!BL11*BB11 -> 106.68442
B11: % Revenue | D11: =D10/'Consolidated IS Build'!$N$11 -> 0.031053697 | H11: =H10/'Consolidated IS Build'!N11 -> 0.025877629 | I11: =I10/'Consolidated IS Build'!$S$11 -> 0.022741024 | N11: =N10/'Consolidated IS Build'!$X$11 -> 0.018264118 | S11: =S10/'Consolidated IS Build'!$AC$11 -> 0.022554282 | X11: =X10/'Consolidated IS Build'!$AH$11 -> 0.021039467 | AC11: =AC10/'Consolidated IS Build'!$AM$11 -> 0.024951142 | AH11: =AH10/'Consolidated IS Build'!$AR$11 -> 0.029463122 | AM11: =AM10/'Consolidated IS Build'!$AW$11 -> 0.018474897 | AR11: =AR10/'Consolidated IS Build'!$BB$11 -> 0.02017404 | AW11: =AW10/'Consolidated IS Build'!$BG$11 -> 0.018360792 | AX11: =AVERAGE(AC11,AH11,AM11,AR11,AW11) -> 0.022284799 | AY11: =AVERAGE(AX11,AW11,AR11,AM11,AH11) -> 0.02175153 | AZ11: =AVERAGE(AY11,AX11,AW11,AR11,AM11) -> 0.020209211 | BA11: =AVERAGE(AZ11,AY11,AX11,AW11,AR11) -> 0.020556074 | BB11: =AVERAGE(BA11,AZ11,AY11,AX11,AW11) -> 0.020632481
B12: Prepaid Expenses | D12: 38.233 | E12: 46.579 | F12: 46.622 | G12: 44.08 | H12: 41.976 | I12: 41.976 | J12: 40.637 | K12: 37.824 | L12: 36.337 | M12: 52.438 | N12: 52.438 | O12: 52.585 | P12: 50.919 | Q12: 48.521 | R12: 57.666 | S12: 57.666 | T12: 54.036 | U12: 52.946 | V12: 48.327 | W12: 40.645 | X12: 40.645 | Y12: 46.771 | Z12: 39.524 | AA12: 38.895 | AB12: 43.946 | AC12: 43.946 | AD12: 42.489 | AE12: 36.342 | AF12: 32.188 | AG12: 35.31 | AH12: 35.31 | AI12: 30.727 | AJ12: 32.039 | AK12: 29.714 | AL12: 36.446 | AM12: 36.446 | AN12: 33.741 | AO12: 33.373 | AP12: 30.953 | AQ12: 48.399 | AR12: 48.399 | AS12: 48.387 | AT12: 52.641 | AU12: 55.558 | AV12: 63.09 | AW12: 63.09 | AX12: ='Consolidated IS Build'!BH11*AX13 -> 61.219784 | AY12: ='Consolidated IS Build'!BI11*AY13 -> 65.103033 | AZ12: ='Consolidated IS Build'!BJ11*AZ13 -> 68.753044 | BA12: ='Consolidated IS Build'!BK11*BA13 -> 77.266256 | BB12: ='Consolidated IS Build'!BL11*BB13 -> 84.841254
B13: % Revenue | D13: =D12/'Consolidated IS Build'!$N$11 -> 0.020711312 | H13: =H12/'Consolidated IS Build'!N11 -> 0.022738944 | I13: =I12/'Consolidated IS Build'!$S$11 -> 0.019982776 | N13: =N12/'Consolidated IS Build'!$X$11 -> 0.023042388 | S13: =S12/'Consolidated IS Build'!$AC$11 -> 0.025510263 | X13: =X12/'Consolidated IS Build'!$AH$11 -> 0.017426772 | AC13: =AC12/'Consolidated IS Build'!$AM$11 -> 0.017700947 | AH13: =AH12/'Consolidated IS Build'!$AR$11 -> 0.017804334 | AM13: =AM12/'Consolidated IS Build'!$AW$11 -> 0.01244936 | AR13: =AR12/'Consolidated IS Build'!$BB$11 -> 0.014652351 | AW13: =AW12/'Consolidated IS Build'!$BG$11 -> 0.018342766 | AX13: =AVERAGE(AC13,AH13,AM13,AR13,AW13) -> 0.016189952 | AY13: =AVERAGE(AX13,AW13,AR13,AM13,AH13) -> 0.015887753 | AZ13: =AVERAGE(AY13,AX13,AW13,AR13,AM13) -> 0.015504436 | BA13: =AVERAGE(AZ13,AY13,AX13,AW13,AR13) -> 0.016115452 | BB13: =AVERAGE(BA13,AZ13,AY13,AX13,AW13) -> 0.016408072
B14: Accrued Expenses | D14: 264.686 | E14: 243.623 | F14: 246.07 | G14: 246.428 | H14: 302.456 | I14: 302.456 | J14: 267.857 | K14: 265.851 | L14: 265.197 | M14: 179.034 | N14: 179.034 | O14: 155.081 | P14: 160.046 | Q14: 159.823 | R14: 183.016 | S14: 183.016 | T14: 167.367 | U14: 182.659 | V14: 179.062 | W14: 194.381 | X14: 194.381 | Y14: 171.315 | Z14: 172.973 | AA14: 172.098 | AB14: 236.582 | AC14: 236.582 | AD14: 166.828 | AE14: 192.549 | AF14: 194.575 | AG14: 210.461 | AH14: 210.461 | AI14: 203.211 | AJ14: 241.488 | AK14: 210.155 | AL14: 239.187 | AM14: 239.187 | AN14: 202.217 | AO14: 237.453 | AP14: 225 | AQ14: 231.133 | AR14: 231.133 | AS14: 237.293 | AT14: 220.917 | AU14: 240.44 | AV14: 239.699 | AW14: 239.699 | AX14: ='Consolidated IS Build'!BH11*AX15 -> 319.73452 | AY14: ='Consolidated IS Build'!BI11*AY15 -> 337.68393 | AZ14: ='Consolidated IS Build'!BJ11*AZ15 -> 344.40296 | BA14: ='Consolidated IS Build'!BK11*BA15 -> 368.50258 | BB14: ='Consolidated IS Build'!BL11*BB15 -> 404.53397
B15: % Revenue | D15: =D14/'Consolidated IS Build'!$N$11 -> 0.14338384 | H15: =H14/'Consolidated IS Build'!N11 -> 0.16384434 | I15: =I14/'Consolidated IS Build'!$S$11 -> 0.14398491 | N15: =N14/'Consolidated IS Build'!$X$11 -> 0.0786714 | S15: =S14/'Consolidated IS Build'!$AC$11 -> 0.080962547 | X15: =X14/'Consolidated IS Build'!$AH$11 -> 0.083341944 | AC15: =AC14/'Consolidated IS Build'!$AM$11 -> 0.095292529 | AH15: =AH14/'Consolidated IS Build'!$AR$11 -> 0.10612059 | AM15: =AM14/'Consolidated IS Build'!$AW$11 -> 0.081702385 | AR15: =AR14/'Consolidated IS Build'!$BB$11 -> 0.069973383 | AW15: =AW14/'Consolidated IS Build'!$BG$11 -> 0.06969001 | AX15: =AVERAGE(AC15,AH15,AM15,AR15,AW15) -> 0.084555779 | AY15: =AVERAGE(AX15,AW15,AR15,AM15,AH15) -> 0.082408429 | AZ15: =AVERAGE(AY15,AX15,AW15,AR15,AM15) -> 0.077665997 | BA15: =AVERAGE(AZ15,AY15,AX15,AW15,AR15) -> 0.07685872 | BB15: =AVERAGE(BA15,AZ15,AY15,AX15,AW15) -> 0.078235787
B17: Change in NWC
B18: Cash Change | I18: =-(I6-D6)-(I8-D8)+(I10-D10)+(I12-D12)+(I14-D14) -> 21.883 | J18: =-(J6-E6)-(J8-E8)+(J10-E10)+(J12-E12)+(J14-E14) -> -1.847 | K18: =-(K6-F6)-(K8-F8)+(K10-F10)+(K12-F12)+(K14-F14) -> -0.114 | L18: =-(L6-G6)-(L8-G8)+(L10-G10)+(L12-G12)+(L14-G14) -> 8.08 | M18: =-(M6-H6)-(M8-H8)+(M10-H10)+(M12-H12)+(M14-H14) -> -113.489 | N18: =-(N6-I6)-(N8-I8)+(N10-I10)+(N12-I12)+(N14-I14) -> -113.489 | O18: =-(O6-J6)-(O8-J8)+(O10-J10)+(O12-J12)+(O14-J14) -> -108.373 | P18: =-(P6-K6)-(P8-K8)+(P10-K10)+(P12-K12)+(P14-K14) -> -97.936 | ... AW18: =-(AW6-AR6)-(AW8-AR8)+(AW10-AR10)+(AW12-AR12)+(AW14-AR14) -> 20.093 | AX18: =-(AX6-AW6)-(AX8-AW8)+(AX10-AW10)+(AX12-AW12)+(AX14-AW14) -> 65.000886 | AY18: =-(AY6-AX6)-(AY8-AX8)+(AY10-AX10)+(AY12-AX12)+(AY14-AX14) -> 13.51059 | AZ18: =-(AZ6-AY6)-(AZ8-AY8)+(AZ10-AY10)+(AZ12-AY12)+(AZ14-AY14) -> 0.1402224 | BA18: =-(BA6-AZ6)-(BA8-AZ8)+(BA10-AZ10)+(BA12-AZ12)+(BA14-AZ14) -> 23.384323 | BB18: =-(BB6-BA6)-(BB8-BA8)+(BB10-BA10)+(BB12-BA12)+(BB14-BA14) -> 32.419836
B20: CapEx | D20: 113.982 | E20: -24.151 | F20: -59.473 | G20: -108.593 | H20: =I20 -> 153.941 | I20: 153.941 | J20: -22.441 | K20: -40.208 | L20: -70.607 | M20: =N20 -> 115.821 | N20: 115.821 | O20: -19.223 | P20: -43.699 | Q20: -73.417 | R20: =S20 -> 120.779 | S20: 120.779 | T20: -30.688 | U20: -51.87 | V20: -78.716 | W20: =X20 -> 102.909 | X20: 102.909 | Y20: -13.351 | Z20: -29.371 | AA20: -46.702 | AB20: =AC20 -> 73.765 | AC20: 73.765 | AD20: -15.775 | AE20: -29.424 | AF20: -38.27 | AG20: =AH20 -> 50.329 | AH20: 50.329 | AI20: -7.227 | AJ20: -30.902 | AK20: -49.158 | AL20: =AM20 -> 66.943 | AM20: 66.943 | AN20: -29.093 | AO20: -46.382 | AP20: -78.053 | AQ20: =AR20 -> 112.464 | AR20: 112.464 | AS20: -37.962 | AT20: -62.66 | AU20: -99.923 | AV20: =AW20 -> 151.565 | AW20: 151.565 | AX20: ='Valuation and Cash Flow'!L24 -> 180.09 | AY20: ='Valuation and Cash Flow'!M24 -> 165.318 | AZ20: ='Valuation and Cash Flow'!N24 -> 175.7616 | BA20: ='Valuation and Cash Flow'!O24 -> 195.19392 | BB20: ='Valuation and Cash Flow'!P24 -> 193.9217
B21: % Revenue | H21: =H20/'Consolidated IS Build'!N11 -> 0.083391838 | I21: =I20/'Consolidated IS Build'!O11 -> 0.32558262 | J21: =J20/'Consolidated IS Build'!P11 -> -0.046434299 | K21: =K20/'Consolidated IS Build'!Q11 -> -0.08357931 | L21: =L20/'Consolidated IS Build'!R11 -> -0.14815351 | M21: =M20/'Consolidated IS Build'!S11 -> 0.055136867 | N21: =N20/'Consolidated IS Build'!T11 -> 0.20828464 | O21: =O20/'Consolidated IS Build'!U11 -> -0.034236805 | ... BB21: =BB20/'Consolidated IS Build'!BH11 -> 0.051283798
B23: D&A | D23: 82.835 | E23: 21.177 | F23: 42.335 | G23: 63.652 | H23: =I23 -> 85.563 | I23: 85.563 | J23: 21.464 | K23: 42.925 | L23: 64.559 | M23: =N23 -> 88.01 | N23: 88.01 | O23: 23.196 | P23: 46.493 | Q23: 69.492 | R23: =S23 -> 92.729 | S23: 92.729 | T23: 24.002 | U23: 47.729 | V23: 71.819 | W23: =X23 -> 95.976 | X23: 95.976 | Y23: 21.362 | Z23: 43.021 | AA23: 64.363 | AB23: =AC23 -> 88.133 | AC23: 88.133 | AD23: 23.562 | AE23: 46.152 | AF23: 68.803 | AG23: =AH23 -> 91.415 | AH23: 91.415 | AI23: 22.006 | AJ23: 44.229 | AK23: 66.805 | AL23: =AM23 -> 89.654 | AM23: 89.654 | AN23: 21.505 | AO23: 44.113 | AP23: 66.764 | AQ23: =AR23 -> 92.38 | AR23: 92.38 | AS23: 22.955 | AT23: 46.287 | AU23: 69.124 | AV23: =AW23 -> 93.136 | AW23: 93.136 | AX23: =AX25*AW26 -> 93.136 | AY23: =AY25*AX26 -> 100.01489 | AZ23: =AZ25*AY26 -> 110.25205 | BA23: =BA25*AZ26 -> 117.94024 | BB23: =BB25*BA26 -> 125.65273
B24: % CapEx | H24: =H23/H20 -> 0.55581684 | I24: =I23/I20 -> 0.55581684 | J24: =J23/J20 -> -0.95646362 | K24: =K23/K20 -> -1.0675736 | L24: =L23/L20 -> -0.91434277 | M24: =M23/M20 -> 0.75987947 | N24: =N23/N20 -> 0.75987947 | O24: =O23/O20 -> -1.2066795 | ... AW24: =AW23/AW20 -> 0.61449543
B25: % PP&E | H25: =H23/G26 -> 0.0978601 | I25: =I23/H26 -> 0.095902111 | J25: =J23/I26 -> 0.024057629 | K25: =K23/J26 -> 0.04845005 | L25: =L23/K26 -> 0.072632134 | M25: =M23/L26 -> 0.097509254 | N25: =N23/M26 -> 0.096700046 | O25: =O23/N26 -> 0.025486357 | ... AW25: =AW23/AV26 -> 0.11773079 | AX25: =$AW$25 -> 0.11773079 | AY25: =$AW$25 -> 0.11773079 | AZ25: =$AW$25 -> 0.11773079 | BA25: =$AW$25 -> 0.11773079 | BB25: =$AW$25 -> 0.11773079
B26: PP&E | E26: =Historicals!Q724 -> 828.966 | F26: =Historicals!R724 -> 851.477 | G26: =Historicals!S724 -> 874.34 | H26: =Historicals!T724 -> 892.191 | I26: =Historicals!U724 -> 892.191 | J26: =Historicals!V724 -> 885.964 | K26: =Historicals!W724 -> 888.849 | L26: =Historicals!X724 -> 902.581 | ... AW26: =Historicals!BI724 -> 791.093 | AX26: =AW26-AW23+'Consolidated BS Build'!AW20 -> 849.522 | AY26: =AX26-AX23+'Consolidated BS Build'!AX20 -> 936.476 | AZ26: =AY26-AY23+'Consolidated BS Build'!AY20 -> 1001.7791 | BA26: =AZ26-AZ23+'Consolidated BS Build'!AZ20 -> 1067.2887 | BB26: =BA26-BA23+'Consolidated BS Build'!BA20 -> 1144.5423

Sheet Revenue Build - CK F.
N2: Actual
B4: Period Ended | J4: 41730 | K4: 41821 | L4: 41912 | M4: 42003 | N4: 42003 | O4: 42094 | P4: 42185 | Q4: 42276 | R4: 42367 | S4: 42367 | T4: 42458 | U4: 42549 | V4: 42640 | W4: 42738 | X4: 42738 | Y4: 42829 | Z4: 42920 | AA4: 43011 | AB4: 43102 | AC4: 43102 | AD4: 43193 | AE4: 43284 | AF4: 43375 | AG4: 43466 | AH4: 43466 | AI4: 43557 | AJ4: 43648 | AK4: 43739 | AL4: 43830 | AM4: 43830 | AN4: 43921 | AO4: 44012 | AP4: 44103 | AQ4: 44194 | AR4: 44194 | AS4: 44285 | AT4: 44376 | AU4: 44467 | AV4: 44558 | AW4: 44558 | AX4: 44649 | AY4: 44740 | AZ4: 44831 | BA4: 44929 | BB4: 44929 | BC4: 45019 | BD4: 45111 | BE4: 45202 | BF4: 45293 | BG4: 45293
J5: Q1-2014 | K5: Q2-2014 | L5: Q3-2014 | M5: Q4-2014 | N5: FY2014 | O5: Q1-2015 | P5: Q2-2015 | Q5: Q3-2015 | R5: Q4-2015 | S5: FY2015 | T5: Q1-2016 | U5: Q2-2016 | V5: Q3-2016 | W5: Q4-2016 | X5: FY2016 | Y5: Q1-2017 | Z5: Q2-2017 | AA5: Q3-2017 | AB5: Q4-2017 | AC5: FY2017 | AD5: Q1-2018 | AE5: Q2-2018 | AF5: Q3-2018 | AG5: Q4-2018 | AH5: FY2018 | AI5: Q1-2019 | AJ5: Q2-2019 | AK5: Q3-2019 | AL5: Q4-2019 | AM5: FY2019 | AN5: Q1-2020 | AO5: Q2-2020 | AP5: Q3-2020 | AQ5: Q4-2020 | AR5: FY2020 | AS5: Q1-2021 | AT5: Q2-2021 | AU5: Q3-2021 | AV5: Q4-2021 | AW5: FY2021 | AX5: Q1-2022 | AY5: Q2-2022 | AZ5: Q3-2022 | BA5: Q4-2022 | BB5: FY2022 | BC5: Q1-2023 | BD5: Q2-2023 | BE5: Q3-2023 | BF5: Q4-2023 | BG5: FY2023 | BH5: FY2024E | BI5: FY2025E | BJ5: FY2026E | BK5: FY2027E | BL5: FY2028E
B7: Cheesecake Factory Revenue Build
B9: The Cheesecake Factory restaurants - BoP, # of restaurants | J9: 168 | K9: =J12 -> 169 | L9: =K12 -> 170 | M9: =L12 -> 172 | N9: =J12 -> 169 | O9: =N12 -> 177 | P9: =O12 -> 177 | Q9: =P12 -> 179 | R9: =Q12 -> 181 | S9: =N12 -> 177 | T9: =S12 -> 187 | U9: =T12 -> 188 | V9: =U12 -> 189 | W9: =V12 -> 189 | X9: =S12 -> 187 | Y9: =X12 -> 194 | Z9: =Y12 -> 194 | AA9: =Z12 -> 193 | AB9: =AA12 -> 194 | AC9: =X12 -> 194 | AD9: =AC12 -> 199 | AE9: =AD12 -> 199 | AF9: =AE12 -> 198 | AG9: =AF12 -> 199 | AH9: =AC12 -> 199 | AI9: =AH12 -> 201 | AJ9: =AI12 -> 201 | AK9: =AJ12 -> 202 | AL9: =AK12 -> 203 | AM9: =AH12 -> 201 | AN9: =AM12 -> 206 | AO9: =AN12 -> 206 | AP9: =AO12 -> 206 | AQ9: =AP12 -> 205 | AR9: =AM12 -> 206 | AS9: =AR12 -> 206 | AT9: =AS12 -> 207 | AU9: =AT12 -> 207 | AV9: =AU12 -> 207 | AW9: =AR12 -> 206 | AX9: =AW12 -> 208 | AY9: =AX12 -> 208 | AZ9: =AY12 -> 208 | BA9: =AZ12 -> 209 | BB9: =AW12 -> 208 | BC9: =BB12 -> 211 | BD9: =BC12 -> 210 | BE9: =BD12 -> 211 | BF9: =BE12 -> 213 | BG9: =BB12 -> 211 | BH9: =BG12 -> 216 | BI9: =BH12 -> 219.6 | BJ9: =BI12 -> 224.12 | BK9: =BJ12 -> 228.744 | BL9: =BK12 -> 234.2928
B10: CF restaurants opened, # of restaurants | J10: 1 | K10: 2 | L10: 2 | M10: 5 | N10: 10 | O10: 0 | P10: 2 | Q10: 2 | R10: 6 | S10: 10 | T10: 1 | U10: 1 | V10: 0 | W10: 5 | X10: 7 | Y10: 0 | Z10: 1 | AA10: 1 | AB10: 5 | AC10: 7 | AD10: 0 | AE10: 0 | AF10: 1 | AG10: 3 | AH10: 4 | AI10: 0 | AJ10: 1 | AK10: 1 | AL10: 3 | AM10: =SUM(AI10,AJ10,AK10,AL10) -> 5 | AN10: 0 | AO10: 0 | AP10: 0 | AQ10: 1 | AR10: =SUM(AN10,AO10,AP10,AQ10) -> 1 | AS10: 1 | AT10: 0 | AU10: 0 | AV10: 1 | AW10: =SUM(AS10,AT10,AU10,AV10) -> 2 | AX10: 0 | AY10: 0 | AZ10: 1 | BA10: 2 | BB10: =SUM(AX10,AY10,AZ10,BA10) -> 3 | BC10: 0 | BD10: 1 | BE10: 2 | BF10: 3 | BG10: =SUM(BC10,BD10,BE10,BF10) -> 6 | BH10: ='Forecast Assumptions'!G9 -> 4 | BI10: ='Forecast Assumptions'!H9 -> 5 | BJ10: ='Forecast Assumptions'!I9 -> 5 | BK10: ='Forecast Assumptions'!J9 -> 6 | BL10: ='Forecast Assumptions'!K9 -> 6
B11: CF restaurants closed, # of restaurants | J11: =J12-J9-J10 -> 0 | K11: =K12-K9-K10 -> -1 | L11: =L12-L9-L10 -> 0 | M11: =M12-M9-M10 -> 0 | N11: =-(N10-(N12-N9)) -> -2 | O11: =O12-O9-O10 -> 0 | P11: =P12-P9-P10 -> 0 | Q11: =Q12-Q9-Q10 -> 0 | R11: =R12-R9-R10 -> 0 | S11: =-(S10-(S12-S9)) -> 0 | T11: =T12-T9-T10 -> 0 | U11: =U12-U9-U10 -> 0 | V11: =V12-V9-V10 -> 0 | W11: =W12-W9-W10 -> 0 | X11: =-(X10-(X12-X9)) -> 0 | Y11: =Y12-Y9-Y10 -> 0 | Z11: =Z12-Z9-Z10 -> -2 | AA11: =AA12-AA9-AA10 -> 0 | AB11: =AB12-AB9-AB10 -> 0 | AC11: =-(AC10-(AC12-AC9)) -> -2 | AD11: =AD12-AD9-AD10 -> 0 | AE11: =AE12-AE9-AE10 -> -1 | AF11: =AF12-AF9-AF10 -> 0 | AG11: =AG12-AG9-AG10 -> -1 | AH11: =-(AH10-(AH12-AH9)) -> -2 | AI11: =AI12-AI9-AI10 -> 0 | AJ11: =AJ12-AJ9-AJ10 -> 0 | AK11: =AK12-AK9-AK10 -> 0 | AL11: =AL12-AL9-AL10 -> 0 | AM11: =-(AM10-(AM12-AM9)) -> 0 | AN11: =AN12-AN9-AN10 -> 0 | AO11: =AO12-AO9-AO10 -> 0 | AP11: =AP12-AP9-AP10 -> -1 | AQ11: =AQ12-AQ9-AQ10 -> 0 | AR11: =-(AR10-(AR12-AR9)) -> -1 | AS11: =AS12-AS9-AS10 -> 0 | AT11: =AT12-AT9-AT10 -> 0 | AU11: =AU12-AU9-AU10 -> 0 | AV11: =AV12-AV9-AV10 -> 0 | AW11: =-(AW10-(AW12-AW9)) -> 0 | AX11: =AX12-AX9-AX10 -> 0 | AY11: =AY12-AY9-AY10 -> 0 | AZ11: =AZ12-AZ9-AZ10 -> 0 | BA11: =BA12-BA9-BA10 -> 0 | BB11: 0 | BC11: =BC12-BC9-BC10 -> -1 | BD11: =BD12-BD9-BD10 -> 0 | BE11: =BE12-BE9-BE10 -> 0 | BF11: =BF12-BF9-BF10 -> 0 | BG11: =-(BG10-(BG12-BG9)) -> -1 | BH11: =AVERAGE(BG11,BB11,AW11,AR11,AM11) -> -0.4 | BI11: =AVERAGE(BH11,BG11,BB11,AW11,AR11) -> -0.48 | BJ11: =AVERAGE(BI11,BH11,BG11,BB11,AW11) -> -0.376 | BK11: =AVERAGE(BJ11,BI11,BH11,BG11,BB11) -> -0.4512 | BL11: =AVERAGE(BK11,BJ11,BI11,BH11,BG11) -> -0.54144
B12: The Cheesecake Factory restaurants - EoP, # of restaurants | J12: 169 | K12: 170 | L12: 172 | M12: =N12 -> 177 | N12: 177 | O12: 177 | P12: 179 | Q12: 181 | R12: =S12 -> 187 | S12: 187 | T12: 188 | U12: 189 | V12: 189 | W12: 194 | X12: 194 | Y12: 194 | Z12: 193 | AA12: 194 | AB12: 199 | AC12: 199 | AD12: 199 | AE12: 198 | AF12: 199 | AG12: 201 | AH12: 201 | AI12: 201 | AJ12: 202 | AK12: 203 | AL12: 206 | AM12: =AL12 -> 206 | AN12: 206 | AO12: 206 | AP12: 205 | AQ12: 206 | AR12: =AQ12 -> 206 | AS12: 207 | AT12: 207 | AU12: 207 | AV12: 208 | AW12: =AV12 -> 208 | AX12: 208 | AY12: 208 | AZ12: 209 | BA12: 211 | BB12: =BA12 -> 211 | BC12: 210 | BD12: 211 | BE12: 213 | BF12: 216 | BG12: =BF12 -> 216 | BH12: =BH9+BH10+BH11 -> 219.6 | BI12: =BI9+BI10+BI11 -> 224.12 | BJ12: =BJ9+BJ10+BJ11 -> 228.744 | BK12: =BK9+BK10+BK11 -> 234.2928 | BL12: =BL9+BL10+BL11 -> 239.75136
B13: Y/Y CF restaurant growth, % | J13: 0 | K13: 0 | L13: 0 | M13: 0 | O13: =O12/J12-1 -> 0.047337278 | P13: =P12/K12-1 -> 0.052941176 | Q13: =Q12/L12-1 -> 0.052325581 | R13: =R12/M12-1 -> 0.056497175 | S13: =S12/N12-1 -> 0.056497175 | T13: =T12/O12-1 -> 0.062146893 | U13: =U12/P12-1 -> 0.055865922 | V13: =V12/Q12-1 -> 0.044198895 | ... BG13: =BG12/BB12-1 -> 0.023696682 | BH13: =BH12/BG12-1 -> 0.016666667 | BI13: =BI12/BH12-1 -> 0.020582878 | BJ13: =BJ12/BI12-1 -> 0.020631804 | BK13: =BK12/BJ12-1 -> 0.024257685 | BL13: =BL12/BK12-1 -> 0.023298027
