Workbook
Name \0: #REF!
Name \i: #REF!
Name \L: #REF!
Name \m: #REF!
Name \R: #REF!
Name \t: #REF!
Name __FDS_HYPERLINK_TOGGLE_STATE__: "ON"
Name __FDS_UNIQUE_RANGE_ID_GENERATOR_COUNTER: 1
Name _1: #REF!
Name _1111_19th_Street: #REF!
Name _14180_Accumulated_Depreciation___Equipment________________Courtyard___Plano__TX______0000: #REF!
Name _14182_Accumulated_Depreciation___Equipment___Capital_Leas_Courtyard___Philadelphia___0000: #REF!
Name _25_0: #REF!
Name _45STEP_UP: #REF!
Name _500_Marquette: #REF!
Name _60_Spear: #REF!
Name _bdm.028285451B4742929125DFB41D546413.edm: #REF!
Name _bdm.16AA9A3EFC28404BA85B049587C880C8.edm: #REF!
Name _bdm.1D26AA9B3391447F9A7D401C2A2957EC.edm: #REF!
Name _bdm.1F34719A23B34845A4C25E45C3DDF83D.edm: #REF!
Name _bdm.22432391224B438D8EFBF7683098DD3E.edm: #REF!
Name _bdm.23D8DF48031241CBB016C38B4F807196.edm: #REF!
Name _bdm.450AC11AD54948929B5DFCF6E68CAEE5.edm: #REF!
Name _bdm.5A8BDDFBFD3842C2ABEA35DD2CA102C7.edm: #REF!
Name _bdm.619D0A075BCE49F3AE2DFCAB7922D2FB.edm: #REF!
Name _bdm.6698C999A3DB4955B72A8DE986E8E059.edm: #REF!
Name _bdm.716E8AC41D7F44889A91B9561AB5E54A.edm: #REF!
Name _bdm.8664FDAB4C71436BBE09980F3B0196AB.edm: #REF!
Name _bdm.8AB906D8C9734F2286D5C9AF62741447.edm: #REF!
Name _bdm.9A173BE4CFF34FAE89F3FA5B0BC17717.edm: #REF!
Name _bdm.A5D1906AC03742F2A1DCEBD455574B86.edm: #REF!
Name _bdm.A9DB6556387A48C986268CFFA66D14C5.edm: #REF!
Name _bdm.B1CD14597A1448FBBAD91ADC116AA817.edm: #REF!
Name _bdm.BD200F3830E14C118FAEF247DA56A648.edm: #REF!
Name _bdm.BE01C6A9B87D4520B2B9A588797491FA.edm: #REF!
Name _bdm.CAF081D66FB74576B10C513AD7F2BD14.edm: #REF!
Name _bdm.CD342BFF8027460E98352C7B8C9343A6.edm: #REF!
Name _bdm.D84D0266F6A548778138E8EDADA2A502.edm: #REF!
Name _bdm.DC24C60BD8804AD3B3B483F23A282A8E.edm: #REF!
Name _bdm.DC5CF1FCF3F649CC85B6C35F227B6EE3.edm: #REF!
Name _bdm.ED95D5371F0B4032AE81D39228F05494.edm: #REF!
Name _bdm.F05EE0B050FD40D196B178505BC36B9D.edm: #REF!
Name _bdm.ToolkitBookmark.1_24_2004_11_15_31_PM.edm: #REF!
Name _bdm.ToolkitBookmark.1_24_2004_8_24_02_PM.edm: #REF!
Name _bdm.ToolkitBookmark.1_24_2004_8_54_41_PM.edm: #REF!
Name _bdm.ToolkitBookmark.1_25_2004_9_47_15_PM.edm: #REF!
Name _bdm.ToolkitBookmark.1_25_2004_9_47_23_PM.edm: #REF!
Name _DCF2: #REF!
Name _DCF22: #REF!
Name _Dev2000: #REF!,#REF!,#REF!,#REF!,#REF!,#REF!
Name _Dev98: #REF!,#REF!,#REF!,#REF!,#REF!,#REF!
Name _FAC05: #REF!
Name _FAC11: #REF!
Name _FAC12: #REF!
Name _FAC14: #REF!
Name _FAC16: #REF!
Name _FAC18: #REF!
Name _FFO1: #REF!
Name _FFO2: #REF!
Name _FFO3: #REF!

Sheet Cover
F28: Northwind Industries - FINANCIAL MODEL
F35: =TODAY() -> 46081

Sheet Historical Financials
B2: Northwind Industries
B3: Historical Financials | J3: Draft - Preliminary & Confidential
B5: $ in millions, except where otherwise denoted
A6: x | B6: Financials | K6: x
A8: x | B8: Income Statement | K8: x
D10: 42004 | E10: =EOMONTH(D10,12) -> 42369 | F10: =EOMONTH(E10,12) -> 42735 | G10: =EOMONTH(F10,12) -> 43100 | H10: =EOMONTH(G10,12) -> 43465 | J10: ="'14A - '18A CAGR" -> '14A - '18A CAGR
D11: =YEAR(D10) -> 2014 | E11: =YEAR(E10) -> 2015 | F11: =YEAR(F10) -> 2016 | G11: =YEAR(G10) -> 2017 | H11: =YEAR(H10) -> 2018
B13: Products Revenue | D13: 236.277 | E13: 148.565 | F13: 134.755 | G13: 211.313 | H13: 238.459 | J13: =RATE($H$11-$D$11,0,-$D13,$H13) -> 0.0023007783
B14: (+) Services Revenue | D14: 298.665 | E14: 208.283 | F14: 243.91 | G14: 301.656 | H14: 314.68 | J14: =RATE($H$11-$D$11,0,-$D14,$H14) -> 0.01314406
B15: Total Revenue | D15: =SUM(D13:D14) -> 534.942 | E15: =SUM(E13:E14) -> 356.848 | F15: =SUM(F13:F14) -> 378.665 | G15: =SUM(G13:G14) -> 512.969 | H15: =SUM(H13:H14) -> 553.139 | J15: =RATE($H$11-$D$11,0,-$D15,$H15) -> 0.0083978146
B16: % Y-O-Y Growth | E16: =E15/D15-1 -> -0.33292207 | F16: =F15/E15-1 -> 0.061138076 | G16: =G15/F15-1 -> 0.35467762 | H16: =H15/G15-1 -> 0.078308826
B18: (–) Product Cost of Goods Sold (COGS) | D18: -141.08299 | E18: -101.54867 | F18: -85.732825 | G18: -140.56916 | H18: -158.4088
B19: (–) Services Cost of Goods Sold (COGS) | D19: -227.01605 | E19: -184.62581 | F19: -185.29518 | G19: -229.76384 | H19: -219.6612
B20: Gross Profit | D20: =SUM(D15,D18:D19) -> 166.84297 | E20: =SUM(E15,E18:E19) -> 70.673517 | F20: =SUM(F15,F18:F19) -> 107.637 | G20: =SUM(G15,G18:G19) -> 142.636 | H20: =SUM(H15,H18:H19) -> 175.069 | J20: =RATE($H$11-$D$11,0,-$D20,$H20) -> 0.012104455
B21: Gross Margin % | D21: =D20/D15 -> 0.31188983 | E21: =E20/E15 -> 0.19804936 | F21: =F20/F15 -> 0.28425389 | G21: =G20/G15 -> 0.27805969 | H21: =H20/H15 -> 0.31650092
B23: (–) Selling, Generative, & Administrative (SG&A) | D23: -49.069 | E23: -43.735 | F23: -47.117 | G23: -49.146 | H23: -44.828
B24: (–) Research & Development (R&D) | D24: -11.049 | E24: -7.431 | F24: -9.075 | G24: -12.512 | H24: -10.457
B25: EBITDA | D25: =SUM(D20,D23:D24) -> 106.72497 | E25: =SUM(E20,E23:E24) -> 19.507517 | F25: =SUM(F20,F23:F24) -> 51.445 | G25: =SUM(G20,G23:G24) -> 80.978 | H25: =SUM(H20,H23:H24) -> 119.784 | J25: =RATE($H$11-$D$11,0,-$D25,$H25) -> 0.029279198
B26: EBITDA Margin % | D26: =D25/D15 -> 0.19950755 | E26: =E25/E15 -> 0.05466618 | F26: =F25/F15 -> 0.13585887 | G26: =G25/G15 -> 0.15786139 | H26: =H25/H15 -> 0.21655316
B28: (–) Depreciation & Amortization (D&A) | D28: -31.877967 | E28: -33.936517 | F28: -36.128 | G28: -38.461 | H28: -42.989
B29: Earnings Before Interest & Taxes (EBIT) | D29: =SUM(D25,D28) -> 74.847 | E29: =SUM(E25,E28) -> -14.429 | F29: =SUM(F25,F28) -> 15.317 | G29: =SUM(G25,G28) -> 42.517 | H29: =SUM(H25,H28) -> 76.795 | J29: =RATE($H$11-$D$11,0,-$D29,$H29) -> 0.0064440501
B30: EBIT Margin % | D30: =D29/D15 -> 0.1399161 | E30: =E29/E15 -> -0.040434583 | F30: =F29/F15 -> 0.040450002 | G30: =G29/G15 -> 0.082884151 | H30: =H29/H15 -> 0.1388349
B32: (–) Interest Expense | D32: -2.5 | E32: =D32-0.4 -> -2.9 | F32: =E32-0.4 -> -3.3 | G32: =F32-0.4 -> -3.7 | H32: =G32-0.4 -> -4.1
B33: Income (Loss) Before Income Taxes | D33: =SUM(D29,D32) -> 72.347 | E33: =SUM(E29,E32) -> -17.329 | F33: =SUM(F29,F32) -> 12.017 | G33: =SUM(G29,G32) -> 38.817 | H33: =SUM(H29,H32) -> 72.695
B34: (–) Income Taxes | D34: -20.849 | E34: 12.34 | F34: -6.777 | G34: -14.276 | H34: -24.781
B35: Net Income | D35: =SUM(D33:D34) -> 51.498 | E35: =SUM(E33:E34) -> -4.989 | F35: =SUM(F33:F34) -> 5.24 | G35: =SUM(G33:G34) -> 24.541 | H35: =SUM(H33:H34) -> 47.914 | J35: =RATE($H$11-$D$11,0,-$D35,$H35) -> -0.017872173
B36: Net Income Margin % | D36: =D35/D15 -> 0.09626838 | E36: =E35/E15 -> -0.013980743 | F36: =F35/F15 -> 0.013838089 | G36: =G35/G15 -> 0.047841098 | H36: =H35/H15 -> 0.086621988
A38: x | B38: Balance Sheet | K38: x
D40: 42004 | E40: =EOMONTH(D40,12) -> 42369 | F40: =EOMONTH(E40,12) -> 42735 | G40: =EOMONTH(F40,12) -> 43100 | H40: =EOMONTH(G40,12) -> 43465
D41: =YEAR(D40) -> 2014 | E41: =YEAR(E40) -> 2015 | F41: =YEAR(F40) -> 2016 | G41: =YEAR(G40) -> 2017 | H41: =YEAR(H40) -> 2018
B43: Assets
B45: Cash and Cash Equivalents | D45: 35.937 | E45: =D45+E114 -> 39.93 | F45: =E45+F114 -> 60.603 | G45: =F45+G114 -> 23.069 | H45: =G45+H114 -> 22.014
B46: Accounts Receivable | D46: 48.573 | E46: 53.97 | F46: 72.971 | G46: 117.711 | H46: 130.769
B47: Inventory | D47: 66.9051 | E47: 74.339 | F47: 59.19 | G47: 111.769 | H47: 124.506
B48: Income Tax Recoverable | D48: 9.8505 | E48: 10.945 | F48: 2.343 | G48: 3.02 | H48: 4.228
B49: Deferred Income Taxes | D49: 12.4524 | E49: 13.836 | F49: 8.11 | G49: 4.909 | H49: 4.367
B50: Prepaid Expenses and Other Assets | D50: 16.812 | E50: 18.68 | F50: 22.768 | G50: 33.326 | H50: 40.331
B51: Total Current Assets | D51: =SUM(D45:D50) -> 190.53 | E51: =SUM(E45:E50) -> 211.7 | F51: =SUM(F45:F50) -> 225.985 | G51: =SUM(G45:G50) -> 293.804 | H51: =SUM(H45:H50) -> 326.215
B53: Net Plant, Property, & Equipment (PP&E) | D53: 178 | E53: 183.025 | F53: 182.686 | G53: 203.068 | H53: 209.933
B54: Goodwill | D54: 29.394 | E54: 29.394 | F54: 29.394 | G54: 32.732 | H54: 32.732
...

Sheet Capex & NWC Drivers
B2: Northwind Industries
B3: Capex & NWC Drivers | M3: Draft - Preliminary & Confidential
B5: $ in millions, except where otherwise denoted
A6: x | B6: Capex Drivers | N6: x
B8: Select Case ([=1] Base Case; [=2] Upside Case; [=3] Downside Case) >>> | E8: ='P&L Drivers'!$E$8 -> 1
B10: Operating Scenario >>> | E10: =CHOOSE($E$8,B22,B23,B24) -> Base Case
D12: 42004 | E12: =EOMONTH(D12,12) -> 42369 | F12: =EOMONTH(E12,12) -> 42735 | G12: =EOMONTH(F12,12) -> 43100 | H12: =EOMONTH(G12,12) -> 43465 | I12: =EOMONTH(H12,12) -> 43830 | J12: =EOMONTH(I12,12) -> 44196 | K12: =EOMONTH(J12,12) -> 44561 | L12: =EOMONTH(K12,12) -> 44926 | M12: =EOMONTH(L12,12) -> 45291
D13: =YEAR(D12) -> 2014 | E13: =YEAR(E12) -> 2015 | F13: =YEAR(F12) -> 2016 | G13: =YEAR(G12) -> 2017 | H13: =YEAR(H12) -> 2018 | I13: =YEAR(I12) -> 2019 | J13: =YEAR(J12) -> 2020 | K13: =YEAR(K12) -> 2021 | ... M13: =YEAR(M12) -> 2023
A15: x | B15: Capex: % of Total Revenue | N15: x
B17: Capex | D17: ='Historical Financials'!D105 -> -52.373218 | E17: ='Historical Financials'!E105 -> -34.937018 | F17: ='Historical Financials'!F105 -> -37.073 | G17: ='Historical Financials'!G105 -> -47.387 | H17: ='Historical Financials'!H105 -> -63.662 | I17: =-PRODUCT(I$20,SUM('P&L Drivers'!I17,'P&L Drivers'!I28)) -> -74.902428 | J17: =-PRODUCT(J$20,SUM('P&L Drivers'!J17,'P&L Drivers'!J28)) -> -84.563963 | K17: =-PRODUCT(K$20,SUM('P&L Drivers'!K17,'P&L Drivers'!K28)) -> -95.517345 | L17: =-PRODUCT(L$20,SUM('P&L Drivers'!L17,'P&L Drivers'!L28)) -> -107.94061 | M17: =-PRODUCT(M$20,SUM('P&L Drivers'!M17,'P&L Drivers'!M28)) -> -122.03694
B18: % of Total Revenue | D18: =-D17/'Historical Financials'!D15 -> 0.09790448 | E18: =-E17/'Historical Financials'!E15 -> 0.09790448 | F18: =-F17/'Historical Financials'!F15 -> 0.09790448 | G18: =-G17/'Historical Financials'!G15 -> 0.092377902 | H18: =-H17/'Historical Financials'!H15 -> 0.11509223 | I18: =-I17/SUM('P&L Drivers'!I17,'P&L Drivers'!I28) -> 0.12 | J18: =-J17/SUM('P&L Drivers'!J17,'P&L Drivers'!J28) -> 0.12 | K18: =-K17/SUM('P&L Drivers'!K17,'P&L Drivers'!K28) -> 0.12 | L18: =-L17/SUM('P&L Drivers'!L17,'P&L Drivers'!L28) -> 0.12 | M18: =-M17/SUM('P&L Drivers'!M17,'P&L Drivers'!M28) -> 0.12
B20: ="Operating Scenario: "&$E$10&" % of Total Revenue" -> Operating Scenario: Base Case % of Total Revenue | I20: =INDEX(I$22:I$24,MATCH($E$10,$B$22:$B$24,0),0) -> 0.12 | J20: =INDEX(J$22:J$24,MATCH($E$10,$B$22:$B$24,0),0) -> 0.12 | K20: =INDEX(K$22:K$24,MATCH($E$10,$B$22:$B$24,0),0) -> 0.12 | L20: =INDEX(L$22:L$24,MATCH($E$10,$B$22:$B$24,0),0) -> 0.12 | M20: =INDEX(M$22:M$24,MATCH($E$10,$B$22:$B$24,0),0) -> 0.12
B22: Base Case | I22: 0.12 | J22: 0.12 | K22: 0.12 | L22: 0.12 | M22: 0.12
B23: Upside Case | I23: 0.1 | J23: 0.1 | K23: 0.1 | L23: 0.1 | M23: 0.1
B24: Downside Case | I24: 0.15 | J24: 0.15 | K24: 0.15 | L24: 0.15 | M24: 0.15
A26: x | B26: NWC Drivers | N26: x
D28: 42004 | E28: =EOMONTH(D28,12) -> 42369 | F28: =EOMONTH(E28,12) -> 42735 | G28: =EOMONTH(F28,12) -> 43100 | H28: =EOMONTH(G28,12) -> 43465 | I28: =EOMONTH(H28,12) -> 43830 | J28: =EOMONTH(I28,12) -> 44196 | K28: =EOMONTH(J28,12) -> 44561 | L28: =EOMONTH(K28,12) -> 44926 | M28: =EOMONTH(L28,12) -> 45291
D29: =YEAR(D28) -> 2014 | E29: =YEAR(E28) -> 2015 | F29: =YEAR(F28) -> 2016 | G29: =YEAR(G28) -> 2017 | H29: =YEAR(H28) -> 2018 | I29: =YEAR(I28) -> 2019 | J29: =YEAR(J28) -> 2020 | K29: =YEAR(K28) -> 2021 | ... M29: =YEAR(M28) -> 2023
B31: Total Revenue | D31: =SUM('P&L Drivers'!D17,'P&L Drivers'!D28) -> 534.942 | E31: =SUM('P&L Drivers'!E17,'P&L Drivers'!E28) -> 356.848 | F31: =SUM('P&L Drivers'!F17,'P&L Drivers'!F28) -> 378.665 | G31: =SUM('P&L Drivers'!G17,'P&L Drivers'!G28) -> 512.969 | H31: =SUM('P&L Drivers'!H17,'P&L Drivers'!H28) -> 553.139 | I31: =SUM('P&L Drivers'!I17,'P&L Drivers'!I28) -> 624.1869 | J31: =SUM('P&L Drivers'!J17,'P&L Drivers'!J28) -> 704.69969 | K31: =SUM('P&L Drivers'!K17,'P&L Drivers'!K28) -> 795.97787 | ... M31: =SUM('P&L Drivers'!M17,'P&L Drivers'!M28) -> 1016.9745
B32: Total COGs | D32: =-SUM('P&L Drivers'!D41,'P&L Drivers'!D52) -> 368.09903 | E32: =-SUM('P&L Drivers'!E41,'P&L Drivers'!E52) -> 286.17448 | F32: =-SUM('P&L Drivers'!F41,'P&L Drivers'!F52) -> 271.028 | G32: =-SUM('P&L Drivers'!G41,'P&L Drivers'!G52) -> 370.333 | H32: =-SUM('P&L Drivers'!H41,'P&L Drivers'!H52) -> 378.07 | I32: =-SUM('P&L Drivers'!I41,'P&L Drivers'!I52) -> 405.72149 | J32: =-SUM('P&L Drivers'!J41,'P&L Drivers'!J52) -> 458.0548 | K32: =-SUM('P&L Drivers'!K41,'P&L Drivers'!K52) -> 517.38562 | ... M32: =-SUM('P&L Drivers'!M41,'P&L Drivers'!M52) -> 661.03341
B34: Net Working Capital Schedule
B35: Accounts Receivable | D35: ='Historical Financials'!D77 -> 48.573 | E35: ='Historical Financials'!E77 -> 53.97 | F35: ='Historical Financials'!F77 -> 72.971 | G35: ='Historical Financials'!G77 -> 117.711 | H35: ='Historical Financials'!H77 -> 130.769 | I35: =PRODUCT(I$54/365.25)*I$31 -> 145.2591 | J35: =PRODUCT(J$54/365.25)*J$31 -> 163.99582 | K35: =PRODUCT(K$54/365.25)*K$31 -> 185.23784 | L35: =PRODUCT(L$54/365.25)*L$31 -> 209.33042 | M35: =PRODUCT(M$54/365.25)*M$31 -> 236.66757
B36: Inventory | D36: ='Historical Financials'!D78 -> 66.9051 | E36: ='Historical Financials'!E78 -> 74.339 | F36: ='Historical Financials'!F78 -> 59.19 | G36: ='Historical Financials'!G78 -> 111.769 | H36: ='Historical Financials'!H78 -> 124.506 | I36: =PRODUCT(I$55/365.25)*I$32 -> 111.08049 | J36: =PRODUCT(J$55/365.25)*J$32 -> 125.40857 | K36: =PRODUCT(K$55/365.25)*K$32 -> 141.65246 | L36: =PRODUCT(L$55/365.25)*L$32 -> 160.0762 | M36: =PRODUCT(M$55/365.25)*M$32 -> 180.98109
B37: Income Tax Recoverable | D37: ='Historical Financials'!D79 -> 9.8505 | E37: ='Historical Financials'!E79 -> 10.945 | F37: ='Historical Financials'!F79 -> 2.343 | G37: ='Historical Financials'!G79 -> 3.02 | H37: ='Historical Financials'!H79 -> 4.228 | I37: =PRODUCT(I$56,I$31) -> 6.241869 | J37: =PRODUCT(J$56,J$31) -> 7.0469969 | K37: =PRODUCT(K$56,K$31) -> 7.9597787 | L37: =PRODUCT(L$56,L$31) -> 8.9950511 | M37: =PRODUCT(M$56,M$31) -> 10.169745
B38: Deferred Income Taxes | D38: ='Historical Financials'!D80 -> 12.4524 | E38: ='Historical Financials'!E80 -> 13.836 | F38: ='Historical Financials'!F80 -> 8.11 | G38: ='Historical Financials'!G80 -> 4.909 | H38: ='Historical Financials'!H80 -> 4.367 | I38: =PRODUCT(I$57,I$31) -> 9.3628035 | J38: =PRODUCT(J$57,J$31) -> 10.570495 | K38: =PRODUCT(K$57,K$31) -> 11.939668 | L38: =PRODUCT(L$57,L$31) -> 13.492577 | M38: =PRODUCT(M$57,M$31) -> 15.254617
B39: Prepaid Expenses and Other Assets | D39: ='Historical Financials'!D81 -> 16.812 | E39: ='Historical Financials'!E81 -> 18.68 | F39: ='Historical Financials'!F81 -> 22.768 | G39: ='Historical Financials'!G81 -> 33.326 | H39: ='Historical Financials'!H81 -> 40.331 | I39: =PRODUCT(I$58,I$32) -> 34.486326 | J39: =PRODUCT(J$58,J32) -> 38.934658 | K39: =PRODUCT(K$58,K32) -> 43.977778 | L39: =PRODUCT(L$58,L32) -> 49.697657 | M39: =PRODUCT(M$58,M32) -> 56.18784
B40: Current Assets (Excluding Cash) | D40: =SUM(D35:D39) -> 154.593 | E40: =SUM(E35:E39) -> 171.77 | F40: =SUM(F35:F39) -> 165.382 | G40: =SUM(G35:G39) -> 270.735 | H40: =SUM(H35:H39) -> 304.201 | I40: =SUM(I35:I39) -> 306.43059 | J40: =SUM(J35:J39) -> 345.95654 | K40: =SUM(K35:K39) -> 390.76752 | ... M40: =SUM(M35:M39) -> 499.26086
B42: Accounts Payable | D42: ='Historical Financials'!D84 -> 13 | E42: ='Historical Financials'!E84 -> 15.992 | F42: ='Historical Financials'!F84 -> 23.785 | G42: ='Historical Financials'!G84 -> 57.443 | H42: ='Historical Financials'!H84 -> 43.603 | I42: =(I60/365.25)*I32 -> 44.432195 | J42: =(J60/365.25)*J32 -> 50.163428 | K42: =(K60/365.25)*K32 -> 56.660985 | L42: =(L60/365.25)*L32 -> 64.03048 | M42: =(M60/365.25)*M32 -> 72.392434
B43: Deferred Revenue | D43: ='Historical Financials'!D85 -> 16 | E43: ='Historical Financials'!E85 -> 14.007 | F43: ='Historical Financials'!F85 -> 11.987 | G43: ='Historical Financials'!G85 -> 25.924 | H43: ='Historical Financials'!H85 -> 10.65 | I43: =PRODUCT(I$61,I$31) -> 18.725607 | J43: =PRODUCT(J$61,J$31) -> 21.140991 | K43: =PRODUCT(K$61,K$31) -> 23.879336 | L43: =PRODUCT(L$61,L$31) -> 26.985153 | M43: =PRODUCT(M$61,M$31) -> 30.509235
B44: Warranty Reserves | D44: ='Historical Financials'!D86 -> 2.5 | E44: ='Historical Financials'!E86 -> 2.251 | F44: ='Historical Financials'!F86 -> 1.698 | G44: ='Historical Financials'!G86 -> 3.103 | H44: ='Historical Financials'!H86 -> 3.719 | I44: =PRODUCT(I$62,I$31) -> 3.1209345 | J44: =PRODUCT(J$62,J$31) -> 3.5234985 | K44: =PRODUCT(K$62,K$31) -> 3.9798894 | L44: =PRODUCT(L$62,L$31) -> 4.4975255 | M44: =PRODUCT(M$62,M$31) -> 5.0848724
B45: Income Taxes Payable | D45: ='Historical Financials'!D87 -> 0 | E45: ='Historical Financials'!E87 -> 0 | F45: ='Historical Financials'!F87 -> 3.433 | G45: ='Historical Financials'!G87 -> 2.336 | H45: ='Historical Financials'!H87 -> 6.894 | I45: =PRODUCT(I$63,I$32) -> 4.0572149 | J45: =PRODUCT(J$63,J$32) -> 4.580548 | K45: =PRODUCT(K$63,K$32) -> 5.1738562 | L45: =PRODUCT(L$63,L$32) -> 5.8467832 | M45: =PRODUCT(M$63,M$32) -> 6.6103341
B46: Accrued and Other Current Liabilities | D46: ='Historical Financials'!D88 -> 23 | E46: ='Historical Financials'!E88 -> 27.075 | F46: ='Historical Financials'!F88 -> 32.289 | G46: ='Historical Financials'!G88 -> 34.069 | H46: ='Historical Financials'!H88 -> 41.572 | I46: =PRODUCT(I$64,I$32) -> 40.572149 | J46: =PRODUCT(J$64,J$32) -> 45.80548 | K46: =PRODUCT(K$64,K$32) -> 51.738562 | L46: =PRODUCT(L$64,L$32) -> 58.467832 | M46: =PRODUCT(M$64,M$32) -> 66.103341
B47: Current Liabilities | D47: =SUM(D42:D46) -> 54.5 | E47: =SUM(E42:E46) -> 59.325 | F47: =SUM(F42:F46) -> 73.192 | G47: =SUM(G42:G46) -> 122.875 | H47: =SUM(H42:H46) -> 106.438 | I47: =SUM(I42:I46) -> 110.9081 | J47: =SUM(J42:J46) -> 125.21394 | K47: =SUM(K42:K46) -> 141.43263 | ... M47: =SUM(M42:M46) -> 180.70022
B49: Net Working Capital (NWC) | D49: =D40-D47 -> 100.093 | E49: =E40-E47 -> 112.445 | F49: =F40-F47 -> 92.19 | G49: =G40-G47 -> 147.86 | H49: =H40-H47 -> 197.763 | I49: =I40-I47 -> 195.52249 | J49: =J40-J47 -> 220.7426 | K49: =K40-K47 -> 249.33489 | ... M49: =M40-M47 -> 318.56064
B50: Δ NWC | D50: ='Historical Financials'!D92 -> -8.7 | E50: =D49-E49 -> -12.352 | F50: =E49-F49 -> 20.255 | G50: =F49-G49 -> -55.67 | H50: =G49-H49 -> -49.903 | I50: =H49-I49 -> 2.2405123 | J50: =I49-J49 -> -25.220108 | K50: =J49-K49 -> -28.592298 | L50: =K49-L49 -> -32.429233 | M50: =L49-M49 -> -36.796518
B52: NWC Drivers
B54: Days Sales Outstanding (DSO) | D54: =D35/D31*365.25 -> 33.164882 | E54: =E35/E31*365.25 -> 55.240726 | F54: =F35/F31*365.25 -> 70.38585 | G54: =G35/G31*365.25 -> 83.81392 | H54: =H35/H31*365.25 -> 86.349683 | I54: 85 | J54: =$I$54 -> 85 | K54: =$I$54 -> 85 | L54: =$I$54 -> 85 | M54: =$I$54 -> 85
B55: Inventory Days | D55: =D36/D32*365.25 -> 66.387264 | E55: =E36/E32*365.25 -> 94.880296 | F55: =F36/F32*365.25 -> 79.76721 | G55: =G36/G32*365.25 -> 110.23492 | H55: =H36/H32*365.25 -> 120.28412 | I55: 100 | J55: =$I$55 -> 100 | K55: =$I$55 -> 100 | L55: =$I$55 -> 100 | M55: =$I$55 -> 100
B56: Income Tax Recoverable as % of Total Revenue | D56: =D37/D31 -> 0.018414146 | E56: =E37/E31 -> 0.030671322 | F56: =F37/F31 -> 0.0061875272 | G56: =G37/G31 -> 0.0058872953 | H56: =H37/H31 -> 0.0076436483 | I56: 0.01 | J56: =$I$56 -> 0.01 | K56: =$I$56 -> 0.01 | L56: =$I$56 -> 0.01 | M56: =$I$56 -> 0.01
B57: Deferred Income Taxes as % of Total Revenue | D57: =D38/D31 -> 0.023278038 | E57: =E38/E31 -> 0.038772811 | F57: =F38/F31 -> 0.021417348 | G57: =G38/G31 -> 0.0095697791 | H57: =H38/H31 -> 0.0078949414 | I57: 0.015 | J57: =$I$57 -> 0.015 | K57: =$I$57 -> 0.015 | L57: =$I$57 -> 0.015 | M57: =$I$57 -> 0.015
...

Sheet P&L Drivers
B2: Northwind Industries
B3: P&L Drivers | M3: Draft - Preliminary & Confidential
B5: $ in millions, except where otherwise denoted
A6: x | B6: Revenue Drivers | N6: x
B8: Select Case ([=1] Base Case; [=2] Upside Case; [=3] Downside Case) >>> | E8: 1
B10: Operating Scenario >>> | E10: =CHOOSE($E$8,B22,B23,B24) -> Base Case
D12: 42004 | E12: =EOMONTH(D12,12) -> 42369 | F12: =EOMONTH(E12,12) -> 42735 | G12: =EOMONTH(F12,12) -> 43100 | H12: =EOMONTH(G12,12) -> 43465 | I12: =EOMONTH(H12,12) -> 43830 | J12: =EOMONTH(I12,12) -> 44196 | K12: =EOMONTH(J12,12) -> 44561 | L12: =EOMONTH(K12,12) -> 44926 | M12: =EOMONTH(L12,12) -> 45291
D13: =YEAR(D12) -> 2014 | E13: =YEAR(E12) -> 2015 | F13: =YEAR(F12) -> 2016 | G13: =YEAR(G12) -> 2017 | H13: =YEAR(H12) -> 2018 | I13: =YEAR(I12) -> 2019 | J13: =YEAR(J12) -> 2020 | K13: =YEAR(K12) -> 2021 | ... M13: =YEAR(M12) -> 2023
A15: x | B15: Products Revenue: Annual Growth Rates | N15: x
B17: Products Revenue | D17: ='Historical Financials'!D13 -> 236.277 | E17: ='Historical Financials'!E13 -> 148.565 | F17: ='Historical Financials'!F13 -> 134.755 | G17: ='Historical Financials'!G13 -> 211.313 | H17: ='Historical Financials'!H13 -> 238.459 | I17: =PRODUCT(H17,1+I$20) -> 262.3049 | J17: =PRODUCT(I17,1+J$20) -> 288.53539 | K17: =PRODUCT(J17,1+K$20) -> 317.38893 | L17: =PRODUCT(K17,1+L$20) -> 349.12782 | M17: =PRODUCT(L17,1+M$20) -> 384.0406
B18: Y-O-Y Growth % | E18: =E17/D17-1 -> -0.3712253 | F18: =F17/E17-1 -> -0.092955945 | G18: =G17/F17-1 -> 0.56812734 | H18: =H17/G17-1 -> 0.12846346 | I18: =I17/H17-1 -> 0.1 | J18: =J17/I17-1 -> 0.1 | K18: =K17/J17-1 -> 0.1 | L18: =L17/K17-1 -> 0.1 | M18: =M17/L17-1 -> 0.1
B20: ="Operating Scenario: "&$E$10&" Escalation Factors Per Annum" -> Operating Scenario: Base Case Escalation Factors Per Annum | I20: =INDEX(I$22:I$24,MATCH($E$10,$B$22:$B$24,0),0) -> 0.1 | J20: =INDEX(J$22:J$24,MATCH($E$10,$B$22:$B$24,0),0) -> 0.1 | K20: =INDEX(K$22:K$24,MATCH($E$10,$B$22:$B$24,0),0) -> 0.1 | L20: =INDEX(L$22:L$24,MATCH($E$10,$B$22:$B$24,0),0) -> 0.1 | M20: =INDEX(M$22:M$24,MATCH($E$10,$B$22:$B$24,0),0) -> 0.1
B22: Base Case | I22: 0.1 | J22: 0.1 | K22: 0.1 | L22: 0.1 | M22: 0.1
B23: Upside Case | I23: 0.2 | J23: 0.2 | K23: 0.2 | L23: 0.2 | M23: 0.2
B24: Downside Case | I24: 0.05 | J24: 0.05 | K24: 0.05 | L24: 0.05 | M24: 0.05
A26: x | B26: Services Revenue: Annual Growth Rates | N26: x
B28: Services Revenue | D28: ='Historical Financials'!D14 -> 298.665 | E28: ='Historical Financials'!E14 -> 208.283 | F28: ='Historical Financials'!F14 -> 243.91 | G28: ='Historical Financials'!G14 -> 301.656 | H28: ='Historical Financials'!H14 -> 314.68 | I28: =PRODUCT(H28,1+I$31) -> 361.882 | J28: =PRODUCT(I28,1+J$31) -> 416.1643 | K28: =PRODUCT(J28,1+K$31) -> 478.58894 | L28: =PRODUCT(K28,1+L$31) -> 550.37729 | M28: =PRODUCT(L28,1+M$31) -> 632.93388
B29: Y-O-Y Growth % | E29: =E28/D28-1 -> -0.30261999 | F29: =F28/E28-1 -> 0.17105093 | G29: =G28/F28-1 -> 0.23675126 | H29: =H28/G28-1 -> 0.043175007 | I29: =I28/H28-1 -> 0.15 | J29: =J28/I28-1 -> 0.15 | K29: =K28/J28-1 -> 0.15 | L29: =L28/K28-1 -> 0.15 | M29: =M28/L28-1 -> 0.15
B31: ="Operating Scenario: "&$E$10&" Escalation Factors Per Annum" -> Operating Scenario: Base Case Escalation Factors Per Annum | I31: =INDEX(I$33:I$35,MATCH($E$10,$B$33:$B$35,0),0) -> 0.15 | J31: =INDEX(J$33:J$35,MATCH($E$10,$B$33:$B$35,0),0) -> 0.15 | K31: =INDEX(K$33:K$35,MATCH($E$10,$B$33:$B$35,0),0) -> 0.15 | L31: =INDEX(L$33:L$35,MATCH($E$10,$B$33:$B$35,0),0) -> 0.15 | M31: =INDEX(M$33:M$35,MATCH($E$10,$B$33:$B$35,0),0) -> 0.15
B33: Base Case | I33: 0.15 | J33: 0.15 | K33: 0.15 | L33: 0.15 | M33: 0.15
B34: Upside Case | I34: 0.2 | J34: 0.2 | K34: 0.2 | L34: 0.2 | M34: 0.2
B35: Downside Case | I35: 0.1 | J35: 0.1 | K35: 0.1 | L35: 0.1 | M35: 0.1
A37: x | B37: Expense Drivers | N37: x
A39: x | B39: Products COGS: % of Products Revenue | N39: x
B41: Products COGS | D41: ='Historical Financials'!D18 -> -141.08299 | E41: ='Historical Financials'!E18 -> -101.54867 | F41: ='Historical Financials'!F18 -> -85.732825 | G41: ='Historical Financials'!G18 -> -140.56916 | H41: ='Historical Financials'!H18 -> -158.4088 | I41: =-PRODUCT(I$44,I17) -> -170.49819 | J41: =-PRODUCT(J$44,J17) -> -187.548 | K41: =-PRODUCT(K$44,K17) -> -206.3028 | L41: =-PRODUCT(L$44,L17) -> -226.93308 | M41: =-PRODUCT(M$44,M17) -> -249.62639
B42: % of Products Revenue | D42: =-D41/D17 -> 0.59710842 | E42: =-E41/E17 -> 0.68353023 | F42: =-F41/F17 -> 0.63621257 | G42: =-G41/G17 -> 0.66521778 | H42: =-H41/H17 -> 0.66430204 | I42: =-I41/I17 -> 0.65 | J42: =-J41/J17 -> 0.65 | K42: =-K41/K17 -> 0.65 | ... M42: =-M41/M17 -> 0.65
B44: ="Operating Scenario: "&$E$10&" % of Products Revenue" -> Operating Scenario: Base Case % of Products Revenue | I44: =INDEX(I$46:I$48,MATCH($E$10,$B$46:$B$48,0),0) -> 0.65 | J44: =INDEX(J$46:J$48,MATCH($E$10,$B$46:$B$48,0),0) -> 0.65 | K44: =INDEX(K$46:K$48,MATCH($E$10,$B$46:$B$48,0),0) -> 0.65 | L44: =INDEX(L$46:L$48,MATCH($E$10,$B$46:$B$48,0),0) -> 0.65 | M44: =INDEX(M$46:M$48,MATCH($E$10,$B$46:$B$48,0),0) -> 0.65
B46: Base Case | I46: 0.65 | J46: 0.65 | K46: 0.65 | L46: 0.65 | M46: 0.65
B47: Upside Case | I47: 0.6 | J47: 0.6 | K47: 0.6 | L47: 0.6 | M47: 0.6
B48: Downside Case | I48: 0.7 | J48: 0.7 | K48: 0.7 | L48: 0.7 | M48: 0.7
A50: x | B50: Services COGS: % of Services Revenue | N50: x
B52: Services COGS | D52: ='Historical Financials'!D19 -> -227.01605 | E52: ='Historical Financials'!E19 -> -184.62581 | F52: ='Historical Financials'!F19 -> -185.29518 | G52: ='Historical Financials'!G19 -> -229.76384 | H52: ='Historical Financials'!H19 -> -219.6612 | I52: =-PRODUCT(I$55,I28) -> -235.2233 | J52: =-PRODUCT(J$55,J28) -> -270.5068 | K52: =-PRODUCT(K$55,K28) -> -311.08281 | L52: =-PRODUCT(L$55,L28) -> -357.74524 | M52: =-PRODUCT(M$55,M28) -> -411.40702
B53: % of Services Revenue | D53: =-D52/D28 -> 0.76010261 | E53: =-E52/E28 -> 0.88641807 | F53: =-F52/F28 -> 0.75968667 | G53: =-G52/G28 -> 0.76167501 | H53: =-H52/H28 -> 0.69804627 | I53: =-I52/I28 -> 0.65 | J53: =-J52/J28 -> 0.65 | K53: =-K52/K28 -> 0.65 | ... M53: =-M52/M28 -> 0.65
B55: ="Operating Scenario: "&$E$10&" % of Services Revenue" -> Operating Scenario: Base Case % of Services Revenue | I55: =INDEX(I$57:I$59,MATCH($E$10,$B$57:$B$59,0),0) -> 0.65 | J55: =INDEX(J$57:J$59,MATCH($E$10,$B$57:$B$59,0),0) -> 0.65 | K55: =INDEX(K$57:K$59,MATCH($E$10,$B$57:$B$59,0),0) -> 0.65 | L55: =INDEX(L$57:L$59,MATCH($E$10,$B$57:$B$59,0),0) -> 0.65 | M55: =INDEX(M$57:M$59,MATCH($E$10,$B$57:$B$59,0),0) -> 0.65
B57: Base Case | I57: 0.65 | J57: 0.65 | K57: 0.65 | L57: 0.65 | M57: 0.65
B58: Upside Case | I58: 0.6 | J58: 0.6 | K58: 0.6 | L58: 0.6 | M58: 0.6
B59: Downside Case | I59: 0.75 | J59: 0.75 | K59: 0.75 | L59: 0.75 | M59: 0.75
A61: x | B61: SG&A: % of Revenue | N61: x
B63: SG&A | D63: ='Historical Financials'!D23 -> -49.069 | E63: ='Historical Financials'!E23 -> -43.735 | F63: ='Historical Financials'!F23 -> -47.117 | G63: ='Historical Financials'!G23 -> -49.146 | H63: ='Historical Financials'!H23 -> -44.828 | I63: =-PRODUCT(I$66,SUM(I17,I28)) -> -62.41869 | J63: =-PRODUCT(J$66,SUM(J17,J28)) -> -70.469969 | K63: =-PRODUCT(K$66,SUM(K17,K28)) -> -79.597787 | L63: =-PRODUCT(L$66,SUM(L17,L28)) -> -89.950511 | M63: =-PRODUCT(M$66,SUM(M17,M28)) -> -101.69745
B64: % of Revenue | D64: =-D63/SUM(D17,D28) -> 0.091727701 | E64: =-E63/SUM(E17,E28) -> 0.12255918 | F64: =-F63/SUM(F17,F28) -> 0.12442924 | G64: =-G63/SUM(G17,G28) -> 0.095806959 | H64: =-H63/SUM(H17,H28) -> 0.08104292 | I64: =-I63/SUM(I17,I28) -> 0.1 | J64: =-J63/SUM(J17,J28) -> 0.1 | K64: =-K63/SUM(K17,K28) -> 0.1 | ... M64: =-M63/SUM(M17,M28) -> 0.1
...

Sheet Returns Model
B2: Northwind Industries
B3: Illustrative Transaction Overview & Returns Analysis | O3: Draft - Preliminary & Confidential
B5: $ in millions, except where otherwise denoted
A6: x | B6: Transaction Assumptions | P6: x
A8: x | B8: General Inputs | P8: x
B10: Effective Federal Corporate Tax Rate | E10: 0.21 | G10: Transaction Expenses (% Purchase Price) | J10: 0.01 | L10: Dividend Sweep | N10: 0
B11: Write-Up % of Identifiable Intangibles | E11: 0.15 | G11: Seller Equity Rollover (% of NewCo) | J11: 0.05 | L11: Exit Multiple | N11: 5
B12: Acquisition Purchase Date | E12: 43465 | G12: Circularity Switch | J12: 0 | L12: Sponsor Preferred Hurdle | N12: 0.08
L13: Mgmt. Promote | N13: 0.05
A15: x | B15: Purchase Assumptions | P15: x
B17: Purchase Price Derivation | G17: Net Identifiable Assets | L17: Identifiable Intangibles Write-Up
B18: LTM EBITDA (2018A) | E18: ='Historical Financials'!H25 -> 119.784 | G18: Equity Purchase Price | J18: =E23 -> 620.673 | L18: Goodwill & Identifiable Intangibles Created | O18: =J21 -> 183.897
B19: (x) Entry EV / EBITDA Multiple | E19: 5 | G19: (–) Book Value of Net Assets | J19: =-G153 -> -469.508 | L19: (–) Identifiable Intangibles Write-Up | O19: =-PRODUCT(O18,$E$11) -> -27.58455
B20: Enterprise Value | E20: =PRODUCT(E18:E19) -> 598.92 | G20: (+) Write-off of Existing Goodwill | J20: =G132 -> 32.732 | L20: (+) Deferred Tax Liability | O20: =-PRODUCT($O$19,$E$10) -> 5.7927555
B21: (–) Debt Outstanding (12/31/2018) | E21: =-'Historical Financials'!H68 -> -0.261 | G21: Goodwill & Identifiable Intangibles Created | J21: =SUM(J18:J20) -> 183.897 | L21: Goodwill Created in Transaction | O21: =SUM(O18:O20) -> 162.10521
B22: (+) Cash Balance (12/31/2018) | E22: ='Historical Financials'!H45 -> 22.014
B23: Equity Purchase Price | E23: =SUM(E20:E22) -> 620.673 | L23: Identifiable Intangibles Write-Up | O23: =O19 -> -27.58455
B24: (–) Seller Rollover | E24: =-D35 -> -16.833226 | L24: (÷) Total Amortization Period | O24: 15
B25: Adjusted Equity Purchase Price | E25: =SUM(E23:E24) -> 603.83977 | L25: Intangibles Amortization Per Annum | O25: =O23/O24 -> -1.83897
A27: x | B27: Sources & Uses (S&U) | P27: x
B29: Sources of Capital | D29: $mm | E29: % of Total | F29: Entry Multiple (LTM EBITDA) | H29: Uses of Capital | J29: $mm | K29: % of Total | L29: Entry Multiple (LTM EBITDA)
B32: Revolver | D32: =E44 -> 0 | E32: =D32/$D$37 -> 0 | F32: =D32/$E$18 -> 0 | H32: Purchase of Equity: Sponsor | J32: =E25 -> 603.83977 | K32: =J32/$J$37 -> 0.94924774 | L32: =J32/$E$18 -> 5.041072
B33: 1st Lien Bank Debt | D33: =E45 -> 179.676 | E33: =D33/$D$37 -> 0.28245413 | F33: =D33/$E$18 -> 1.5 | H33: Rollover of Equity: Seller | J33: =D35 -> 16.833226 | K33: =J33/$J$37 -> 0.026462156 | L33: =J33/$E$18 -> 0.14052984
B34: Senior Unsecured Notes | D34: =E46 -> 119.784 | E34: =D34/$D$37 -> 0.18830275 | F34: =D34/$E$18 -> 1 | H34: Refinanced Debt | J34: =-E21 -> 0.261 | K34: =J34/$J$37 -> 0.00041029702 | L34: =J34/$E$18 -> 0.0021789221
B35: Seller Rollover Equity | D35: =(D37-SUM(D32:D34))*$J$11 -> 16.833226 | E35: =D35/$D$37 -> 0.026462156 | F35: =D35/$E$18 -> 0.14052984 | H35: Financing Fees & OID | J35: =J47+H47 -> 8.9838 | K35: =J35/$J$37 -> 0.014122706 | L35: =J35/$E$18 -> 0.075
B36: Sponsor Equity | D36: =D37-SUM(D32:D35) -> 319.8313 | E36: =D36/$D$37 -> 0.50278096 | F36: =D36/$E$18 -> 2.670067 | H36: Transaction Expenses | J36: =PRODUCT($J$10,$E$23) -> 6.20673 | K36: =J36/$J$37 -> 0.009757099 | L36: =J36/$E$18 -> 0.051816019
B37: Total Sources of Capital | D37: =$J$37 -> 636.12453 | E37: =SUM(E32:E36) -> 1 | F37: =SUM(F32:F36) -> 5.3105968 | H37: Total Uses of Capital | J37: =SUM(J32:J36) -> 636.12453 | K37: =SUM(K32:K36) -> 1 | L37: =SUM(L32:L36) -> 5.3105968
A39: x | B39: Debt Capital Stack Assumptions | P39: x
D41: Leverage Multiple | E41: Debt Quantum | F41: Floor | G41: Spread to Libor | H41: OID % | I41: Commitment Fee % | J41: Financing Fee % | K41: Mandatory Amort % | L41: Sweep % | M41: Close Date | N41: Tenor | O41: Maturity Date
B44: Revolver | D44: 0 | E44: =PRODUCT($D44,$E$18) -> 0 | F44: 0.015 | G44: 400 | H44: 0.99 | I44: 0.0075 | J44: 0.02 | K44: 0 | L44: 1 | M44: =$E$12 -> 43465 | N44: 3 | O44: =EOMONTH(M44,12*N44) -> 44561
B45: 1st Lien Bank Debt (Term Loan) | D45: =$D$49*0.6 -> 1.5 | E45: =PRODUCT($D45,$E$18) -> 179.676 | F45: 0.015 | G45: 400 | H45: 0.99 | I45: N/A | J45: 0.02 | K45: 0.05 | L45: 1 | M45: =$E$12 -> 43465 | N45: 6 | O45: =EOMONTH(M45,12*N45) -> 45657
B46: Senior Unsecured Notes | D46: =$D$49*0.4 -> 1 | E46: =PRODUCT($D46,$E$18) -> 119.784 | F46: N/A | G46: 750 | H46: 0.99 | I46: N/A | J46: 0.02 | K46: 0 | L46: 1 | M46: =$E$12 -> 43465 | N46: 8 | O46: =EOMONTH(M46,12*N46) -> 46387
B47: Total Leverage | D47: =SUM(D44:D46) -> 2.5 | E47: =SUM(E44:E46) -> 299.46 | H47: =(1-H44)*E44+(1-H45)*E45+(1-H46)*E46 -> 2.9946 | J47: =SUMPRODUCT($J$44:$J$46,$E$44:$E$46) -> 5.9892
B49: Total Leverage Multiple | D49: 2.5 | F49: Revolver Undrawn Amount | H49: 50
A51: x | B51: Income Statement | P51: x
F53: Historical FYE | K53: Projected FYE
D54: ="'19E - '23E Total" -> '19E - '23E Total | E54: ="'19E - '23E CAGR" -> '19E - '23E CAGR | F54: 42004 | G54: =EOMONTH(F54,12) -> 42369 | H54: =EOMONTH(G54,12) -> 42735 | I54: =EOMONTH(H54,12) -> 43100 | J54: =EOMONTH(I54,12) -> 43465 | K54: =EOMONTH(J54,12) -> 43830 | L54: =EOMONTH(K54,12) -> 44196 | M54: =EOMONTH(L54,12) -> 44561 | N54: =EOMONTH(M54,12) -> 44926 | O54: =EOMONTH(N54,12) -> 45291
F55: =YEAR(F54) -> 2014 | G55: =YEAR(G54) -> 2015 | H55: =YEAR(H54) -> 2016 | I55: =YEAR(I54) -> 2017 | J55: =YEAR(J54) -> 2018 | K55: =YEAR(K54) -> 2019 | L55: =YEAR(L54) -> 2020 | M55: =YEAR(M54) -> 2021 | ... O55: =YEAR(O54) -> 2023
B57: Products Revenue | D57: =SUM(K57:O57) -> 1601.3976 | E57: =RATE($O$55-$K$55,0,-$K57,$O57) -> 0.1 | F57: ='Historical Financials'!D13 -> 236.277 | G57: ='Historical Financials'!E13 -> 148.565 | H57: ='Historical Financials'!F13 -> 134.755 | I57: ='Historical Financials'!G13 -> 211.313 | J57: ='Historical Financials'!H13 -> 238.459 | K57: ='P&L Drivers'!I17 -> 262.3049 | L57: ='P&L Drivers'!J17 -> 288.53539 | M57: ='P&L Drivers'!K17 -> 317.38893 | N57: ='P&L Drivers'!L17 -> 349.12782 | O57: ='P&L Drivers'!M17 -> 384.0406
B58: (+) Services Revenue | D58: =SUM(K58:O58) -> 2439.9464 | E58: =RATE($O$55-$K$55,0,-$K58,$O58) -> 0.15 | F58: ='Historical Financials'!D14 -> 298.665 | G58: ='Historical Financials'!E14 -> 208.283 | H58: ='Historical Financials'!F14 -> 243.91 | I58: ='Historical Financials'!G14 -> 301.656 | J58: ='Historical Financials'!H14 -> 314.68 | K58: ='P&L Drivers'!I28 -> 361.882 | L58: ='P&L Drivers'!J28 -> 416.1643 | M58: ='P&L Drivers'!K28 -> 478.58894 | N58: ='P&L Drivers'!L28 -> 550.37729 | O58: ='P&L Drivers'!M28 -> 632.93388
...
