Workbook
Name circ: 'LBO Model'!$O$5
Name circ2: #REF!
Name IQ_CH: 110000
Name IQ_CQ: 5000
Name IQ_CY: 10000
Name IQ_DAILY: 500000
Name IQ_FH: 100000
Name IQ_FQ: 500
Name IQ_FY: 1000
Name IQ_LTM: 2000
Name IQ_MONTH: 15000
Name IQ_NTM: 6000
Name IQ_WEEK: 50000
Name IQ_YTD: 3000
Name recap: 'LBO Model'!$D$23

Sheet Assumptions
B2: Balance Sheet Assumptions
F3: Pre-
B4: Balance Sheet Item | F4: Transaction | H4: Operating Assumptions
B5: Cash | F5: ='LBO Model'!F55 -> 200
B6: Accounts Receivable | F6: ='LBO Model'!F56 -> 200 | H6: 30 Days Sales
B7: Inventory | F7: ='LBO Model'!F57 -> 250 | H7: 60 Days COGS
B8: Prepaid Expenses | F8: ='LBO Model'!F58 -> 50 | H8: 2.0% of Revenue
B9: Total Current Assets | F9: =SUM(F5:F8) -> 700
B11: Property, Plant & Equipment | F11: ='LBO Model'!F61 -> 2000
B12: Capitalized Financing Fees | F12: ='LBO Model'!F77 -> 0 | H12: Amortized over 7 years
B13: Goodwill | F13: ='LBO Model'!F62 -> 1300
B14: Intangible Assets | F14: ='LBO Model'!F63 -> 0 | H14: 10% of Step-Up. Amortized over 15 years
B15: Total Assets | F15: =SUM(F11:F14)+F9 -> 4000
B17: Accounts Payable | F17: ='LBO Model'!F66 -> 200 | H17: 60 Days COGS
B18: Accrued Liabilities | F18: ='LBO Model'!F67 -> 50 | H18: 2.0% of Revenue
B19: Total Current Liabilities | F19: =SUM(F17:F18) -> 250
B21: Existing Debt | F21: ='LBO Model'!F70 -> 2500 | H21: Paid down
B22: Revolver | F22: ='LBO Model'!F71 -> 0
B23: Recap Debt | F23: ='LBO Model'!F72 -> 0
B24: Bank Debt | F24: ='LBO Model'!F73 -> 0
B25: Senior Notes | F25: ='LBO Model'!F74 -> 0
B26: Total Debt Outstanding | F26: =SUM(F21:F25) -> 2500
B28: Deferred Tax Liability | F28: ='LBO Model'!F78 -> 0 | H28: 10% of Step-Up. Amortized over 15 years
B30: Shareholder Equity | F30: ='LBO Model'!F80 -> 1250
B31: Total Liabilities and Equity | F31: =F26+F28+F30+F19 -> 4000

Sheet LBO Model
B4: Transaction Drivers | O4: Circ
O5: 1
B6: Model Assumptions
B7: Entry Valuation
B8: Entry LTM EBITDA | F8: =G129 -> 500 | I8: 5 Year Returns
B9: (x) Entry Multiple | F9: 10 | I9: IRR
B10: Purchase Enterprise Value | F10: =F8*F9 -> 5000 | I10: MoM
B11: Less: Debt | F11: =-F75 -> -2500
B12: Plus: Cash | F12: =F55 -> 200
B13: Equity Value | F13: =SUM(F10:F12) -> 2700
B15: Transaction
B16: LTM Exit Multiple | F16: 10
B17: Tax Rate | F17: 0.38
B18: Cash to B/S | F18: 100
B19: Transaction Expenses | F19: 25
B21: Debt | F21: (x) EBITDA
B22: Total Leverage | F22: 6 | H22: L+ Floor | I22: Rate | J22: Fee (%) | K22: Fee ($) | L22: Year | M22: Multiple
B23: Recap Debt | D23: 1 | F23: 0 | H23: 0.01 | I23: 400 | J23: 0 | K23: =J23*F32 -> 0 | L23: 2023 | M23: 6
B24: PIK Debt | F24: =F33/F29 -> 3 | H24: 0 | I24: 0.08 | J24: 0.02 | K24: =J24*F33 -> 30
B25: Senior Notes | F25: =MAX(F22-F24,0) -> 3 | H25: 0 | I25: 0.07 | J25: 0.02 | K25: =J25*F34 -> 30
B28: Revolver Capacity | F28: 300 | H28: 0.01 | I28: 400 | J28: 0 | K28: =J28*F28 -> 0
B29: Leverageable EBITDA | F29: =G129 -> 500
B31: Sources & Uses
B32: Sources | I32: Uses
B33: PIK Debt | F33: 1500 | I33: Purchase Equity Value | M33: =F13 -> 2700
B34: Senior Notes | F34: =F25*$F$29 -> 1500 | I34: Refinancing Net Debt | M34: =-SUM(F11:F12) -> 2300
B35: Total Debt | F35: =SUM(F33:F34) -> 3000 | I35: Cash to B/S | M35: =F18 -> 100
I36: Underwriting Fees | M36: =SUM(K23:K28) -> 60
B37: Equity Investment | F37: =MAX(F38-F35,0) -> 2185 | I37: Transaction Expenses | M37: =F19 -> 25 | O37: Check
B38: Total Sources | F38: =M38 -> 5185 | I38: Total Uses | M38: =SUM(M33:M37) -> 5185 | O38: =M38-F38 -> 0
B40: Goodwill Calculation
B42: Purchase Equity Value | F42: =M33 -> 2700
B43: Less: Book Value of Equity | F43: =-F80 -> -1250
B44: Plus: Existing Goodwill | F44: =F62 -> 1300 | H44: % of
B45: Step-Up of Equity | F45: =SUM(F42:F44) -> 2750 | H45: Step-Up | I45: Years | J45: Annual
B46: Less: Write-Up of Intangible Assets | F46: =-H46*$F$45 -> -275 | H46: 0.1 | I46: 15 | J46: =-F46/I46 -> 18.333333
B47: Plus: Deferred Tax Liability | F47: =-F17*$F$46 -> 104.5 | I47: 15 | J47: =F47/I47 -> 6.9666667
B48: Pro Forma Goodwill | F48: =SUM(F45:F47) -> 2579.5
B51: Closing Balance Sheet
F53: Pre- | K53: Pro
...
