Workbook
Name IQ_CH: 110000
Name IQ_CQ: 5000
Name IQ_CY: 10000
Name IQ_DAILY: 500000
Name IQ_FH: 100000
Name IQ_FQ: 500
Name IQ_FY: 1000
Name IQ_LTM: 2000
Name IQ_MONTH: 15000
Name IQ_NTM: 6000
Name IQ_WEEK: 50000
Name IQ_YTD: 3000

Sheet Summary Annual Financials
A2: x | B2: Historical & Projected Annual Financial Summary | O2: x
B4: Annual Historical & Forecasted P&L
C6: Historical FYE | G6: Projected FYE
C7: 42735 | D7: =EOMONTH(C7,12) -> 43100 | E7: =EOMONTH(D7,12) -> 43465 | F7: =EOMONTH(E7,12) -> 43830 | G7: =EOMONTH(F7,12) -> 44196 | H7: =EOMONTH(G7,12) -> 44561 | I7: =EOMONTH(H7,12) -> 44926 | J7: =EOMONTH(I7,12) -> 45291 | K7: =EOMONTH(J7,12) -> 45657 | M7: ="'16A - '19A" -> '16A - '19A | N7: ="'20E - '24E" -> '20E - '24E
C8: =YEAR(C7) -> 2016 | D8: =YEAR(D7) -> 2017 | E8: =YEAR(E7) -> 2018 | F8: =YEAR(F7) -> 2019 | G8: =YEAR(G7) -> 2020 | H8: =YEAR(H7) -> 2021 | I8: =YEAR(I7) -> 2022 | J8: =YEAR(J7) -> 2023 | K8: =YEAR(K7) -> 2024 | M8: CAGR | N8: CAGR
B10: Subscription ACV | C10: ='Operating Model'!D150 -> 10583 | D10: ='Operating Model'!E150 -> 13462 | E10: ='Operating Model'!F150 -> 13698 | F10: ='Operating Model'!G150 -> 14334.923 | G10: ='Operating Model'!H150 -> 25086.356 | H10: ='Operating Model'!I150 -> 44780.935 | I10: ='Operating Model'!J150 -> 66322.846 | J10: ='Operating Model'!K150 -> 98798.763 | K10: ='Operating Model'!L150 -> 137301.22 | M10: =IFERROR(RATE($F$8-$C$8,0,-$C10,$F10),"N/A") -> 0.1064425 | N10: =IFERROR(RATE($K$8-$G$8,0,-$G10,$K10),"N/A") -> 0.52953425
B11: (+) Professional Services ACV | C11: ='Operating Model'!D151 -> 304 | D11: ='Operating Model'!E151 -> 1197 | E11: ='Operating Model'!F151 -> 2481 | F11: ='Operating Model'!G151 -> 10615.65 | G11: ='Operating Model'!H151 -> 16931.044 | H11: ='Operating Model'!I151 -> 26725 | I11: ='Operating Model'!J151 -> 35636.662 | J11: ='Operating Model'!K151 -> 46493.536 | K11: ='Operating Model'!L151 -> 58843.381 | M11: =IFERROR(RATE($F$8-$C$8,0,-$C11,$F11),"N/A") -> 2.2685691 | N11: =IFERROR(RATE($K$8-$G$8,0,-$G11,$K11),"N/A") -> 0.36537979
B12: (+) Other ACV | C12: ='Operating Model'!D152 -> 0 | D12: ='Operating Model'!E152 -> 147.865 | E12: ='Operating Model'!F152 -> 337.7 | F12: ='Operating Model'!G152 -> 0.5 | G12: ='Operating Model'!H152 -> 0 | H12: ='Operating Model'!I152 -> 0 | I12: ='Operating Model'!J152 -> 0 | J12: ='Operating Model'!K152 -> 0 | K12: ='Operating Model'!L152 -> 0 | M12: =IFERROR(RATE($F$8-$C$8,0,-$C12,$F12),"N/A") -> N/A | N12: =IFERROR(RATE($K$8-$G$8,0,-$G12,$K12),"N/A") -> N/A
B13: Total ACV (Bookings) | C13: =SUM(C10:C12) -> 10887 | D13: =SUM(D10:D12) -> 14806.865 | E13: =SUM(E10:E12) -> 16516.7 | F13: =SUM(F10:F12) -> 24951.073 | G13: =SUM(G10:G12) -> 42017.4 | H13: =SUM(H10:H12) -> 71505.935 | I13: =SUM(I10:I12) -> 101959.51 | J13: =SUM(J10:J12) -> 145292.3 | K13: =SUM(K10:K12) -> 196144.6 | M13: =IFERROR(RATE($F$8-$C$8,0,-$C13,$F13),"N/A") -> 0.31843988 | N13: =IFERROR(RATE($K$8-$G$8,0,-$G13,$K13),"N/A") -> 0.46989664
B14: Y-O-Y Growth % | D14: =D13/C13-1 -> 0.36005006 | E14: =E13/D13-1 -> 0.11547583 | F14: =F13/E13-1 -> 0.51065724 | G14: =G13/F13-1 -> 0.68399174 | H14: =H13/G13-1 -> 0.70181722 | I14: =I13/H13-1 -> 0.42588875 | J14: =J13/I13-1 -> 0.425 | K14: =K13/J13-1 -> 0.35
B16: Subscription Revenue | C16: ='Operating Model'!D160 -> 6452.948 | D16: ='Operating Model'!E160 -> 9384.025 | E16: ='Operating Model'!F160 -> 11241.66 | F16: ='Operating Model'!G160 -> 11937.494 | G16: ='Operating Model'!H160 -> 16914.655 | H16: ='Operating Model'!I160 -> 24733 | I16: ='Operating Model'!J160 -> 48670.188 | J16: ='Operating Model'!K160 -> 72718.102 | K16: ='Operating Model'!L160 -> 104964.84 | M16: =IFERROR(RATE($F$8-$C$8,0,-$C16,$F16),"N/A") -> 0.22758525 | N16: =IFERROR(RATE($K$8-$G$8,0,-$G16,$K16),"N/A") -> 0.57832043
B17: (+) Professional Services Revenue | C17: ='Operating Model'!D161 -> 3852.46 | D17: ='Operating Model'!E161 -> 1107.899 | E17: ='Operating Model'!F161 -> 1685.792 | F17: ='Operating Model'!G161 -> 4044.0992 | G17: ='Operating Model'!H161 -> 12492.517 | H17: ='Operating Model'!I161 -> 19325 | I17: ='Operating Model'!J161 -> 27638.311 | J17: ='Operating Model'!K161 -> 35993.517 | K17: ='Operating Model'!L161 -> 47694.205 | M17: =IFERROR(RATE($F$8-$C$8,0,-$C17,$F17),"N/A") -> 0.016313959 | N17: =IFERROR(RATE($K$8-$G$8,0,-$G17,$K17),"N/A") -> 0.39782859
B18: (+) Other Revenue | C18: ='Operating Model'!D162 -> 0 | D18: ='Operating Model'!E162 -> 0 | E18: ='Operating Model'!F162 -> 0 | F18: ='Operating Model'!G162 -> 0 | G18: ='Operating Model'!H162 -> 0 | H18: ='Operating Model'!I162 -> 0 | I18: ='Operating Model'!J162 -> 0 | J18: ='Operating Model'!K162 -> 0 | K18: ='Operating Model'!L162 -> 0 | M18: =IFERROR(RATE($F$8-$C$8,0,-$C18,$F18),"N/A") -> N/A | N18: =IFERROR(RATE($K$8-$G$8,0,-$G18,$K18),"N/A") -> N/A
B19: Total Revenue | C19: =SUM(C16:C18) -> 10305.408 | D19: =SUM(D16:D18) -> 10491.924 | E19: =SUM(E16:E18) -> 12927.452 | F19: =SUM(F16:F18) -> 15981.593 | G19: =SUM(G16:G18) -> 29407.172 | H19: =SUM(H16:H18) -> 44058 | I19: =SUM(I16:I18) -> 76308.499 | J19: =SUM(J16:J18) -> 108711.62 | K19: =SUM(K16:K18) -> 152659.05 | M19: =IFERROR(RATE($F$8-$C$8,0,-$C19,$F19),"N/A") -> 0.15749278 | N19: =IFERROR(RATE($K$8-$G$8,0,-$G19,$K19),"N/A") -> 0.5094451
B20: Y-O-Y Growth % | D20: =D19/C19-1 -> 0.018098847 | E20: =E19/D19-1 -> 0.23213359 | F20: =F19/E19-1 -> 0.23625235 | G20: =G19/F19-1 -> 0.84006515 | H20: =H19/G19-1 -> 0.49820595 | I20: =I19/H19-1 -> 0.73200098 | J20: =J19/I19-1 -> 0.42463317 | K20: =K19/J19-1 -> 0.40425698
B21: ARR * | C21: ='Operating Model'!D100 -> 5291.5 | D21: ='Operating Model'!E100 -> 9367 | E21: ='Operating Model'!F100 -> 11661 | F21: ='Operating Model'!G100 -> 14339 | G21: ='Operating Model'!H100 -> 19355 | H21: ='Operating Model'!I100 -> 34271 | I21: ='Operating Model'!J100 -> 55116 | J21: ='Operating Model'!K100 -> 82992 | K21: ='Operating Model'!L100 -> 116931
B24: (–) Cost of Goods Sold (Subscription) | C24: ='Operating Model'!D166 -> 0 | D24: ='Operating Model'!E166 -> -2926 | E24: ='Operating Model'!F166 -> -4706.26 | F24: ='Operating Model'!G166 -> -3838.9536 | G24: ='Operating Model'!H166 -> -7433.3234 | H24: ='Operating Model'!I166 -> -11135.954 | I24: ='Operating Model'!J166 -> -15936.922 | J24: ='Operating Model'!K166 -> -20501.264 | K24: ='Operating Model'!L166 -> -26953.975
B25: (–) Cost of Goods Sold (Professional Services) | C25: ='Operating Model'!D167 -> 0 | D25: ='Operating Model'!E167 -> -1323.9 | E25: ='Operating Model'!F167 -> -1822.74 | F25: ='Operating Model'!G167 -> -2480.7139 | G25: ='Operating Model'!H167 -> -3195.3975 | H25: ='Operating Model'!I167 -> -4144.6384 | I25: ='Operating Model'!J167 -> -8681.0692 | J25: ='Operating Model'!K167 -> -12034.097 | K25: ='Operating Model'!L167 -> -16539.377
B26: (+/–) Other Adjustments | C26: ='Operating Model'!D168 -> -3710.1656 | D26: ='Operating Model'!E168 -> 303.396 | E26: ='Operating Model'!F168 -> 348.978 | F26: ='Operating Model'!G168 -> 0.01386 | G26: ='Operating Model'!H168 -> -108 | H26: ='Operating Model'!I168 -> 0.01386 | I26: ='Operating Model'!J168 -> 0.01386 | J26: ='Operating Model'!K168 -> 0.01386 | K26: ='Operating Model'!L168 -> 0.01386
B27: Total Gross Profit | C27: =SUM(C19,C24:C26) -> 6595.2424 | D27: =SUM(D19,D24:D26) -> 6545.42 | E27: =SUM(E19,E24:E26) -> 6747.43 | F27: =SUM(F19,F24:F26) -> 9661.9392 | G27: =SUM(G19,G24:G26) -> 18670.451 | H27: =SUM(H19,H24:H26) -> 28777.421 | I27: =SUM(I19,I24:I26) -> 51690.522 | J27: =SUM(J19,J24:J26) -> 76176.271 | K27: =SUM(K19,K24:K26) -> 109165.71 | M27: =IFERROR(RATE($F$8-$C$8,0,-$C27,$F27),"N/A") -> 0.13573719 | N27: =IFERROR(RATE($K$8-$G$8,0,-$G27,$K27),"N/A") -> 0.55500883
B28: Gross Margin % | C28: =C27/C19 -> 0.63997878 | D28: =D27/D19 -> 0.62385317 | E28: =E27/E19 -> 0.52194586 | F28: =F27/F19 -> 0.60456672 | G28: =G27/G19 -> 0.63489448 | H28: =H27/H19 -> 0.6531713 | I28: =I27/I19 -> 0.67738879 | J28: =J27/J19 -> 0.70071876 | K28: =K27/K19 -> 0.71509492
B30: (–) OpEx: Personnel Expenses | C30: ='Operating Model'!D172 -> -6340.5862 | D30: ='Operating Model'!E172 -> -11467.276 | E30: ='Operating Model'!F172 -> -16185.352 | F30: ='Operating Model'!G172 -> -25229.878 | G30: ='Operating Model'!H172 -> -28327.955 | H30: ='Operating Model'!I172 -> -32011.486 | I30: ='Operating Model'!J172 -> -40312.83 | J30: ='Operating Model'!K172 -> -50972.619 | K30: ='Operating Model'!L172 -> -63256.732
B31: (–) OpEx: Non-Staff Expenses | C31: ='Operating Model'!D173 -> -10059.776 | D31: ='Operating Model'!E173 -> -5057.2005 | E31: ='Operating Model'!F173 -> -7954.0113 | F31: ='Operating Model'!G173 -> -9387.2908 | G31: ='Operating Model'!H173 -> -10414.902 | H31: ='Operating Model'!I173 -> -12670.973 | I31: ='Operating Model'!J173 -> -14650.681 | J31: ='Operating Model'!K173 -> -16892.155 | K31: ='Operating Model'!L173 -> -19324.917
B32: Adjusted EBITDA | C32: =SUM(C27,C30:C31) -> -9805.1193 | D32: =SUM(D27,D30:D31) -> -9979.0561 | E32: =SUM(E27,E30:E31) -> -17391.933 | F32: =SUM(F27,F30:F31) -> -24955.23 | G32: =SUM(G27,G30:G31) -> -20072.406 | H32: =SUM(H27,H30:H31) -> -15905.038 | I32: =SUM(I27,I30:I31) -> -3272.99 | J32: =SUM(J27,J30:J31) -> 8311.497 | K32: =SUM(K27,K30:K31) -> 26584.063
B33: EBITDA Margin % | C33: ='Operating Model'!D175 -> NM | D33: ='Operating Model'!E175 -> NM | E33: ='Operating Model'!F175 -> NM | F33: ='Operating Model'!G175 -> NM | G33: ='Operating Model'!H175 -> NM | H33: ='Operating Model'!I175 -> NM | I33: ='Operating Model'!J175 -> NM | J33: ='Operating Model'!K175 -> 0.076454542 | K33: ='Operating Model'!L175 -> 0.17414011
B35: Note: * ARR expressed as average quarterly MRR annualized
B37: Annual Cash Flow Schedule
C39: Historical FYE | G39: Projected FYE
C40: 42735 | D40: =EOMONTH(C40,12) -> 43100 | E40: =EOMONTH(D40,12) -> 43465 | F40: =EOMONTH(E40,12) -> 43830 | G40: =EOMONTH(F40,12) -> 44196 | H40: =EOMONTH(G40,12) -> 44561 | I40: =EOMONTH(H40,12) -> 44926 | J40: =EOMONTH(I40,12) -> 45291 | K40: =EOMONTH(J40,12) -> 45657
C41: =YEAR(C40) -> 2016 | D41: =YEAR(D40) -> 2017 | E41: =YEAR(E40) -> 2018 | F41: =YEAR(F40) -> 2019 | G41: =YEAR(G40) -> 2020 | H41: =YEAR(H40) -> 2021 | I41: =YEAR(I40) -> 2022 | J41: =YEAR(J40) -> 2023 | K41: =YEAR(K40) -> 2024
B43: Adjusted EBITDA | C43: ='Operating Model'!D183 -> -9805.1193 | D43: ='Operating Model'!E183 -> -9979.0561 | E43: ='Operating Model'!F183 -> -17391.933 | F43: ='Operating Model'!G183 -> -24955.23 | G43: ='Operating Model'!H183 -> -20072.406 | H43: ='Operating Model'!I183 -> -15905.038 | I43: ='Operating Model'!J183 -> -3272.99 | J43: ='Operating Model'!K183 -> 8311.497 | K43: ='Operating Model'!L183 -> 26584.063
B44: (–) Depreciation & Amortization | C44: ='Operating Model'!D184 -> -22.461 | D44: ='Operating Model'!E184 -> -141.629 | E44: ='Operating Model'!F184 -> -154.033 | F44: ='Operating Model'!G184 -> -217.28181 | G44: ='Operating Model'!H184 -> -279.55732 | H44: ='Operating Model'!I184 -> -279.54991 | I44: ='Operating Model'!J184 -> -279.5496 | J44: ='Operating Model'!K184 -> -279.5496 | K44: ='Operating Model'!L184 -> -279.5496
B45: (–) Employee Non-Cash Equity Expense | C45: ='Operating Model'!D185 -> -154.63 | D45: ='Operating Model'!E185 -> -251.855 | E45: ='Operating Model'!F185 -> -699.858 | F45: ='Operating Model'!G185 -> -1145 | G45: ='Operating Model'!H185 -> -3000 | H45: ='Operating Model'!I185 -> -3000 | I45: ='Operating Model'!J185 -> -6000 | J45: ='Operating Model'!K185 -> -6000 | K45: ='Operating Model'!L185 -> -9000
B46: (+/–) Other Non-Cash OpEx Adjustments, Net | C46: ='Operating Model'!D186 -> 6340.5853 | D46: ='Operating Model'!E186 -> 59.21806 | E46: ='Operating Model'!F186 -> -0.00256 | F46: ='Operating Model'!G186 -> -375.54141 | G46: ='Operating Model'!H186 -> -0.0032634868 | H46: ='Operating Model'!I186 -> 0 | I46: ='Operating Model'!J186 -> 0 | J46: ='Operating Model'!K186 -> 0 | K46: ='Operating Model'!L186 -> 0
B47: Operating Income (EBIT) | C47: =SUM(C43:C46) -> -3641.625 | D47: =SUM(D43:D46) -> -10313.322 | E47: =SUM(E43:E46) -> -18245.827 | F47: =SUM(F43:F46) -> -26693.053 | G47: =SUM(G43:G46) -> -23351.967 | H47: =SUM(H43:H46) -> -19184.588 | I47: =SUM(I43:I46) -> -9552.5396 | J47: =SUM(J43:J46) -> 2031.9474 | K47: =SUM(K43:K46) -> 17304.514
B48: (–) Other Expense, Net | C48: ='Operating Model'!D188 -> -511.933 | D48: ='Operating Model'!E188 -> -651.48598 | E48: ='Operating Model'!F188 -> -61.85321 | F48: ='Operating Model'!G188 -> -183.67753 | G48: ='Operating Model'!H188 -> -589 | H48: ='Operating Model'!I188 -> 0 | I48: ='Operating Model'!J188 -> 0 | J48: ='Operating Model'!K188 -> 0 | K48: ='Operating Model'!L188 -> 0
B49: (+/–) Interest Income (Expense), Net | C49: ='Operating Model'!D189 -> 0 | D49: ='Operating Model'!E189 -> 305.48198 | E49: ='Operating Model'!F189 -> 51.99022 | F49: ='Operating Model'!G189 -> 705.26704 | G49: ='Operating Model'!H189 -> 64.720266 | H49: ='Operating Model'!I189 -> 745.92894 | I49: ='Operating Model'!J189 -> 729.13576 | J49: ='Operating Model'!K189 -> 731.28733 | K49: ='Operating Model'!L189 -> 1006.0857
B50: (+/–) Income Taxes | C50: ='Operating Model'!D190 -> 0 | D50: ='Operating Model'!E190 -> 0 | E50: ='Operating Model'!F190 -> -19.8 | F50: ='Operating Model'!G190 -> 0.51824 | G50: ='Operating Model'!H190 -> 0 | H50: ='Operating Model'!I190 -> 0 | I50: ='Operating Model'!J190 -> 0 | J50: ='Operating Model'!K190 -> 0 | K50: ='Operating Model'!L190 -> 0
B51: Net Income | C51: =SUM(C47:C50) -> -4153.558 | D51: =SUM(D47:D50) -> -10659.326 | E51: =SUM(E47:E50) -> -18275.49 | F51: =SUM(F47:F50) -> -26170.945 | G51: =SUM(G47:G50) -> -23876.246 | H51: =SUM(H47:H50) -> -18438.659 | I51: =SUM(I47:I50) -> -8823.4039 | J51: =SUM(J47:J50) -> 2763.2347 | K51: =SUM(K47:K50) -> 18310.599
B52: (+) Depreciation & Amortization | C52: ='Operating Model'!D192 -> 22.461 | D52: ='Operating Model'!E192 -> 141.629 | E52: ='Operating Model'!F192 -> 154.033 | F52: ='Operating Model'!G192 -> 217.28181 | G52: ='Operating Model'!H192 -> 279.55732 | H52: ='Operating Model'!I192 -> 279.54991 | I52: ='Operating Model'!J192 -> 279.5496 | J52: ='Operating Model'!K192 -> 279.5496 | K52: ='Operating Model'!L192 -> 279.5496
...

Sheet Operating Model
A2: x | B2: Assumptions | P2: x
B4: ACV-Related Assumptions
C6: 2020 | D6: =C6+1 -> 2021 | E6: =D6+1 -> 2022 | F6: =E6+1 -> 2023 | G6: =F6+1 -> 2024
B8: ACV Annual Growth Escalator | C8: 0.68399174 | D8: 0.70181722 | E8: 0.42588875 | F8: 0.425 | G8: 0.35
B10: ACV Composition Mix Profile
B11: Subscription (% of Total) | C11: 0.59704684 | D11: 0.6262548 | E11: 0.65048221 | F11: 0.68 | G11: 0.7
B12: Professional Services (% of Total) | C12: 0.40295316 | D12: 0.3737452 | E12: 0.34951779 | F12: 0.32 | G12: 0.3
B13: Other (% of Total) | C13: 0 | D13: 0 | E13: 0 | F13: 0 | G13: 0
B14: Total | C14: =SUM(C11:C13) -> 1 | D14: =SUM(D11:D13) -> 1 | E14: =SUM(E11:E13) -> 1 | F14: =SUM(F11:F13) -> 1 | G14: =SUM(G11:G13) -> 1
B16: Number of Total Clients | C16: 26 | D16: 49 | E16: 73 | F16: 96 | G16: 111
B17: Number of Subscription ACV Clients | C17: 21 | D17: 40 | E17: 59 | F17: 77 | G17: 89
B19: Revenue-Related Assumptions
C21: 2020 | D21: =C21+1 -> 2021 | E21: =D21+1 -> 2022 | F21: =E21+1 -> 2023 | G21: =F21+1 -> 2024
B23: Revenue (ACV In-Year Realization Factor %) | C23: 0.3 | D23: 0.3 | E23: 0.3 | F23: 0.3 | G23: 0.3
B24: Revenue (ACV Prior-Year Realization Factor %) | C24: 0.67339598 | D24: 0.53802043 | E24: 0.63939653 | F24: 0.63872345 | G24: 0.64570296
B26: Revenue Composition Mix Profile
B27: Subscription (% of Total) | C27: 0.5751881 | D27: 0.56137364 | E27: 0.63780822 | F27: 0.66890828 | G27: 0.68757696
B28: Professional Services (% of Total) | C28: 0.4248119 | D28: 0.43862636 | E28: 0.36219178 | F28: 0.33109172 | G28: 0.31242304
B29: Other (% of Total) | C29: 0 | D29: 0 | E29: 0 | F29: 0 | G29: 0
B30: Total | C30: =SUM(C27:C29) -> 1 | D30: =SUM(D27:D29) -> 1 | E30: =SUM(E27:E29) -> 1 | F30: =SUM(F27:F29) -> 1 | G30: =SUM(G27:G29) -> 1
B32: Cost-Related Assumptions
D34: 2016 | E34: 2017 | F34: 2018 | G34: 2019 | H34: 2020 | I34: =H34+1 -> 2021 | J34: =I34+1 -> 2022 | K34: =J34+1 -> 2023 | L34: =K34+1 -> 2024
B36: Subscription Cost of Goods Sold (as % of Subscription Revenue) | E36: =-E116/E84 -> 0.3118065 | F36: =-F116/F84 -> 0.41864458 | G36: =-G116/G84 -> 0.32158791 | H36: 0.43946053 | I36: 0.45024681 | J36: 0.32744731 | K36: 0.28192794 | L36: 0.2567905
B37: Professional Services Cost of Goods Sold (as % of Professional Services Revenue) | E37: =-E117/E85 -> 1.1949645 | F37: =-F117/F85 -> 1.0812366 | G37: =-G117/G85 -> 0.61341568 | H37: 0.25578493 | I37: 0.21447029 | J37: 0.31409551 | K37: 0.33434069 | L37: 0.34677959
B38: OpEx: Personnel Expenses (as % of Total Revenue) | D38: =-D129/D$115 -> 0.61526784 | E38: =-E129/E$115 -> 1.0929621 | F38: =-F129/F$115 -> 1.2520141 | G38: =-G129/G$115 -> 1.5786836 | H38: 0.96330089 | I38: 0.72657601 | J38: 0.52828755 | K38: 0.46887921 | L38: 0.41436608
B39: OpEx: Non-Staff Expenses (as % of Total Revenue) | D39: =-D130/D$115 -> 0.97616471 | E39: =-E130/E$115 -> 0.48200888 | F39: =-F130/F$115 -> 0.61528067 | G39: =-G130/G$115 -> 0.58738143 | H39: 0.35416198 | I39: 0.28759755 | J39: 0.19199279 | K39: 0.155385 | L39: 0.12658874
B41: Cash Flow Schedule-Related Assumptions
D43: 2016 | E43: 2017 | F43: 2018 | G43: 2019 | H43: 2020 | I43: =H43+1 -> 2021 | J43: =I43+1 -> 2022 | K43: =J43+1 -> 2023 | L43: =K43+1 -> 2024
B45: D&A (as % of Total Revenue) | D45: =-D184/D$163 -> 0.0021795352 | E45: =-E184/E$163 -> 0.013498859 | F45: =-F184/F$163 -> 0.011915186 | G45: =-G184/G$163 -> 0.013595755 | H45: 0.0095064333 | I45: 0.0063450431 | J45: 0.0036634137 | K45: 0.0025714786 | L45: 0.0018312023
B46: Changes in Net Working Capital (as % of Total Revenue) | D46: =D193/D163 -> 0.10789578 | E46: =E193/E163 -> -0.037818783 | F46: =F193/F163 -> 0.14930066 | G46: =G193/G163 -> 0.23942881 | H46: -0.023731661 | I46: 0.17125531 | J46: 0.095815027 | K46: 0.057314692 | L46: 0.061209835
B47: Capex (as % of Total Revenue) | D47: =-D195/D$163 -> 0.009216229 | E47: =-E195/E$163 -> 0.014928558 | F47: =-F195/F$163 -> 0.016131253 | G47: =-G195/G$163 -> 0.03779759 | H47: 0.055674998 | I47: 0.013509465 | J47: 0.026209401 | K47: 0.027595946 | L47: 0.019651636
A49: x | B49: Operating Model Build-Up | P49: x
B51: Detailed Operating Model Build-Up
D53: Historical FYE | H53: Projected FYE
D54: 42735 | E54: =EOMONTH(D54,12) -> 43100 | F54: =EOMONTH(E54,12) -> 43465 | G54: =EOMONTH(F54,12) -> 43830 | H54: =EOMONTH(G54,12) -> 44196 | I54: =EOMONTH(H54,12) -> 44561 | J54: =EOMONTH(I54,12) -> 44926 | K54: =EOMONTH(J54,12) -> 45291 | L54: =EOMONTH(K54,12) -> 45657 | N54: ="'16A - '19A" -> '16A - '19A | O54: ="'20E - '24E" -> '20E - '24E
D55: =YEAR(D54) -> 2016 | E55: =YEAR(E54) -> 2017 | F55: =YEAR(F54) -> 2018 | G55: =YEAR(G54) -> 2019 | H55: =YEAR(H54) -> 2020 | I55: =YEAR(I54) -> 2021 | J55: =YEAR(J54) -> 2022 | K55: =YEAR(K54) -> 2023 | L55: =YEAR(L54) -> 2024 | N55: CAGR | O55: CAGR
B57: ACV (Bookings)
B59: Subscription (recurring fees for 'access') | D59: 10583 | E59: 13462 | F59: 13698 | G59: 14334.923 | H59: =PRODUCT(H$62,C11) -> 25086.356 | I59: =PRODUCT(I$62,D11) -> 44780.935 | J59: =PRODUCT(J$62,E11) -> 66322.846 | K59: =PRODUCT(K$62,F11) -> 98798.763 | L59: =PRODUCT(L$62,G11) -> 137301.22 | N59: =IFERROR(RATE($G$55-$D$55,0,-$D59,$G59),"N/A") -> 0.1064425 | O59: =IFERROR(RATE($L$55-$H$55,0,-$H59,$L59),"N/A") -> 0.52953425
B60: (+) Professional Services (contingent upon 'completion') | D60: 304 | E60: 1197 | F60: 2481 | G60: 10615.65 | H60: =PRODUCT(H$62,C12) -> 16931.044 | I60: =PRODUCT(I$62,D12) -> 26725 | J60: =PRODUCT(J$62,E12) -> 35636.662 | K60: =PRODUCT(K$62,F12) -> 46493.536 | L60: =PRODUCT(L$62,G12) -> 58843.381 | N60: =IFERROR(RATE($G$55-$D$55,0,-$D60,$G60),"N/A") -> 2.2685691 | O60: =IFERROR(RATE($L$55-$H$55,0,-$H60,$L60),"N/A") -> 0.36537979
B61: (+) Other (non-recurring engineering or setup fees) | D61: 0 | E61: 147.865 | F61: 337.7 | G61: 0.5 | H61: =PRODUCT(H$62,C13) -> 0 | I61: =PRODUCT(I$62,D13) -> 0 | J61: =PRODUCT(J$62,E13) -> 0 | K61: =PRODUCT(K$62,F13) -> 0 | L61: =PRODUCT(L$62,G13) -> 0 | N61: =IFERROR(RATE($G$55-$D$55,0,-$D61,$G61),"N/A") -> N/A | O61: =IFERROR(RATE($L$55-$H$55,0,-$H61,$L61),"N/A") -> N/A
...
