Workbook

Sheet Budget Assumption Driver
C2: Happy Pets Vets | P2: =TODAY() -> 45999
D3: Budget Assumptions Driver | P3: ($ in 000s)
D5: MoM Change in Employed Vets
E6: 45658 | F6: =EOMONTH(E6,1) -> 45716 | G6: =EOMONTH(F6,1) -> 45747 | H6: =EOMONTH(G6,1) -> 45777 | I6: =EOMONTH(H6,1) -> 45808 | J6: =EOMONTH(I6,1) -> 45838 | K6: =EOMONTH(J6,1) -> 45869 | L6: =EOMONTH(K6,1) -> 45900 | M6: =EOMONTH(L6,1) -> 45930 | ... P6: =EOMONTH(O6,1) -> 46022
A7: 1 | D7: Sites with 1 Doctor at YE-24 | E7: 0 | F7: 1 | G7: 0 | H7: 0 | I7: 0 | J7: 0 | K7: 1 | L7: 0 | M7: 0 | N7: 0 | O7: 0 | P7: 0
A8: =A7+1 -> 2 | D8: Sites with 2 Doctors at YE-24 | E8: 0 | F8: 0 | G8: 0 | H8: 1 | I8: 0 | J8: 0 | K8: 0 | L8: 0 | M8: 0 | N8: 0 | O8: 0 | P8: 0
A9: =A8+1 -> 3 | D9: Sites with 3 Doctors at YE-24 | E9: 0 | F9: 0 | G9: 0 | H9: 0 | I9: 0 | J9: 0 | K9: 1 | L9: 0 | M9: 0 | N9: 0 | O9: 0 | P9: 0
A10: =A9+1 -> 4 | D10: Sites with 4 Doctors at YE-24 | E10: 0 | F10: 0 | G10: 0 | H10: 0 | I10: 0 | J10: 0 | K10: 0 | L10: 0 | M10: 0 | N10: 0 | O10: 0 | P10: 0
A11: =A10+1 -> 5 | D11: Sites with 5 Doctors at YE-24 | E11: 0 | F11: 0 | G11: 0 | H11: 0 | I11: 0 | J11: 0 | K11: 0 | L11: 0 | M11: 0 | N11: 0 | O11: 0 | P11: 0
D13: MoM Change in Production per Vet per Workday
E14: 45658 | F14: =EOMONTH(E14,1) -> 45716 | G14: =EOMONTH(F14,1) -> 45747 | H14: =EOMONTH(G14,1) -> 45777 | I14: =EOMONTH(H14,1) -> 45808 | J14: =EOMONTH(I14,1) -> 45838 | K14: =EOMONTH(J14,1) -> 45869 | L14: =EOMONTH(K14,1) -> 45900 | M14: =EOMONTH(L14,1) -> 45930 | ... P14: =EOMONTH(O14,1) -> 46022
A15: 1 | D15: Sites with 1 Doctor at YE-24 | E15: =E$23+IF(E7>0,$E26,0) -> 0.41480875 | F15: =F$23+IF(F7>0,$E26,0) -> -0.11745397 | G15: =G$23+IF(G7>0,$E26,0) -> 0.073789234 | H15: =H$23+IF(H7>0,$E26,0) -> 0.071161542 | I15: =I$23+IF(I7>0,$E26,0) -> 0.089469046 | J15: =J$23+IF(J7>0,$E26,0) -> -0.040287147 | K15: =K$23+IF(K7>0,$E26,0) -> -0.28016608 | L15: =L$23+IF(L7>0,$E26,0) -> -0.14250917 | ... P15: =P$23+IF(P7>0,$E26,0) -> -0.18378745
A16: =A15+1 -> 2 | D16: Sites with 2 Doctors at YE-24 | E16: =E$23+IF(E8>0,$E27,0) -> 0.41480875 | F16: =F$23+IF(F8>0,$E27,0) -> 0.082546031 | G16: =G$23+IF(G8>0,$E27,0) -> 0.073789234 | H16: =H$23+IF(H8>0,$E27,0) -> -0.078838458 | I16: =I$23+IF(I8>0,$E27,0) -> 0.089469046 | J16: =J$23+IF(J8>0,$E27,0) -> -0.040287147 | K16: =K$23+IF(K8>0,$E27,0) -> -0.080166078 | L16: =L$23+IF(L8>0,$E27,0) -> -0.14250917 | ... P16: =P$23+IF(P8>0,$E27,0) -> -0.18378745
A17: =A16+1 -> 3 | D17: Sites with 3 Doctors at YE-24 | E17: =E$23+IF(E9>0,$E28,0) -> 0.41480875 | F17: =F$23+IF(F9>0,$E28,0) -> 0.082546031 | G17: =G$23+IF(G9>0,$E28,0) -> 0.073789234 | H17: =H$23+IF(H9>0,$E28,0) -> 0.071161542 | I17: =I$23+IF(I9>0,$E28,0) -> 0.089469046 | J17: =J$23+IF(J9>0,$E28,0) -> -0.040287147 | K17: =K$23+IF(K9>0,$E28,0) -> -0.18016608 | L17: =L$23+IF(L9>0,$E28,0) -> -0.14250917 | ... P17: =P$23+IF(P9>0,$E28,0) -> -0.18378745
A18: =A17+1 -> 4 | D18: Sites with 4 Doctors at YE-24 | E18: =E$23+IF(E10>0,$E29,0) -> 0.41480875 | F18: =F$23+IF(F10>0,$E29,0) -> 0.082546031 | G18: =G$23+IF(G10>0,$E29,0) -> 0.073789234 | H18: =H$23+IF(H10>0,$E29,0) -> 0.071161542 | I18: =I$23+IF(I10>0,$E29,0) -> 0.089469046 | J18: =J$23+IF(J10>0,$E29,0) -> -0.040287147 | K18: =K$23+IF(K10>0,$E29,0) -> -0.080166078 | L18: =L$23+IF(L10>0,$E29,0) -> -0.14250917 | ... P18: =P$23+IF(P10>0,$E29,0) -> -0.18378745
A19: =A18+1 -> 5 | D19: Sites with 5 Doctors at YE-24 | E19: =E$23 -> 0.41480875 | F19: =F$23 -> 0.082546031 | G19: =G$23 -> 0.073789234 | H19: =H$23 -> 0.071161542 | I19: =I$23 -> 0.089469046 | J19: =J$23 -> -0.040287147 | K19: =K$23 -> -0.080166078 | L19: =L$23 -> -0.14250917 | ... P19: =P$23 -> -0.18378745
D21: All Sites - 2024 | E21: ='Cons. Financials - ''23 ''24'!P11/'Cons. Financials - ''23 ''24'!O11-1 -> 0.41147542 | F21: ='Cons. Financials - ''23 ''24'!Q11/'Cons. Financials - ''23 ''24'!P11-1 -> 0.079212697 | G21: ='Cons. Financials - ''23 ''24'!R11/'Cons. Financials - ''23 ''24'!Q11-1 -> 0.070455901 | H21: ='Cons. Financials - ''23 ''24'!S11/'Cons. Financials - ''23 ''24'!R11-1 -> 0.067828209 | I21: ='Cons. Financials - ''23 ''24'!T11/'Cons. Financials - ''23 ''24'!S11-1 -> 0.086135713 | J21: ='Cons. Financials - ''23 ''24'!U11/'Cons. Financials - ''23 ''24'!T11-1 -> -0.043620481 | K21: ='Cons. Financials - ''23 ''24'!V11/'Cons. Financials - ''23 ''24'!U11-1 -> -0.083499412 | L21: ='Cons. Financials - ''23 ''24'!W11/'Cons. Financials - ''23 ''24'!V11-1 -> -0.1458425 | ... P21: ='Cons. Financials - ''23 ''24'!AA11/'Cons. Financials - ''23 ''24'!Z11-1 -> -0.18712078
D22: 2025 Year over Year Growth Adjustment | E22: =4%/12 -> 0.0033333333 | F22: =4%/12 -> 0.0033333333 | G22: =4%/12 -> 0.0033333333 | H22: =4%/12 -> 0.0033333333 | I22: =4%/12 -> 0.0033333333 | J22: =4%/12 -> 0.0033333333 | K22: =4%/12 -> 0.0033333333 | L22: =4%/12 -> 0.0033333333 | ... P22: =4%/12 -> 0.0033333333
D23: Baseline Assumption for 2025 | E23: =SUM(E21:E22) -> 0.41480875 | F23: =SUM(F21:F22) -> 0.082546031 | G23: =SUM(G21:G22) -> 0.073789234 | H23: =SUM(H21:H22) -> 0.071161542 | I23: =SUM(I21:I22) -> 0.089469046 | J23: =SUM(J21:J22) -> -0.040287147 | K23: =SUM(K21:K22) -> -0.080166078 | L23: =SUM(L21:L22) -> -0.14250917 | ... P23: =SUM(P21:P22) -> -0.18378745
D25: MoM Adjustment for Adding New Doctor
D26: Sites with 1 Doctor at YE-24 | E26: -0.2
D27: Sites with 2 Doctors at YE-24 | E27: -0.15
D28: Sites with 3 Doctors at YE-24 | E28: -0.1
D29: Sites with 4 Doctors at YE-24 | E29: -0.05
D31: Other Site Level Assumptions
E32: 45658 | F32: =EOMONTH(E32,1) -> 45716 | G32: =EOMONTH(F32,1) -> 45747 | H32: =EOMONTH(G32,1) -> 45777 | I32: =EOMONTH(H32,1) -> 45808 | J32: =EOMONTH(I32,1) -> 45838 | K32: =EOMONTH(J32,1) -> 45869 | L32: =EOMONTH(K32,1) -> 45900 | M32: =EOMONTH(L32,1) -> 45930 | ... P32: =EOMONTH(O32,1) -> 46022
A33: % of Revenue - Doctor Compensation | D33: YoY Change - % of Revenue - Doctor Compensation | E33: 0 | F33: 0 | G33: 0 | H33: 0 | I33: 0 | J33: 0 | K33: 0 | L33: 0 | M33: 0 | N33: 0 | O33: 0 | P33: 0
A34: % of Revenue - Administrative Staff Compensation | D34: YoY Change - % of Revenue - Administrative Staff Compensation | E34: 0 | F34: 0 | G34: 0 | H34: 0 | I34: 0 | J34: 0 | K34: 0 | L34: 0 | M34: 0 | N34: 0 | O34: 0 | P34: 0
A35: % of Revenue - Office Supplies | D35: YoY Change - % of Revenue - Office Supplies | E35: 0 | F35: 0 | G35: 0 | H35: 0 | I35: 0 | J35: 0 | K35: 0 | L35: 0 | M35: 0 | N35: 0 | O35: 0 | P35: 0
A36: % of Revenue - General and Administrative Expense | D36: YoY Change - % of Revenue - General and Administrative Expense | E36: 0 | F36: 0 | G36: 0 | H36: 0 | I36: 0 | J36: 0 | K36: 0 | L36: 0 | M36: 0 | N36: 0 | O36: 0 | P36: 0
A37: % of Revenue - Marketing | D37: YoY Change - % of Revenue - Marketing | E37: 0 | F37: 0 | G37: 0 | H37: 0 | I37: 0 | J37: 0 | K37: 0 | L37: 0 | M37: 0 | N37: 0 | O37: 0 | P37: 0
A38: % YoY Growth | D38: % YoY Change - Office Rent | E38: 0.03 | F38: 0.03 | G38: 0.03 | H38: 0.03 | I38: 0.03 | J38: 0.03 | K38: 0.03 | L38: 0.03 | M38: 0.03 | N38: 0.03 | O38: 0.03 | P38: 0.03
A39: Collections as a % of Production | D39: YoY Change - Collections as a % of Production | E39: 0 | F39: 0 | G39: 0 | H39: 0 | I39: 0 | J39: 0 | K39: 0 | L39: 0 | M39: 0 | N39: 0 | O39: 0 | P39: 0
D41: Corporate Level & NWC Assumptions
E42: 45658 | F42: =EOMONTH(E42,1) -> 45716 | G42: =EOMONTH(F42,1) -> 45747 | H42: =EOMONTH(G42,1) -> 45777 | I42: =EOMONTH(H42,1) -> 45808 | J42: =EOMONTH(I42,1) -> 45838 | K42: =EOMONTH(J42,1) -> 45869 | L42: =EOMONTH(K42,1) -> 45900 | M42: =EOMONTH(L42,1) -> 45930 | ... P42: =EOMONTH(O42,1) -> 46022
D43: YoY Change - % of Revenue - SG&A | E43: 0 | F43: 0 | G43: 0 | H43: 0 | I43: 0 | J43: 0 | K43: 0 | L43: 0 | M43: 0 | N43: 0 | O43: 0 | P43: 0
D44: YoY Change - Corporate Office Rent | E44: 0.03 | F44: 0.03 | G44: 0.03 | H44: 0.03 | I44: 0.03 | J44: 0.03 | K44: 0.03 | L44: 0.03 | M44: 0.03 | N44: 0.03 | O44: 0.03 | P44: 0.03
D45: Income Tax Rate | E45: 0.25663562 | F45: 0.25663562 | G45: 0.25663562 | H45: 0.25663562 | I45: 0.25663562 | J45: 0.25663562 | K45: 0.25663562 | L45: 0.25663562 | M45: 0.25663562 | N45: 0.25663562 | O45: 0.25663562 | P45: 0.25663562
A46: Accounts Receivable - Days Outstanding | D46: ="YoY Change - "&A46 -> YoY Change - Accounts Receivable - Days Outstanding | E46: 0 | F46: 0 | G46: 0 | H46: 0 | I46: 0 | J46: 0 | K46: 0 | L46: 0 | M46: 0 | N46: 0 | O46: 0 | P46: 0
A47: Inventories - Days Outstanding | D47: ="YoY Change - "&A47 -> YoY Change - Inventories - Days Outstanding | E47: 0 | F47: 0 | G47: 0 | H47: 0 | I47: 0 | J47: 0 | K47: 0 | L47: 0 | M47: 0 | N47: 0 | O47: 0 | P47: 0
...

Sheet Consolidated Budget - '25
B2: Happy Pets Vets | AE2: =TODAY() -> 45999
C3: Income Statement | AE3: ($ in 000s)
D5: 2024A | P5: 2025 Budget | AC5: Historicals | AE5: Budget
D6: 44957 | E6: =EOMONTH(D6,1) -> 44985 | F6: =EOMONTH(E6,1) -> 45016 | G6: =EOMONTH(F6,1) -> 45046 | H6: =EOMONTH(G6,1) -> 45077 | I6: =EOMONTH(H6,1) -> 45107 | J6: =EOMONTH(I6,1) -> 45138 | K6: =EOMONTH(J6,1) -> 45169 | L6: =EOMONTH(K6,1) -> 45199 | ... AA6: =EOMONTH(Z6,1) -> 45657 | AC6: 45291 | AD6: 45657 | AE6: 46022
C8: Employed Vets | D8: =_xlfn.XLOOKUP($C8,'Cons. Financials - ''23 ''24'!$C$8:$C$79,'Cons. Financials - ''23 ''24'!P$8:P$79) -> 116 | E8: =_xlfn.XLOOKUP($C8,'Cons. Financials - ''23 ''24'!$C$8:$C$79,'Cons. Financials - ''23 ''24'!Q$8:Q$79) -> 106 | F8: =_xlfn.XLOOKUP($C8,'Cons. Financials - ''23 ''24'!$C$8:$C$79,'Cons. Financials - ''23 ''24'!R$8:R$79) -> 98 | G8: =_xlfn.XLOOKUP($C8,'Cons. Financials - ''23 ''24'!$C$8:$C$79,'Cons. Financials - ''23 ''24'!S$8:S$79) -> 86 | H8: =_xlfn.XLOOKUP($C8,'Cons. Financials - ''23 ''24'!$C$8:$C$79,'Cons. Financials - ''23 ''24'!T$8:T$79) -> 72 | I8: =_xlfn.XLOOKUP($C8,'Cons. Financials - ''23 ''24'!$C$8:$C$79,'Cons. Financials - ''23 ''24'!U$8:U$79) -> 79 | J8: =_xlfn.XLOOKUP($C8,'Cons. Financials - ''23 ''24'!$C$8:$C$79,'Cons. Financials - ''23 ''24'!V$8:V$79) -> 92 | K8: =_xlfn.XLOOKUP($C8,'Cons. Financials - ''23 ''24'!$C$8:$C$79,'Cons. Financials - ''23 ''24'!W$8:W$79) -> 113 | ... O8: =_xlfn.XLOOKUP($C8,'Cons. Financials - ''23 ''24'!$C$8:$C$79,'Cons. Financials - ''23 ''24'!AA$8:AA$79) -> 125 | P8: =SUMIFS('Site Level Budget - ''25'!S:S,'Site Level Budget - ''25'!$F:$F,'Consolidated Budget - ''25'!$C8) -> 125 | Q8: =SUMIFS('Site Level Budget - ''25'!T:T,'Site Level Budget - ''25'!$F:$F,'Consolidated Budget - ''25'!$C8) -> 127 | R8: =SUMIFS('Site Level Budget - ''25'!U:U,'Site Level Budget - ''25'!$F:$F,'Consolidated Budget - ''25'!$C8) -> 127 | S8: =SUMIFS('Site Level Budget - ''25'!V:V,'Site Level Budget - ''25'!$F:$F,'Consolidated Budget - ''25'!$C8) -> 129 | T8: =SUMIFS('Site Level Budget - ''25'!W:W,'Site Level Budget - ''25'!$F:$F,'Consolidated Budget - ''25'!$C8) -> 129 | U8: =SUMIFS('Site Level Budget - ''25'!X:X,'Site Level Budget - ''25'!$F:$F,'Consolidated Budget - ''25'!$C8) -> 129 | V8: =SUMIFS('Site Level Budget - ''25'!Y:Y,'Site Level Budget - ''25'!$F:$F,'Consolidated Budget - ''25'!$C8) -> 137 | W8: =SUMIFS('Site Level Budget - ''25'!Z:Z,'Site Level Budget - ''25'!$F:$F,'Consolidated Budget - ''25'!$C8) -> 137 | X8: =SUMIFS('Site Level Budget - ''25'!AA:AA,'Site Level Budget - ''25'!$F:$F,'Consolidated Budget - ''25'!$C8) -> 137 | Y8: =SUMIFS('Site Level Budget - ''25'!AB:AB,'Site Level Budget - ''25'!$F:$F,'Consolidated Budget - ''25'!$C8) -> 137 | Z8: =SUMIFS('Site Level Budget - ''25'!AC:AC,'Site Level Budget - ''25'!$F:$F,'Consolidated Budget - ''25'!$C8) -> 137 | AA8: =SUMIFS('Site Level Budget - ''25'!AD:AD,'Site Level Budget - ''25'!$F:$F,'Consolidated Budget - ''25'!$C8) -> 137 | AC8: ='Cons. Financials - ''23 ''24'!AC8 -> 91.75 | AD8: =AVERAGE(D8:O8) -> 103.08333 | AE8: =AVERAGE(P8:AA8) -> 132.33333
C9: Workdays in Month / Year | D9: =_xlfn.XLOOKUP($C9,'Cons. Financials - ''23 ''24'!$C$8:$C$79,'Cons. Financials - ''23 ''24'!P$8:P$79) -> 22.801724 | E9: =_xlfn.XLOOKUP($C9,'Cons. Financials - ''23 ''24'!$C$8:$C$79,'Cons. Financials - ''23 ''24'!Q$8:Q$79) -> 21.792453 | F9: =_xlfn.XLOOKUP($C9,'Cons. Financials - ''23 ''24'!$C$8:$C$79,'Cons. Financials - ''23 ''24'!R$8:R$79) -> 21.77551 | G9: =_xlfn.XLOOKUP($C9,'Cons. Financials - ''23 ''24'!$C$8:$C$79,'Cons. Financials - ''23 ''24'!S$8:S$79) -> 21.744186 | H9: =_xlfn.XLOOKUP($C9,'Cons. Financials - ''23 ''24'!$C$8:$C$79,'Cons. Financials - ''23 ''24'!T$8:T$79) -> 24 | I9: =_xlfn.XLOOKUP($C9,'Cons. Financials - ''23 ''24'!$C$8:$C$79,'Cons. Financials - ''23 ''24'!U$8:U$79) -> 21 | J9: =_xlfn.XLOOKUP($C9,'Cons. Financials - ''23 ''24'!$C$8:$C$79,'Cons. Financials - ''23 ''24'!V$8:V$79) -> 23 | K9: =_xlfn.XLOOKUP($C9,'Cons. Financials - ''23 ''24'!$C$8:$C$79,'Cons. Financials - ''23 ''24'!W$8:W$79) -> 22.79646 | ... O9: =_xlfn.XLOOKUP($C9,'Cons. Financials - ''23 ''24'!$C$8:$C$79,'Cons. Financials - ''23 ''24'!AA$8:AA$79) -> 22 | P9: =P10/P8 -> 23 | Q9: =Q10/Q8 -> 22 | R9: =R10/R8 -> 22 | S9: =S10/S8 -> 22 | T9: =T10/T8 -> 24 | U9: =U10/U8 -> 21 | V9: =V10/V8 -> 23 | W9: =W10/W8 -> 23 | ... AA9: =AA10/AA8 -> 22 | AC9: ='Cons. Financials - ''23 ''24'!AC9 -> 270.16784 | AD9: =SUM(D9:O9) -> 267.72449 | AE9: =SUM(P9:AA9) -> 269
C10: Total Vet Days | D10: =_xlfn.XLOOKUP($C10,'Cons. Financials - ''23 ''24'!$C$8:$C$79,'Cons. Financials - ''23 ''24'!P$8:P$79) -> 2645 | E10: =_xlfn.XLOOKUP($C10,'Cons. Financials - ''23 ''24'!$C$8:$C$79,'Cons. Financials - ''23 ''24'!Q$8:Q$79) -> 2310 | F10: =_xlfn.XLOOKUP($C10,'Cons. Financials - ''23 ''24'!$C$8:$C$79,'Cons. Financials - ''23 ''24'!R$8:R$79) -> 2134 | G10: =_xlfn.XLOOKUP($C10,'Cons. Financials - ''23 ''24'!$C$8:$C$79,'Cons. Financials - ''23 ''24'!S$8:S$79) -> 1870 | H10: =_xlfn.XLOOKUP($C10,'Cons. Financials - ''23 ''24'!$C$8:$C$79,'Cons. Financials - ''23 ''24'!T$8:T$79) -> 1728 | I10: =_xlfn.XLOOKUP($C10,'Cons. Financials - ''23 ''24'!$C$8:$C$79,'Cons. Financials - ''23 ''24'!U$8:U$79) -> 1659 | J10: =_xlfn.XLOOKUP($C10,'Cons. Financials - ''23 ''24'!$C$8:$C$79,'Cons. Financials - ''23 ''24'!V$8:V$79) -> 2116 | K10: =_xlfn.XLOOKUP($C10,'Cons. Financials - ''23 ''24'!$C$8:$C$79,'Cons. Financials - ''23 ''24'!W$8:W$79) -> 2576 | ... O10: =_xlfn.XLOOKUP($C10,'Cons. Financials - ''23 ''24'!$C$8:$C$79,'Cons. Financials - ''23 ''24'!AA$8:AA$79) -> 2750 | P10: =SUMIFS('Site Level Budget - ''25'!S:S,'Site Level Budget - ''25'!$F:$F,'Consolidated Budget - ''25'!$C10) -> 2875 | Q10: =SUMIFS('Site Level Budget - ''25'!T:T,'Site Level Budget - ''25'!$F:$F,'Consolidated Budget - ''25'!$C10) -> 2794 | R10: =SUMIFS('Site Level Budget - ''25'!U:U,'Site Level Budget - ''25'!$F:$F,'Consolidated Budget - ''25'!$C10) -> 2794 | S10: =SUMIFS('Site Level Budget - ''25'!V:V,'Site Level Budget - ''25'!$F:$F,'Consolidated Budget - ''25'!$C10) -> 2838 | T10: =SUMIFS('Site Level Budget - ''25'!W:W,'Site Level Budget - ''25'!$F:$F,'Consolidated Budget - ''25'!$C10) -> 3096 | U10: =SUMIFS('Site Level Budget - ''25'!X:X,'Site Level Budget - ''25'!$F:$F,'Consolidated Budget - ''25'!$C10) -> 2709 | V10: =SUMIFS('Site Level Budget - ''25'!Y:Y,'Site Level Budget - ''25'!$F:$F,'Consolidated Budget - ''25'!$C10) -> 3151 | W10: =SUMIFS('Site Level Budget - ''25'!Z:Z,'Site Level Budget - ''25'!$F:$F,'Consolidated Budget - ''25'!$C10) -> 3151 | X10: =SUMIFS('Site Level Budget - ''25'!AA:AA,'Site Level Budget - ''25'!$F:$F,'Consolidated Budget - ''25'!$C10) -> 2877 | Y10: =SUMIFS('Site Level Budget - ''25'!AB:AB,'Site Level Budget - ''25'!$F:$F,'Consolidated Budget - ''25'!$C10) -> 3288 | Z10: =SUMIFS('Site Level Budget - ''25'!AC:AC,'Site Level Budget - ''25'!$F:$F,'Consolidated Budget - ''25'!$C10) -> 3014 | AA10: =SUMIFS('Site Level Budget - ''25'!AD:AD,'Site Level Budget - ''25'!$F:$F,'Consolidated Budget - ''25'!$C10) -> 3014 | AC10: ='Cons. Financials - ''23 ''24'!AC10 -> 24725 | AD10: =SUM(D10:O10) -> 27576 | AE10: =SUM(P10:AA10) -> 35601
C11: Production per Vet Workday | D11: =_xlfn.XLOOKUP($C11,'Cons. Financials - ''23 ''24'!$C$8:$C$79,'Cons. Financials - ''23 ''24'!P$8:P$79) -> 5.2302827 | E11: =_xlfn.XLOOKUP($C11,'Cons. Financials - ''23 ''24'!$C$8:$C$79,'Cons. Financials - ''23 ''24'!Q$8:Q$79) -> 5.6445875 | F11: =_xlfn.XLOOKUP($C11,'Cons. Financials - ''23 ''24'!$C$8:$C$79,'Cons. Financials - ''23 ''24'!R$8:R$79) -> 6.042282 | G11: =_xlfn.XLOOKUP($C11,'Cons. Financials - ''23 ''24'!$C$8:$C$79,'Cons. Financials - ''23 ''24'!S$8:S$79) -> 6.4521191 | H11: =_xlfn.XLOOKUP($C11,'Cons. Financials - ''23 ''24'!$C$8:$C$79,'Cons. Financials - ''23 ''24'!T$8:T$79) -> 7.007877 | I11: =_xlfn.XLOOKUP($C11,'Cons. Financials - ''23 ''24'!$C$8:$C$79,'Cons. Financials - ''23 ''24'!U$8:U$79) -> 6.70219 | J11: =_xlfn.XLOOKUP($C11,'Cons. Financials - ''23 ''24'!$C$8:$C$79,'Cons. Financials - ''23 ''24'!V$8:V$79) -> 6.1425611 | K11: =_xlfn.XLOOKUP($C11,'Cons. Financials - ''23 ''24'!$C$8:$C$79,'Cons. Financials - ''23 ''24'!W$8:W$79) -> 5.2467146 | ... O11: =_xlfn.XLOOKUP($C11,'Cons. Financials - ''23 ''24'!$C$8:$C$79,'Cons. Financials - ''23 ''24'!AA$8:AA$79) -> 3.672441 | P11: =P12/P10 -> 5.1958017 | Q11: =Q12/Q10 -> 5.6081573 | R11: =R12/R10 -> 6.0219789 | S11: =S12/S10 -> 6.4128139 | T11: =T12/T10 -> 6.9865623 | U11: =U12/U10 -> 6.7050936 | V11: =V12/V10 -> 5.9939802 | W11: =W12/W10 -> 5.139783 | ... AA11: =AA12/AA10 -> 3.6505511 | AC11: ='Cons. Financials - ''23 ''24'!AC11 -> 5.2426569 | AD11: =AD12/AD10 -> 5.4597704 | AE11: =AE12/AE10 -> 5.5305807
C12: Total Production | D12: =_xlfn.XLOOKUP($C12,'Cons. Financials - ''23 ''24'!$C$8:$C$79,'Cons. Financials - ''23 ''24'!P$8:P$79) -> 13834.098 | E12: =_xlfn.XLOOKUP($C12,'Cons. Financials - ''23 ''24'!$C$8:$C$79,'Cons. Financials - ''23 ''24'!Q$8:Q$79) -> 13038.997 | F12: =_xlfn.XLOOKUP($C12,'Cons. Financials - ''23 ''24'!$C$8:$C$79,'Cons. Financials - ''23 ''24'!R$8:R$79) -> 12894.23 | G12: =_xlfn.XLOOKUP($C12,'Cons. Financials - ''23 ''24'!$C$8:$C$79,'Cons. Financials - ''23 ''24'!S$8:S$79) -> 12065.463 | H12: =_xlfn.XLOOKUP($C12,'Cons. Financials - ''23 ''24'!$C$8:$C$79,'Cons. Financials - ''23 ''24'!T$8:T$79) -> 12109.611 | I12: =_xlfn.XLOOKUP($C12,'Cons. Financials - ''23 ''24'!$C$8:$C$79,'Cons. Financials - ''23 ''24'!U$8:U$79) -> 11118.933 | J12: =_xlfn.XLOOKUP($C12,'Cons. Financials - ''23 ''24'!$C$8:$C$79,'Cons. Financials - ''23 ''24'!V$8:V$79) -> 12997.659 | K12: =_xlfn.XLOOKUP($C12,'Cons. Financials - ''23 ''24'!$C$8:$C$79,'Cons. Financials - ''23 ''24'!W$8:W$79) -> 13515.537 | ... O12: =_xlfn.XLOOKUP($C12,'Cons. Financials - ''23 ''24'!$C$8:$C$79,'Cons. Financials - ''23 ''24'!AA$8:AA$79) -> 10099.213 | P12: =SUMIFS('Site Level Budget - ''25'!S:S,'Site Level Budget - ''25'!$F:$F,'Consolidated Budget - ''25'!$C12) -> 14937.93 | Q12: =SUMIFS('Site Level Budget - ''25'!T:T,'Site Level Budget - ''25'!$F:$F,'Consolidated Budget - ''25'!$C12) -> 15669.191 | R12: =SUMIFS('Site Level Budget - ''25'!U:U,'Site Level Budget - ''25'!$F:$F,'Consolidated Budget - ''25'!$C12) -> 16825.409 | S12: =SUMIFS('Site Level Budget - ''25'!V:V,'Site Level Budget - ''25'!$F:$F,'Consolidated Budget - ''25'!$C12) -> 18199.566 | T12: =SUMIFS('Site Level Budget - ''25'!W:W,'Site Level Budget - ''25'!$F:$F,'Consolidated Budget - ''25'!$C12) -> 21630.397 | U12: =SUMIFS('Site Level Budget - ''25'!X:X,'Site Level Budget - ''25'!$F:$F,'Consolidated Budget - ''25'!$C12) -> 18164.099 | V12: =SUMIFS('Site Level Budget - ''25'!Y:Y,'Site Level Budget - ''25'!$F:$F,'Consolidated Budget - ''25'!$C12) -> 18887.032 | W12: =SUMIFS('Site Level Budget - ''25'!Z:Z,'Site Level Budget - ''25'!$F:$F,'Consolidated Budget - ''25'!$C12) -> 16195.456 | X12: =SUMIFS('Site Level Budget - ''25'!AA:AA,'Site Level Budget - ''25'!$F:$F,'Consolidated Budget - ''25'!$C12) -> 14848.594 | Y12: =SUMIFS('Site Level Budget - ''25'!AB:AB,'Site Level Budget - ''25'!$F:$F,'Consolidated Budget - ''25'!$C12) -> 17053.503 | Z12: =SUMIFS('Site Level Budget - ''25'!AC:AC,'Site Level Budget - ''25'!$F:$F,'Consolidated Budget - ''25'!$C12) -> 13480.265 | AA12: =SUMIFS('Site Level Budget - ''25'!AD:AD,'Site Level Budget - ''25'!$F:$F,'Consolidated Budget - ''25'!$C12) -> 11002.761 | AC12: ='Cons. Financials - ''23 ''24'!AC12 -> 129624.69 | AD12: =SUM(D12:O12) -> 150558.63 | AE12: =SUM(P12:AA12) -> 196894.2
C13: Revenue as a % of Production | D13: =_xlfn.XLOOKUP($C13,'Cons. Financials - ''23 ''24'!$C$8:$C$79,'Cons. Financials - ''23 ''24'!P$8:P$79) -> 0.97968328 | E13: =_xlfn.XLOOKUP($C13,'Cons. Financials - ''23 ''24'!$C$8:$C$79,'Cons. Financials - ''23 ''24'!Q$8:Q$79) -> 0.97955179 | F13: =_xlfn.XLOOKUP($C13,'Cons. Financials - ''23 ''24'!$C$8:$C$79,'Cons. Financials - ''23 ''24'!R$8:R$79) -> 0.97940904 | G13: =_xlfn.XLOOKUP($C13,'Cons. Financials - ''23 ''24'!$C$8:$C$79,'Cons. Financials - ''23 ''24'!S$8:S$79) -> 0.97938359 | H13: =_xlfn.XLOOKUP($C13,'Cons. Financials - ''23 ''24'!$C$8:$C$79,'Cons. Financials - ''23 ''24'!T$8:T$79) -> 0.97919883 | I13: =_xlfn.XLOOKUP($C13,'Cons. Financials - ''23 ''24'!$C$8:$C$79,'Cons. Financials - ''23 ''24'!U$8:U$79) -> 0.97919968 | J13: =_xlfn.XLOOKUP($C13,'Cons. Financials - ''23 ''24'!$C$8:$C$79,'Cons. Financials - ''23 ''24'!V$8:V$79) -> 0.97923242 | K13: =_xlfn.XLOOKUP($C13,'Cons. Financials - ''23 ''24'!$C$8:$C$79,'Cons. Financials - ''23 ''24'!W$8:W$79) -> 0.9795568 | ... O13: =_xlfn.XLOOKUP($C13,'Cons. Financials - ''23 ''24'!$C$8:$C$79,'Cons. Financials - ''23 ''24'!AA$8:AA$79) -> 0.9797479 | P13: =P14/P12 -> 0.98001835 | Q13: =Q14/Q12 -> 0.98003254 | R13: =R14/R12 -> 0.98003254 | S13: =S14/S12 -> 0.98006934 | T13: =T14/T12 -> 0.98006934 | U13: =U14/U12 -> 0.98006934 | V13: =V14/V12 -> 0.98001182 | W13: =W14/W12 -> 0.98001182 | ... AA13: =AA14/AA12 -> 0.98001182 | AC13: ='Cons. Financials - ''23 ''24'!AC13 -> 0.98043866 | AD13: =AD14/AD12 -> 0.97946656 | AE13: =AE14/AE12 -> 0.98003268
C14: Total Revenue | D14: =_xlfn.XLOOKUP($C14,'Cons. Financials - ''23 ''24'!$C$8:$C$79,'Cons. Financials - ''23 ''24'!P$8:P$79) -> 13553.034 | E14: =_xlfn.XLOOKUP($C14,'Cons. Financials - ''23 ''24'!$C$8:$C$79,'Cons. Financials - ''23 ''24'!Q$8:Q$79) -> 12772.373 | F14: =_xlfn.XLOOKUP($C14,'Cons. Financials - ''23 ''24'!$C$8:$C$79,'Cons. Financials - ''23 ''24'!R$8:R$79) -> 12628.725 | G14: =_xlfn.XLOOKUP($C14,'Cons. Financials - ''23 ''24'!$C$8:$C$79,'Cons. Financials - ''23 ''24'!S$8:S$79) -> 11816.716 | H14: =_xlfn.XLOOKUP($C14,'Cons. Financials - ''23 ''24'!$C$8:$C$79,'Cons. Financials - ''23 ''24'!T$8:T$79) -> 11857.717 | I14: =_xlfn.XLOOKUP($C14,'Cons. Financials - ''23 ''24'!$C$8:$C$79,'Cons. Financials - ''23 ''24'!U$8:U$79) -> 10887.656 | J14: =_xlfn.XLOOKUP($C14,'Cons. Financials - ''23 ''24'!$C$8:$C$79,'Cons. Financials - ''23 ''24'!V$8:V$79) -> 12727.729 | K14: =_xlfn.XLOOKUP($C14,'Cons. Financials - ''23 ''24'!$C$8:$C$79,'Cons. Financials - ''23 ''24'!W$8:W$79) -> 13239.236 | ... O14: =_xlfn.XLOOKUP($C14,'Cons. Financials - ''23 ''24'!$C$8:$C$79,'Cons. Financials - ''23 ''24'!AA$8:AA$79) -> 9894.6826 | P14: =SUMIFS('Site Level Budget - ''25'!S:S,'Site Level Budget - ''25'!$F:$F,'Consolidated Budget - ''25'!$C14) -> 14639.446 | Q14: =SUMIFS('Site Level Budget - ''25'!T:T,'Site Level Budget - ''25'!$F:$F,'Consolidated Budget - ''25'!$C14) -> 15356.317 | R14: =SUMIFS('Site Level Budget - ''25'!U:U,'Site Level Budget - ''25'!$F:$F,'Consolidated Budget - ''25'!$C14) -> 16489.448 | S14: =SUMIFS('Site Level Budget - ''25'!V:V,'Site Level Budget - ''25'!$F:$F,'Consolidated Budget - ''25'!$C14) -> 17836.837 | T14: =SUMIFS('Site Level Budget - ''25'!W:W,'Site Level Budget - ''25'!$F:$F,'Consolidated Budget - ''25'!$C14) -> 21199.289 | U14: =SUMIFS('Site Level Budget - ''25'!X:X,'Site Level Budget - ''25'!$F:$F,'Consolidated Budget - ''25'!$C14) -> 17802.076 | V14: =SUMIFS('Site Level Budget - ''25'!Y:Y,'Site Level Budget - ''25'!$F:$F,'Consolidated Budget - ''25'!$C14) -> 18509.514 | W14: =SUMIFS('Site Level Budget - ''25'!Z:Z,'Site Level Budget - ''25'!$F:$F,'Consolidated Budget - ''25'!$C14) -> 15871.739 | X14: =SUMIFS('Site Level Budget - ''25'!AA:AA,'Site Level Budget - ''25'!$F:$F,'Consolidated Budget - ''25'!$C14) -> 14551.798 | Y14: =SUMIFS('Site Level Budget - ''25'!AB:AB,'Site Level Budget - ''25'!$F:$F,'Consolidated Budget - ''25'!$C14) -> 16712.634 | Z14: =SUMIFS('Site Level Budget - ''25'!AC:AC,'Site Level Budget - ''25'!$F:$F,'Consolidated Budget - ''25'!$C14) -> 13210.819 | AA14: =SUMIFS('Site Level Budget - ''25'!AD:AD,'Site Level Budget - ''25'!$F:$F,'Consolidated Budget - ''25'!$C14) -> 10782.836 | AC14: ='Cons. Financials - ''23 ''24'!AC14 -> 127089.06 | AD14: =SUM(D14:O14) -> 147467.14 | AE14: =SUM(P14:AA14) -> 192962.75
C15: % YoY Revenue Growth | D15: =_xlfn.XLOOKUP($C15,'Cons. Financials - ''23 ''24'!$C$8:$C$79,'Cons. Financials - ''23 ''24'!P$8:P$79) -> 0.48161848 | E15: =_xlfn.XLOOKUP($C15,'Cons. Financials - ''23 ''24'!$C$8:$C$79,'Cons. Financials - ''23 ''24'!Q$8:Q$79) -> 0.44537408 | F15: =_xlfn.XLOOKUP($C15,'Cons. Financials - ''23 ''24'!$C$8:$C$79,'Cons. Financials - ''23 ''24'!R$8:R$79) -> 0.30956681 | G15: =_xlfn.XLOOKUP($C15,'Cons. Financials - ''23 ''24'!$C$8:$C$79,'Cons. Financials - ''23 ''24'!S$8:S$79) -> 0.3299737 | H15: =_xlfn.XLOOKUP($C15,'Cons. Financials - ''23 ''24'!$C$8:$C$79,'Cons. Financials - ''23 ''24'!T$8:T$79) -> 0.20921941 | I15: =_xlfn.XLOOKUP($C15,'Cons. Financials - ''23 ''24'!$C$8:$C$79,'Cons. Financials - ''23 ''24'!U$8:U$79) -> 0.14250038 | J15: =_xlfn.XLOOKUP($C15,'Cons. Financials - ''23 ''24'!$C$8:$C$79,'Cons. Financials - ''23 ''24'!V$8:V$79) -> 0.25017714 | K15: =_xlfn.XLOOKUP($C15,'Cons. Financials - ''23 ''24'!$C$8:$C$79,'Cons. Financials - ''23 ''24'!W$8:W$79) -> 0.02419435 | ... O15: =_xlfn.XLOOKUP($C15,'Cons. Financials - ''23 ''24'!$C$8:$C$79,'Cons. Financials - ''23 ''24'!AA$8:AA$79) -> -0.13453179 | P15: =P14/D14-1 -> 0.080160003 | Q15: =Q14/E14-1 -> 0.20230732 | R15: =R14/F14-1 -> 0.30570966 | S15: =S14/G14-1 -> 0.50945798 | T15: =T14/H14-1 -> 0.7878052 | U15: =U14/I14-1 -> 0.6350697 | V15: =V14/J14-1 -> 0.45426678 | W15: =W14/K14-1 -> 0.19884097 | ... AA15: =AA14/O14-1 -> 0.089760678 | AC15: ='Cons. Financials - ''23 ''24'!AC15 -> 0 | AD15: =AD14/AC14-1 -> 0.1603449 | AE15: =AE14/AD14-1 -> 0.30851355
D16: =_xlfn.XLOOKUP($C16,'Cons. Financials - ''23 ''24'!$C$8:$C$79,'Cons. Financials - ''23 ''24'!P$8:P$79) -> 0 | E16: =_xlfn.XLOOKUP($C16,'Cons. Financials - ''23 ''24'!$C$8:$C$79,'Cons. Financials - ''23 ''24'!Q$8:Q$79) -> 0 | F16: =_xlfn.XLOOKUP($C16,'Cons. Financials - ''23 ''24'!$C$8:$C$79,'Cons. Financials - ''23 ''24'!R$8:R$79) -> 0 | G16: =_xlfn.XLOOKUP($C16,'Cons. Financials - ''23 ''24'!$C$8:$C$79,'Cons. Financials - ''23 ''24'!S$8:S$79) -> 0 | H16: =_xlfn.XLOOKUP($C16,'Cons. Financials - ''23 ''24'!$C$8:$C$79,'Cons. Financials - ''23 ''24'!T$8:T$79) -> 0 | I16: =_xlfn.XLOOKUP($C16,'Cons. Financials - ''23 ''24'!$C$8:$C$79,'Cons. Financials - ''23 ''24'!U$8:U$79) -> 0 | J16: =_xlfn.XLOOKUP($C16,'Cons. Financials - ''23 ''24'!$C$8:$C$79,'Cons. Financials - ''23 ''24'!V$8:V$79) -> 0 | K16: =_xlfn.XLOOKUP($C16,'Cons. Financials - ''23 ''24'!$C$8:$C$79,'Cons. Financials - ''23 ''24'!W$8:W$79) -> 0 | ... O16: =_xlfn.XLOOKUP($C16,'Cons. Financials - ''23 ''24'!$C$8:$C$79,'Cons. Financials - ''23 ''24'!AA$8:AA$79) -> 0 | AC16: ='Cons. Financials - ''23 ''24'!AC16 -> 0
C17: Doctor Compensation | D17: =_xlfn.XLOOKUP($C17,'Cons. Financials - ''23 ''24'!$C$8:$C$79,'Cons. Financials - ''23 ''24'!P$8:P$79) -> -4032.1322 | E17: =_xlfn.XLOOKUP($C17,'Cons. Financials - ''23 ''24'!$C$8:$C$79,'Cons. Financials - ''23 ''24'!Q$8:Q$79) -> -4085.7998 | F17: =_xlfn.XLOOKUP($C17,'Cons. Financials - ''23 ''24'!$C$8:$C$79,'Cons. Financials - ''23 ''24'!R$8:R$79) -> -4099.6397 | G17: =_xlfn.XLOOKUP($C17,'Cons. Financials - ''23 ''24'!$C$8:$C$79,'Cons. Financials - ''23 ''24'!S$8:S$79) -> -4139.5895 | H17: =_xlfn.XLOOKUP($C17,'Cons. Financials - ''23 ''24'!$C$8:$C$79,'Cons. Financials - ''23 ''24'!T$8:T$79) -> -4349.17 | I17: =_xlfn.XLOOKUP($C17,'Cons. Financials - ''23 ''24'!$C$8:$C$79,'Cons. Financials - ''23 ''24'!U$8:U$79) -> -3780.9726 | J17: =_xlfn.XLOOKUP($C17,'Cons. Financials - ''23 ''24'!$C$8:$C$79,'Cons. Financials - ''23 ''24'!V$8:V$79) -> -4111.7717 | K17: =_xlfn.XLOOKUP($C17,'Cons. Financials - ''23 ''24'!$C$8:$C$79,'Cons. Financials - ''23 ''24'!W$8:W$79) -> -3704.5698 | ... O17: =_xlfn.XLOOKUP($C17,'Cons. Financials - ''23 ''24'!$C$8:$C$79,'Cons. Financials - ''23 ''24'!AA$8:AA$79) -> -2724.9779 | P17: =SUMIFS('Site Level Budget - ''25'!S:S,'Site Level Budget - ''25'!$F:$F,'Consolidated Budget - ''25'!$C17) -> -4392.0461 | Q17: =SUMIFS('Site Level Budget - ''25'!T:T,'Site Level Budget - ''25'!$F:$F,'Consolidated Budget - ''25'!$C17) -> -4946.5038 | R17: =SUMIFS('Site Level Budget - ''25'!U:U,'Site Level Budget - ''25'!$F:$F,'Consolidated Budget - ''25'!$C17) -> -5448.4466 | S17: =SUMIFS('Site Level Budget - ''25'!V:V,'Site Level Budget - ''25'!$F:$F,'Consolidated Budget - ''25'!$C17) -> -6518.3659 | T17: =SUMIFS('Site Level Budget - ''25'!W:W,'Site Level Budget - ''25'!$F:$F,'Consolidated Budget - ''25'!$C17) -> -7933.2706 | U17: =SUMIFS('Site Level Budget - ''25'!X:X,'Site Level Budget - ''25'!$F:$F,'Consolidated Budget - ''25'!$C17) -> -6322.0703 | V17: =SUMIFS('Site Level Budget - ''25'!Y:Y,'Site Level Budget - ''25'!$F:$F,'Consolidated Budget - ''25'!$C17) -> -6127.642 | W17: =SUMIFS('Site Level Budget - ''25'!Z:Z,'Site Level Budget - ''25'!$F:$F,'Consolidated Budget - ''25'!$C17) -> -4485.0988 | X17: =SUMIFS('Site Level Budget - ''25'!AA:AA,'Site Level Budget - ''25'!$F:$F,'Consolidated Budget - ''25'!$C17) -> -4425.6795 | Y17: =SUMIFS('Site Level Budget - ''25'!AB:AB,'Site Level Budget - ''25'!$F:$F,'Consolidated Budget - ''25'!$C17) -> -5194.4768 | Z17: =SUMIFS('Site Level Budget - ''25'!AC:AC,'Site Level Budget - ''25'!$F:$F,'Consolidated Budget - ''25'!$C17) -> -3610.5648 | AA17: =SUMIFS('Site Level Budget - ''25'!AD:AD,'Site Level Budget - ''25'!$F:$F,'Consolidated Budget - ''25'!$C17) -> -3013.6255 | AC17: ='Cons. Financials - ''23 ''24'!AC17 -> -38614.057 | AD17: =SUM(D17:O17) -> -46137.125 | AE17: =SUM(P17:AA17) -> -62417.791
C18: % of Revenue | D18: =-(D17/D$14) -> 0.29750771 | E18: =-(E17/E$14) -> 0.31989356 | F18: =-(F17/F$14) -> 0.32462815 | G18: =-(G17/G$14) -> 0.3503164 | H18: =-(H17/H$14) -> 0.36677969 | I18: =-(I17/I$14) -> 0.3472715 | J18: =-(J17/J$14) -> 0.32305618 | K18: =-(K17/K$14) -> 0.27981749 | ... AA18: =-(AA17/AA$14) -> 0.27948357 | AC18: ='Cons. Financials - ''23 ''24'!AC18 -> 0.30383463 | AD18: =-(AD17/AD$14) -> 0.31286376 | AE18: =-(AE17/AE$14) -> 0.32347067
AC19: ='Cons. Financials - ''23 ''24'!AC19 -> 0
C20: Administrative Staff Compensation | D20: =_xlfn.XLOOKUP($C20,'Cons. Financials - ''23 ''24'!$C$8:$C$79,'Cons. Financials - ''23 ''24'!P$8:P$79) -> -2181.494 | E20: =_xlfn.XLOOKUP($C20,'Cons. Financials - ''23 ''24'!$C$8:$C$79,'Cons. Financials - ''23 ''24'!Q$8:Q$79) -> -2236.7333 | F20: =_xlfn.XLOOKUP($C20,'Cons. Financials - ''23 ''24'!$C$8:$C$79,'Cons. Financials - ''23 ''24'!R$8:R$79) -> -2394.2282 | G20: =_xlfn.XLOOKUP($C20,'Cons. Financials - ''23 ''24'!$C$8:$C$79,'Cons. Financials - ''23 ''24'!S$8:S$79) -> -2591.1156 | H20: =_xlfn.XLOOKUP($C20,'Cons. Financials - ''23 ''24'!$C$8:$C$79,'Cons. Financials - ''23 ''24'!T$8:T$79) -> -2967.9251 | I20: =_xlfn.XLOOKUP($C20,'Cons. Financials - ''23 ''24'!$C$8:$C$79,'Cons. Financials - ''23 ''24'!U$8:U$79) -> -2556.2504 | J20: =_xlfn.XLOOKUP($C20,'Cons. Financials - ''23 ''24'!$C$8:$C$79,'Cons. Financials - ''23 ''24'!V$8:V$79) -> -2600.6546 | K20: =_xlfn.XLOOKUP($C20,'Cons. Financials - ''23 ''24'!$C$8:$C$79,'Cons. Financials - ''23 ''24'!W$8:W$79) -> -2253.4917 | ... O20: =_xlfn.XLOOKUP($C20,'Cons. Financials - ''23 ''24'!$C$8:$C$79,'Cons. Financials - ''23 ''24'!AA$8:AA$79) -> -1537.826 | P20: =SUMIFS('Site Level Budget - ''25'!S:S,'Site Level Budget - ''25'!$F:$F,'Consolidated Budget - ''25'!$C20) -> -2424.9389 | Q20: =SUMIFS('Site Level Budget - ''25'!T:T,'Site Level Budget - ''25'!$F:$F,'Consolidated Budget - ''25'!$C20) -> -2783.5486 | R20: =SUMIFS('Site Level Budget - ''25'!U:U,'Site Level Budget - ''25'!$F:$F,'Consolidated Budget - ''25'!$C20) -> -3222.5747 | S20: =SUMIFS('Site Level Budget - ''25'!V:V,'Site Level Budget - ''25'!$F:$F,'Consolidated Budget - ''25'!$C20) -> -4147.0553 | T20: =SUMIFS('Site Level Budget - ''25'!W:W,'Site Level Budget - ''25'!$F:$F,'Consolidated Budget - ''25'!$C20) -> -5732.5853 | U20: =SUMIFS('Site Level Budget - ''25'!X:X,'Site Level Budget - ''25'!$F:$F,'Consolidated Budget - ''25'!$C20) -> -4424.2605 | V20: =SUMIFS('Site Level Budget - ''25'!Y:Y,'Site Level Budget - ''25'!$F:$F,'Consolidated Budget - ''25'!$C20) -> -4034.7727 | W20: =SUMIFS('Site Level Budget - ''25'!Z:Z,'Site Level Budget - ''25'!$F:$F,'Consolidated Budget - ''25'!$C20) -> -2765.7384 | X20: =SUMIFS('Site Level Budget - ''25'!AA:AA,'Site Level Budget - ''25'!$F:$F,'Consolidated Budget - ''25'!$C20) -> -2573.0033 | Y20: =SUMIFS('Site Level Budget - ''25'!AB:AB,'Site Level Budget - ''25'!$F:$F,'Consolidated Budget - ''25'!$C20) -> -2990.7535 | Z20: =SUMIFS('Site Level Budget - ''25'!AC:AC,'Site Level Budget - ''25'!$F:$F,'Consolidated Budget - ''25'!$C20) -> -2056.3073 | AA20: =SUMIFS('Site Level Budget - ''25'!AD:AD,'Site Level Budget - ''25'!$F:$F,'Consolidated Budget - ''25'!$C20) -> -1701.0435 | AC20: ='Cons. Financials - ''23 ''24'!AC20 -> -22557.406 | AD20: =SUM(D20:O20) -> -27690.66 | AE20: =SUM(P20:AA20) -> -38856.582
C21: % of Revenue | D21: =-(D20/D$14) -> 0.16095982 | E21: =-(E20/E$14) -> 0.17512277 | F21: =-(F20/F$14) -> 0.1895859 | G21: =-(G20/G$14) -> 0.21927544 | H21: =-(H20/H$14) -> 0.25029481 | I21: =-(I20/I$14) -> 0.23478427 | J21: =-(J20/J$14) -> 0.20432982 | K21: =-(K20/K$14) -> 0.17021312 | ... AA21: =-(AA20/AA$14) -> 0.15775474 | AC21: ='Cons. Financials - ''23 ''24'!AC21 -> 0.1774929 | AD21: =-(AD20/AD$14) -> 0.18777512 | AE21: =-(AE20/AE$14) -> 0.2013683
AC22: ='Cons. Financials - ''23 ''24'!AC22 -> 0
C23: Office Supplies | D23: =_xlfn.XLOOKUP($C23,'Cons. Financials - ''23 ''24'!$C$8:$C$79,'Cons. Financials - ''23 ''24'!P$8:P$79) -> -772.78999 | E23: =_xlfn.XLOOKUP($C23,'Cons. Financials - ''23 ''24'!$C$8:$C$79,'Cons. Financials - ''23 ''24'!Q$8:Q$79) -> -790.629 | F23: =_xlfn.XLOOKUP($C23,'Cons. Financials - ''23 ''24'!$C$8:$C$79,'Cons. Financials - ''23 ''24'!R$8:R$79) -> -853.76672 | G23: =_xlfn.XLOOKUP($C23,'Cons. Financials - ''23 ''24'!$C$8:$C$79,'Cons. Financials - ''23 ''24'!S$8:S$79) -> -921.87788 | H23: =_xlfn.XLOOKUP($C23,'Cons. Financials - ''23 ''24'!$C$8:$C$79,'Cons. Financials - ''23 ''24'!T$8:T$79) -> -1103.8376 | I23: =_xlfn.XLOOKUP($C23,'Cons. Financials - ''23 ''24'!$C$8:$C$79,'Cons. Financials - ''23 ''24'!U$8:U$79) -> -915.14327 | J23: =_xlfn.XLOOKUP($C23,'Cons. Financials - ''23 ''24'!$C$8:$C$79,'Cons. Financials - ''23 ''24'!V$8:V$79) -> -925.59907 | K23: =_xlfn.XLOOKUP($C23,'Cons. Financials - ''23 ''24'!$C$8:$C$79,'Cons. Financials - ''23 ''24'!W$8:W$79) -> -791.1068 | ... O23: =_xlfn.XLOOKUP($C23,'Cons. Financials - ''23 ''24'!$C$8:$C$79,'Cons. Financials - ''23 ''24'!AA$8:AA$79) -> -524.25461 | P23: =SUMIFS('Site Level Budget - ''25'!S:S,'Site Level Budget - ''25'!$F:$F,'Consolidated Budget - ''25'!$C23) -> -832.89153 | Q23: =SUMIFS('Site Level Budget - ''25'!T:T,'Site Level Budget - ''25'!$F:$F,'Consolidated Budget - ''25'!$C23) -> -952.34169 | R23: =SUMIFS('Site Level Budget - ''25'!U:U,'Site Level Budget - ''25'!$F:$F,'Consolidated Budget - ''25'!$C23) -> -1122.9915 | S23: =SUMIFS('Site Level Budget - ''25'!V:V,'Site Level Budget - ''25'!$F:$F,'Consolidated Budget - ''25'!$C23) -> -1451.2514 | T23: =SUMIFS('Site Level Budget - ''25'!W:W,'Site Level Budget - ''25'!$F:$F,'Consolidated Budget - ''25'!$C23) -> -2074.2657 | U23: =SUMIFS('Site Level Budget - ''25'!X:X,'Site Level Budget - ''25'!$F:$F,'Consolidated Budget - ''25'!$C23) -> -1546.451 | V23: =SUMIFS('Site Level Budget - ''25'!Y:Y,'Site Level Budget - ''25'!$F:$F,'Consolidated Budget - ''25'!$C23) -> -1407.69 | W23: =SUMIFS('Site Level Budget - ''25'!Z:Z,'Site Level Budget - ''25'!$F:$F,'Consolidated Budget - ''25'!$C23) -> -954.56583 | X23: =SUMIFS('Site Level Budget - ''25'!AA:AA,'Site Level Budget - ''25'!$F:$F,'Consolidated Budget - ''25'!$C23) -> -876.25142 | Y23: =SUMIFS('Site Level Budget - ''25'!AB:AB,'Site Level Budget - ''25'!$F:$F,'Consolidated Budget - ''25'!$C23) -> -1013.4337 | Z23: =SUMIFS('Site Level Budget - ''25'!AC:AC,'Site Level Budget - ''25'!$F:$F,'Consolidated Budget - ''25'!$C23) -> -694.01026 | AA23: =SUMIFS('Site Level Budget - ''25'!AD:AD,'Site Level Budget - ''25'!$F:$F,'Consolidated Budget - ''25'!$C23) -> -577.9311 | AC23: ='Cons. Financials - ''23 ''24'!AC23 -> -9020.3982 | AD23: =SUM(D23:O23) -> -9791.4808 | AE23: =SUM(P23:AA23) -> -13504.075
C24: % of Revenue | D24: =-(D23/D$14) -> 0.057019703 | E24: =-(E23/E$14) -> 0.061901496 | F24: =-(F23/F$14) -> 0.067605139 | G24: =-(G23/G$14) -> 0.078014726 | H24: =-(H23/H$14) -> 0.093090223 | I24: =-(I23/I$14) -> 0.084053287 | J24: =-(J23/J$14) -> 0.072723032 | K24: =-(K23/K$14) -> 0.059754716 | ... AA24: =-(AA23/AA$14) -> 0.053597319 | AC24: ='Cons. Financials - ''23 ''24'!AC24 -> 0.070976984 | AD24: =-(AD23/AD$14) -> 0.066397712 | AE24: =-(AE23/AE$14) -> 0.069982808
AC25: ='Cons. Financials - ''23 ''24'!AC25 -> 0
C26: Office Gross Profit | D26: =D14+D17+D20+D23 -> 6566.618 | E26: =E14+E17+E20+E23 -> 5659.2109 | F26: =F14+F17+F20+F23 -> 5281.0905 | G26: =G14+G17+G20+G23 -> 4164.1334 | H26: =H14+H17+H20+H23 -> 3436.7847 | I26: =I14+I17+I20+I23 -> 3635.2896 | J26: =J14+J17+J20+J23 -> 5089.704 | K26: =K14+K17+K20+K23 -> 6490.0678 | ... AA26: =AA14+AA17+AA20+AA23 -> 5490.2359 | AC26: ='Cons. Financials - ''23 ''24'!AC26 -> 56897.198 | AD26: =SUM(D26:O26) -> 63847.876 | AE26: =SUM(P26:AA26) -> 78184.305
C27: % of Revenue | D27: =(D26/D$14) -> 0.48451276 | E27: =(E26/E$14) -> 0.44308218 | F27: =(F26/F$14) -> 0.41818081 | G27: =(G26/G$14) -> 0.35239344 | H27: =(H26/H$14) -> 0.28983527 | I27: =(I26/I$14) -> 0.33389094 | J27: =(J26/J$14) -> 0.39989097 | K27: =(K26/K$14) -> 0.49021467 | ... AA27: =(AA26/AA$14) -> 0.50916437 | AC27: ='Cons. Financials - ''23 ''24'!AC27 -> 0.44769548 | AD27: =(AD26/AD$14) -> 0.43296341 | AE27: =(AE26/AE$14) -> 0.40517822
AC28: ='Cons. Financials - ''23 ''24'!AC28 -> 0
C29: General and Administrative Expense | D29: =_xlfn.XLOOKUP($C29,'Cons. Financials - ''23 ''24'!$C$8:$C$79,'Cons. Financials - ''23 ''24'!P$8:P$79) -> -520.2268 | E29: =_xlfn.XLOOKUP($C29,'Cons. Financials - ''23 ''24'!$C$8:$C$79,'Cons. Financials - ''23 ''24'!Q$8:Q$79) -> -531.73365 | F29: =_xlfn.XLOOKUP($C29,'Cons. Financials - ''23 ''24'!$C$8:$C$79,'Cons. Financials - ''23 ''24'!R$8:R$79) -> -581.61048 | G29: =_xlfn.XLOOKUP($C29,'Cons. Financials - ''23 ''24'!$C$8:$C$79,'Cons. Financials - ''23 ''24'!S$8:S$79) -> -625.21945 | H29: =_xlfn.XLOOKUP($C29,'Cons. Financials - ''23 ''24'!$C$8:$C$79,'Cons. Financials - ''23 ''24'!T$8:T$79) -> -755.27144 | I29: =_xlfn.XLOOKUP($C29,'Cons. Financials - ''23 ''24'!$C$8:$C$79,'Cons. Financials - ''23 ''24'!U$8:U$79) -> -632.69583 | J29: =_xlfn.XLOOKUP($C29,'Cons. Financials - ''23 ''24'!$C$8:$C$79,'Cons. Financials - ''23 ''24'!V$8:V$79) -> -642.35044 | K29: =_xlfn.XLOOKUP($C29,'Cons. Financials - ''23 ''24'!$C$8:$C$79,'Cons. Financials - ''23 ''24'!W$8:W$79) -> -540.61414 | ... O29: =_xlfn.XLOOKUP($C29,'Cons. Financials - ''23 ''24'!$C$8:$C$79,'Cons. Financials - ''23 ''24'!AA$8:AA$79) -> -352.57552 | P29: =SUMIFS('Site Level Budget - ''25'!S:S,'Site Level Budget - ''25'!$F:$F,'Consolidated Budget - ''25'!$C29) -> -557.18909 | Q29: =SUMIFS('Site Level Budget - ''25'!T:T,'Site Level Budget - ''25'!$F:$F,'Consolidated Budget - ''25'!$C29) -> -645.80606 | R29: =SUMIFS('Site Level Budget - ''25'!U:U,'Site Level Budget - ''25'!$F:$F,'Consolidated Budget - ''25'!$C29) -> -771.0925 | S29: =SUMIFS('Site Level Budget - ''25'!V:V,'Site Level Budget - ''25'!$F:$F,'Consolidated Budget - ''25'!$C29) -> -1012.1301 | T29: =SUMIFS('Site Level Budget - ''25'!W:W,'Site Level Budget - ''25'!$F:$F,'Consolidated Budget - ''25'!$C29) -> -1543.0779 | U29: =SUMIFS('Site Level Budget - ''25'!X:X,'Site Level Budget - ''25'!$F:$F,'Consolidated Budget - ''25'!$C29) -> -1172.5585 | V29: =SUMIFS('Site Level Budget - ''25'!Y:Y,'Site Level Budget - ''25'!$F:$F,'Consolidated Budget - ''25'!$C29) -> -1063.4297 | W29: =SUMIFS('Site Level Budget - ''25'!Z:Z,'Site Level Budget - ''25'!$F:$F,'Consolidated Budget - ''25'!$C29) -> -689.95019 | X29: =SUMIFS('Site Level Budget - ''25'!AA:AA,'Site Level Budget - ''25'!$F:$F,'Consolidated Budget - ''25'!$C29) -> -625.91029 | Y29: =SUMIFS('Site Level Budget - ''25'!AB:AB,'Site Level Budget - ''25'!$F:$F,'Consolidated Budget - ''25'!$C29) -> -712.87715 | Z29: =SUMIFS('Site Level Budget - ''25'!AC:AC,'Site Level Budget - ''25'!$F:$F,'Consolidated Budget - ''25'!$C29) -> -482.23418 | AA29: =SUMIFS('Site Level Budget - ''25'!AD:AD,'Site Level Budget - ''25'!$F:$F,'Consolidated Budget - ''25'!$C29) -> -399.8247 | AC29: ='Cons. Financials - ''23 ''24'!AC29 -> -6556.3033 | AD29: =SUM(D29:O29) -> -6665.974 | AE29: =SUM(P29:AA29) -> -9676.0802
C30: % of Revenue | D30: =(D29/D$14) -> -0.038384526 | E30: =(E29/E$14) -> -0.041631547 | F30: =(F29/F$14) -> -0.046054568 | G30: =(G29/G$14) -> -0.052909745 | H30: =(H29/H$14) -> -0.063694506 | I30: =(I29/I$14) -> -0.058111299 | J30: =(J29/J$14) -> -0.050468581 | K30: =(K29/K$14) -> -0.040834239 | ... AA30: =(AA29/AA$14) -> -0.037079735 | AC30: ='Cons. Financials - ''23 ''24'!AC30 -> -0.051588259 | AD30: =(AD29/AD$14) -> -0.045203114 | AE30: =(AE29/AE$14) -> -0.050144808
AC31: ='Cons. Financials - ''23 ''24'!AC31 -> 0
C32: Marketing | D32: =_xlfn.XLOOKUP($C32,'Cons. Financials - ''23 ''24'!$C$8:$C$79,'Cons. Financials - ''23 ''24'!P$8:P$79) -> -297.75131 | E32: =_xlfn.XLOOKUP($C32,'Cons. Financials - ''23 ''24'!$C$8:$C$79,'Cons. Financials - ''23 ''24'!Q$8:Q$79) -> -301.20967 | F32: =_xlfn.XLOOKUP($C32,'Cons. Financials - ''23 ''24'!$C$8:$C$79,'Cons. Financials - ''23 ''24'!R$8:R$79) -> -326.88367 | G32: =_xlfn.XLOOKUP($C32,'Cons. Financials - ''23 ''24'!$C$8:$C$79,'Cons. Financials - ''23 ''24'!S$8:S$79) -> -350.03651 | H32: =_xlfn.XLOOKUP($C32,'Cons. Financials - ''23 ''24'!$C$8:$C$79,'Cons. Financials - ''23 ''24'!T$8:T$79) -> -435.78904 | I32: =_xlfn.XLOOKUP($C32,'Cons. Financials - ''23 ''24'!$C$8:$C$79,'Cons. Financials - ''23 ''24'!U$8:U$79) -> -364.36409 | J32: =_xlfn.XLOOKUP($C32,'Cons. Financials - ''23 ''24'!$C$8:$C$79,'Cons. Financials - ''23 ''24'!V$8:V$79) -> -365.15346 | K32: =_xlfn.XLOOKUP($C32,'Cons. Financials - ''23 ''24'!$C$8:$C$79,'Cons. Financials - ''23 ''24'!W$8:W$79) -> -315.68593 | ... O32: =_xlfn.XLOOKUP($C32,'Cons. Financials - ''23 ''24'!$C$8:$C$79,'Cons. Financials - ''23 ''24'!AA$8:AA$79) -> -215.9737 | P32: =SUMIFS('Site Level Budget - ''25'!S:S,'Site Level Budget - ''25'!$F:$F,'Consolidated Budget - ''25'!$C32) -> -310.04096 | Q32: =SUMIFS('Site Level Budget - ''25'!T:T,'Site Level Budget - ''25'!$F:$F,'Consolidated Budget - ''25'!$C32) -> -356.51836 | R32: =SUMIFS('Site Level Budget - ''25'!U:U,'Site Level Budget - ''25'!$F:$F,'Consolidated Budget - ''25'!$C32) -> -425.23513 | S32: =SUMIFS('Site Level Budget - ''25'!V:V,'Site Level Budget - ''25'!$F:$F,'Consolidated Budget - ''25'!$C32) -> -566.30635 | T32: =SUMIFS('Site Level Budget - ''25'!W:W,'Site Level Budget - ''25'!$F:$F,'Consolidated Budget - ''25'!$C32) -> -858.87611 | U32: =SUMIFS('Site Level Budget - ''25'!X:X,'Site Level Budget - ''25'!$F:$F,'Consolidated Budget - ''25'!$C32) -> -638.06316 | V32: =SUMIFS('Site Level Budget - ''25'!Y:Y,'Site Level Budget - ''25'!$F:$F,'Consolidated Budget - ''25'!$C32) -> -584.95211 | W32: =SUMIFS('Site Level Budget - ''25'!Z:Z,'Site Level Budget - ''25'!$F:$F,'Consolidated Budget - ''25'!$C32) -> -393.83011 | X32: =SUMIFS('Site Level Budget - ''25'!AA:AA,'Site Level Budget - ''25'!$F:$F,'Consolidated Budget - ''25'!$C32) -> -358.84187 | Y32: =SUMIFS('Site Level Budget - ''25'!AB:AB,'Site Level Budget - ''25'!$F:$F,'Consolidated Budget - ''25'!$C32) -> -429.33301 | Z32: =SUMIFS('Site Level Budget - ''25'!AC:AC,'Site Level Budget - ''25'!$F:$F,'Consolidated Budget - ''25'!$C32) -> -292.86784 | AA32: =SUMIFS('Site Level Budget - ''25'!AD:AD,'Site Level Budget - ''25'!$F:$F,'Consolidated Budget - ''25'!$C32) -> -247.5068 | AC32: ='Cons. Financials - ''23 ''24'!AC32 -> -3833.03 | AD32: =SUM(D32:O32) -> -3861.6931 | AE32: =SUM(P32:AA32) -> -5462.3718
C33: % of Revenue | D33: =(D32/D$14) -> -0.021969347 | E33: =(E32/E$14) -> -0.023582906 | F33: =(F32/F$14) -> -0.025884139 | G33: =(G32/G$14) -> -0.029622147 | H33: =(H32/H$14) -> -0.036751512 | I33: =(I32/I$14) -> -0.033465798 | J33: =(J32/J$14) -> -0.028689599 | K33: =(K32/K$14) -> -0.023844724 | ... AA33: =(AA32/AA$14) -> -0.022953776 | AC33: ='Cons. Financials - ''23 ''24'!AC33 -> -0.030160188 | AD33: =(AD32/AD$14) -> -0.026186804 | AE33: =(AE32/AE$14) -> -0.028307908
AC34: ='Cons. Financials - ''23 ''24'!AC34 -> 0
C35: Office Rent | D35: =_xlfn.XLOOKUP($C35,'Cons. Financials - ''23 ''24'!$C$8:$C$79,'Cons. Financials - ''23 ''24'!P$8:P$79) -> -799.23691 | E35: =_xlfn.XLOOKUP($C35,'Cons. Financials - ''23 ''24'!$C$8:$C$79,'Cons. Financials - ''23 ''24'!Q$8:Q$79) -> -800.70615 | F35: =_xlfn.XLOOKUP($C35,'Cons. Financials - ''23 ''24'!$C$8:$C$79,'Cons. Financials - ''23 ''24'!R$8:R$79) -> -803.94851 | G35: =_xlfn.XLOOKUP($C35,'Cons. Financials - ''23 ''24'!$C$8:$C$79,'Cons. Financials - ''23 ''24'!S$8:S$79) -> -806.67021 | H35: =_xlfn.XLOOKUP($C35,'Cons. Financials - ''23 ''24'!$C$8:$C$79,'Cons. Financials - ''23 ''24'!T$8:T$79) -> -806.67021 | I35: =_xlfn.XLOOKUP($C35,'Cons. Financials - ''23 ''24'!$C$8:$C$79,'Cons. Financials - ''23 ''24'!U$8:U$79) -> -811.58748 | J35: =_xlfn.XLOOKUP($C35,'Cons. Financials - ''23 ''24'!$C$8:$C$79,'Cons. Financials - ''23 ''24'!V$8:V$79) -> -815.64517 | K35: =_xlfn.XLOOKUP($C35,'Cons. Financials - ''23 ''24'!$C$8:$C$79,'Cons. Financials - ''23 ''24'!W$8:W$79) -> -818.54817 | ... O35: =_xlfn.XLOOKUP($C35,'Cons. Financials - ''23 ''24'!$C$8:$C$79,'Cons. Financials - ''23 ''24'!AA$8:AA$79) -> -823.21401 | P35: =SUMIFS('Site Level Budget - ''25'!S:S,'Site Level Budget - ''25'!$F:$F,'Consolidated Budget - ''25'!$C35) -> -823.21401 | Q35: =SUMIFS('Site Level Budget - ''25'!T:T,'Site Level Budget - ''25'!$F:$F,'Consolidated Budget - ''25'!$C35) -> -824.72733 | R35: =SUMIFS('Site Level Budget - ''25'!U:U,'Site Level Budget - ''25'!$F:$F,'Consolidated Budget - ''25'!$C35) -> -828.06697 | S35: =SUMIFS('Site Level Budget - ''25'!V:V,'Site Level Budget - ''25'!$F:$F,'Consolidated Budget - ''25'!$C35) -> -830.87031 | T35: =SUMIFS('Site Level Budget - ''25'!W:W,'Site Level Budget - ''25'!$F:$F,'Consolidated Budget - ''25'!$C35) -> -830.87031 | U35: =SUMIFS('Site Level Budget - ''25'!X:X,'Site Level Budget - ''25'!$F:$F,'Consolidated Budget - ''25'!$C35) -> -835.9351 | V35: =SUMIFS('Site Level Budget - ''25'!Y:Y,'Site Level Budget - ''25'!$F:$F,'Consolidated Budget - ''25'!$C35) -> -840.11452 | W35: =SUMIFS('Site Level Budget - ''25'!Z:Z,'Site Level Budget - ''25'!$F:$F,'Consolidated Budget - ''25'!$C35) -> -843.10462 | X35: =SUMIFS('Site Level Budget - ''25'!AA:AA,'Site Level Budget - ''25'!$F:$F,'Consolidated Budget - ''25'!$C35) -> -843.59253 | Y35: =SUMIFS('Site Level Budget - ''25'!AB:AB,'Site Level Budget - ''25'!$F:$F,'Consolidated Budget - ''25'!$C35) -> -846.9492 | Z35: =SUMIFS('Site Level Budget - ''25'!AC:AC,'Site Level Budget - ''25'!$F:$F,'Consolidated Budget - ''25'!$C35) -> -846.9492 | AA35: =SUMIFS('Site Level Budget - ''25'!AD:AD,'Site Level Budget - ''25'!$F:$F,'Consolidated Budget - ''25'!$C35) -> -847.91043 | AC35: ='Cons. Financials - ''23 ''24'!AC35 -> -9465.8118 | AD35: =SUM(D35:O35) -> -9749.8102 | AE35: =SUM(P35:AA35) -> -10042.305
C36: % YoY Growth | D36: =_xlfn.XLOOKUP($C36,'Cons. Financials - ''23 ''24'!$C$8:$C$79,'Cons. Financials - ''23 ''24'!P$8:P$79) -> 0.030002533 | E36: =_xlfn.XLOOKUP($C36,'Cons. Financials - ''23 ''24'!$C$8:$C$79,'Cons. Financials - ''23 ''24'!Q$8:Q$79) -> 0.030002556 | F36: =_xlfn.XLOOKUP($C36,'Cons. Financials - ''23 ''24'!$C$8:$C$79,'Cons. Financials - ''23 ''24'!R$8:R$79) -> 0.030002537 | G36: =_xlfn.XLOOKUP($C36,'Cons. Financials - ''23 ''24'!$C$8:$C$79,'Cons. Financials - ''23 ''24'!S$8:S$79) -> 0.030002544 | H36: =_xlfn.XLOOKUP($C36,'Cons. Financials - ''23 ''24'!$C$8:$C$79,'Cons. Financials - ''23 ''24'!T$8:T$79) -> 0.030002544 | I36: =_xlfn.XLOOKUP($C36,'Cons. Financials - ''23 ''24'!$C$8:$C$79,'Cons. Financials - ''23 ''24'!U$8:U$79) -> 0.030002573 | J36: =_xlfn.XLOOKUP($C36,'Cons. Financials - ''23 ''24'!$C$8:$C$79,'Cons. Financials - ''23 ''24'!V$8:V$79) -> 0.030002553 | K36: =_xlfn.XLOOKUP($C36,'Cons. Financials - ''23 ''24'!$C$8:$C$79,'Cons. Financials - ''23 ''24'!W$8:W$79) -> 0.030002544 | ... O36: =_xlfn.XLOOKUP($C36,'Cons. Financials - ''23 ''24'!$C$8:$C$79,'Cons. Financials - ''23 ''24'!AA$8:AA$79) -> 0.030002533 | P36: =P35/D35-1 -> 0.03 | Q36: =Q35/E35-1 -> 0.03 | R36: =R35/F35-1 -> 0.03 | S36: =S35/G35-1 -> 0.03 | T36: =T35/H35-1 -> 0.03 | U36: =U35/I35-1 -> 0.03 | V36: =V35/J35-1 -> 0.03 | W36: =W35/K35-1 -> 0.03 | ... AA36: =AA35/O35-1 -> 0.03 | AC36: ='Cons. Financials - ''23 ''24'!AC36 -> 0 | AD36: =AD35/AC35-1 -> 0.030002542 | AE36: =AE35/AD35-1 -> 0.03
AC37: ='Cons. Financials - ''23 ''24'!AC37 -> 0
C38: Office EBITDA | D38: =D26+D29+D32+D35 -> 4949.403 | E38: =E26+E29+E32+E35 -> 4025.5614 | F38: =F26+F29+F32+F35 -> 3568.6478 | G38: =G26+G29+G32+G35 -> 2382.2072 | H38: =H26+H29+H32+H35 -> 1439.054 | I38: =I26+I29+I32+I35 -> 1826.6422 | J38: =J26+J29+J32+J35 -> 3266.555 | K38: =K26+K29+K32+K35 -> 4815.2195 | ... AA38: =AA26+AA29+AA32+AA35 -> 3994.994 | AC38: ='Cons. Financials - ''23 ''24'!AC38 -> 37042.053 | AD38: =SUM(D38:O38) -> 43570.399 | AE38: =SUM(P38:AA38) -> 53003.548
C39: % of Revenue | D39: =(D38/D$14) -> 0.36518782 | E39: =(E38/E$14) -> 0.31517725 | F39: =(F38/F$14) -> 0.28258179 | G39: =(G38/G$14) -> 0.20159638 | H39: =(H38/H$14) -> 0.12136012 | I39: =(I38/I$14) -> 0.16777186 | J39: =(J38/J$14) -> 0.25664868 | K39: =(K38/K$14) -> 0.36370826 | ... AA39: =(AA38/AA$14) -> 0.37049566 | AC39: ='Cons. Financials - ''23 ''24'!AC39 -> 0.29146532 | AD39: =(AD38/AD$14) -> 0.29545835 | AE39: =(AE38/AE$14) -> 0.2746828
AC40: ='Cons. Financials - ''23 ''24'!AC40 -> 0
C41: Headcount Expenses | D41: =_xlfn.XLOOKUP($C41,'Cons. Financials - ''23 ''24'!$C$8:$C$79,'Cons. Financials - ''23 ''24'!P$8:P$79) -> -756.41667 | E41: =_xlfn.XLOOKUP($C41,'Cons. Financials - ''23 ''24'!$C$8:$C$79,'Cons. Financials - ''23 ''24'!Q$8:Q$79) -> -765.97917 | F41: =_xlfn.XLOOKUP($C41,'Cons. Financials - ''23 ''24'!$C$8:$C$79,'Cons. Financials - ''23 ''24'!R$8:R$79) -> -775.54167 | G41: =_xlfn.XLOOKUP($C41,'Cons. Financials - ''23 ''24'!$C$8:$C$79,'Cons. Financials - ''23 ''24'!S$8:S$79) -> -758.54167 | H41: =_xlfn.XLOOKUP($C41,'Cons. Financials - ''23 ''24'!$C$8:$C$79,'Cons. Financials - ''23 ''24'!T$8:T$79) -> -743.54167 | I41: =_xlfn.XLOOKUP($C41,'Cons. Financials - ''23 ''24'!$C$8:$C$79,'Cons. Financials - ''23 ''24'!U$8:U$79) -> -747.54167 | J41: =_xlfn.XLOOKUP($C41,'Cons. Financials - ''23 ''24'!$C$8:$C$79,'Cons. Financials - ''23 ''24'!V$8:V$79) -> -705.875 | K41: =_xlfn.XLOOKUP($C41,'Cons. Financials - ''23 ''24'!$C$8:$C$79,'Cons. Financials - ''23 ''24'!W$8:W$79) -> -712.375 | ... O41: =_xlfn.XLOOKUP($C41,'Cons. Financials - ''23 ''24'!$C$8:$C$79,'Cons. Financials - ''23 ''24'!AA$8:AA$79) -> -678.64583 | P41: =-'Corporate Monthly - ''25'!I353/1000 -> -817.70833 | Q41: =-'Corporate Monthly - ''25'!J353/1000 -> -876.5 | R41: =-'Corporate Monthly - ''25'!K353/1000 -> -876.5 | S41: =-'Corporate Monthly - ''25'!L353/1000 -> -876.5 | T41: =-'Corporate Monthly - ''25'!M353/1000 -> -876.5 | U41: =-'Corporate Monthly - ''25'!N353/1000 -> -876.5 | V41: =-'Corporate Monthly - ''25'!O353/1000 -> -876.5 | W41: =-'Corporate Monthly - ''25'!P353/1000 -> -876.5 | ... AA41: =-'Corporate Monthly - ''25'!T353/1000 -> -876.5 | AC41: ='Cons. Financials - ''23 ''24'!AC41 -> -8381.875 | AD41: =SUM(D41:O41) -> -8701.9792 | AE41: =SUM(P41:AA41) -> -10459.208
C42: % of Revenue | D42: =(D41/D$14) -> -0.05581161 | E42: =(E41/E$14) -> -0.059971563 | F42: =(F41/F$14) -> -0.061410923 | G42: =(G41/G$14) -> -0.064192255 | H42: =(H41/H$14) -> -0.062705295 | I42: =(I41/I$14) -> -0.06865956 | J42: =(J41/J$14) -> -0.055459617 | K42: =(K41/K$14) -> -0.053807863 | ... AA42: =(AA41/AA$14) -> -0.081286593 | AC42: ='Cons. Financials - ''23 ''24'!AC42 -> -0.065952766 | AD42: =(AD41/AD$14) -> -0.059009615 | AE42: =(AE41/AE$14) -> -0.05420325
AC43: ='Cons. Financials - ''23 ''24'!AC43 -> 0
...

Sheet Site Level Budget - '25
B2: Site | C2: Key | E2: Happy Pets Vets | AH2: =TODAY() -> 45999
B3: =G5 -> 1 | F3: Site Level Financials | AH3: ($ in 000s)
B5: =G5 -> 1 | F5: Site: | G5: 1
B6: =G5 -> 1 | F6: Paws & Claws Veterinary Care
B7: =G5 -> 1
B8: =G5 -> 1 | G8: 2024A | S8: 2025 Budget | AF8: Historicals | AH8: Budget
B9: =G5 -> 1 | G9: 44957 | H9: =EOMONTH(G9,1) -> 44985 | I9: =EOMONTH(H9,1) -> 45016 | J9: =EOMONTH(I9,1) -> 45046 | K9: =EOMONTH(J9,1) -> 45077 | L9: =EOMONTH(K9,1) -> 45107 | M9: =EOMONTH(L9,1) -> 45138 | N9: =EOMONTH(M9,1) -> 45169 | O9: =EOMONTH(N9,1) -> 45199 | ... AD9: =EOMONTH(AC9,1) -> 45657 | AF9: 45291 | AG9: 45657 | AH9: 46022
B10: =G5 -> 1
B11: =G5 -> 1 | C11: =B11&" - "&F11 -> 1 - Employed Vets | F11: Employed Vets | G11: =_xlfn.XLOOKUP($C11,'Site Level Financials - ''23 ''24'!$C$2:$C$1577,'Site Level Financials - ''23 ''24'!S$2:S$1577) -> 4 | H11: =_xlfn.XLOOKUP($C11,'Site Level Financials - ''23 ''24'!$C$2:$C$1577,'Site Level Financials - ''23 ''24'!T$2:T$1577) -> 4 | I11: =_xlfn.XLOOKUP($C11,'Site Level Financials - ''23 ''24'!$C$2:$C$1577,'Site Level Financials - ''23 ''24'!U$2:U$1577) -> 4 | J11: =_xlfn.XLOOKUP($C11,'Site Level Financials - ''23 ''24'!$C$2:$C$1577,'Site Level Financials - ''23 ''24'!V$2:V$1577) -> 3 | K11: =_xlfn.XLOOKUP($C11,'Site Level Financials - ''23 ''24'!$C$2:$C$1577,'Site Level Financials - ''23 ''24'!W$2:W$1577) -> 3 | L11: =_xlfn.XLOOKUP($C11,'Site Level Financials - ''23 ''24'!$C$2:$C$1577,'Site Level Financials - ''23 ''24'!X$2:X$1577) -> 4 | M11: =_xlfn.XLOOKUP($C11,'Site Level Financials - ''23 ''24'!$C$2:$C$1577,'Site Level Financials - ''23 ''24'!Y$2:Y$1577) -> 4 | N11: =_xlfn.XLOOKUP($C11,'Site Level Financials - ''23 ''24'!$C$2:$C$1577,'Site Level Financials - ''23 ''24'!Z$2:Z$1577) -> 5 | ... R11: =_xlfn.XLOOKUP($C11,'Site Level Financials - ''23 ''24'!$C$2:$C$1577,'Site Level Financials - ''23 ''24'!AD$2:AD$1577) -> 4 | S11: =R11+_xlfn.XLOOKUP($R11,'Budget Assumption Driver'!$A$7:$A$11,'Budget Assumption Driver'!E$7:E$11) -> 4 | T11: =S11+_xlfn.XLOOKUP($R11,'Budget Assumption Driver'!$A$7:$A$11,'Budget Assumption Driver'!F$7:F$11) -> 4 | U11: =T11+_xlfn.XLOOKUP($R11,'Budget Assumption Driver'!$A$7:$A$11,'Budget Assumption Driver'!G$7:G$11) -> 4 | V11: =U11+_xlfn.XLOOKUP($R11,'Budget Assumption Driver'!$A$7:$A$11,'Budget Assumption Driver'!H$7:H$11) -> 4 | W11: =V11+_xlfn.XLOOKUP($R11,'Budget Assumption Driver'!$A$7:$A$11,'Budget Assumption Driver'!I$7:I$11) -> 4 | X11: =W11+_xlfn.XLOOKUP($R11,'Budget Assumption Driver'!$A$7:$A$11,'Budget Assumption Driver'!J$7:J$11) -> 4 | Y11: =X11+_xlfn.XLOOKUP($R11,'Budget Assumption Driver'!$A$7:$A$11,'Budget Assumption Driver'!K$7:K$11) -> 4 | Z11: =Y11+_xlfn.XLOOKUP($R11,'Budget Assumption Driver'!$A$7:$A$11,'Budget Assumption Driver'!L$7:L$11) -> 4 | ... AD11: =AC11+_xlfn.XLOOKUP($R11,'Budget Assumption Driver'!$A$7:$A$11,'Budget Assumption Driver'!P$7:P$11) -> 4 | AF11: =_xlfn.XLOOKUP($C11,'Site Level Financials - ''23 ''24'!$C$2:$C$1577,'Site Level Financials - ''23 ''24'!$AF$2:$AF$1577) -> 4.5873606 | AG11: =AG13/AG12 -> 4.1635688 | AH11: =AH13/AH12 -> 4
B12: =G5 -> 1 | C12: =B12&" - "&F12 -> 1 - Workdays in Month / Year | F12: Workdays in Month / Year | G12: =_xlfn.XLOOKUP($C12,'Site Level Financials - ''23 ''24'!$C$2:$C$1577,'Site Level Financials - ''23 ''24'!S$2:S$1577) -> 23 | H12: =_xlfn.XLOOKUP($C12,'Site Level Financials - ''23 ''24'!$C$2:$C$1577,'Site Level Financials - ''23 ''24'!T$2:T$1577) -> 22 | I12: =_xlfn.XLOOKUP($C12,'Site Level Financials - ''23 ''24'!$C$2:$C$1577,'Site Level Financials - ''23 ''24'!U$2:U$1577) -> 22 | J12: =_xlfn.XLOOKUP($C12,'Site Level Financials - ''23 ''24'!$C$2:$C$1577,'Site Level Financials - ''23 ''24'!V$2:V$1577) -> 22 | K12: =_xlfn.XLOOKUP($C12,'Site Level Financials - ''23 ''24'!$C$2:$C$1577,'Site Level Financials - ''23 ''24'!W$2:W$1577) -> 24 | L12: =_xlfn.XLOOKUP($C12,'Site Level Financials - ''23 ''24'!$C$2:$C$1577,'Site Level Financials - ''23 ''24'!X$2:X$1577) -> 21 | M12: =_xlfn.XLOOKUP($C12,'Site Level Financials - ''23 ''24'!$C$2:$C$1577,'Site Level Financials - ''23 ''24'!Y$2:Y$1577) -> 23 | N12: =_xlfn.XLOOKUP($C12,'Site Level Financials - ''23 ''24'!$C$2:$C$1577,'Site Level Financials - ''23 ''24'!Z$2:Z$1577) -> 23 | ... R12: =_xlfn.XLOOKUP($C12,'Site Level Financials - ''23 ''24'!$C$2:$C$1577,'Site Level Financials - ''23 ''24'!AD$2:AD$1577) -> 22 | S12: =NETWORKDAYS(R9,S9) -> 23 | T12: =NETWORKDAYS(S9,T9) -> 22 | U12: =NETWORKDAYS(T9,U9) -> 22 | V12: =NETWORKDAYS(U9,V9) -> 22 | W12: =NETWORKDAYS(V9,W9) -> 24 | X12: =NETWORKDAYS(W9,X9) -> 21 | Y12: =NETWORKDAYS(X9,Y9) -> 23 | Z12: =NETWORKDAYS(Y9,Z9) -> 23 | ... AD12: =NETWORKDAYS(AC9,AD9) -> 22 | AF12: =_xlfn.XLOOKUP($C12,'Site Level Financials - ''23 ''24'!$C$2:$C$1577,'Site Level Financials - ''23 ''24'!$AF$2:$AF$1577) -> 269 | AG12: =SUM(G12:R12) -> 269 | AH12: =SUM(S12:AD12) -> 269
B13: =G5 -> 1 | C13: =B13&" - "&F13 -> 1 - Total Vet Days | F13: Total Vet Days | G13: =_xlfn.XLOOKUP($C13,'Site Level Financials - ''23 ''24'!$C$2:$C$1577,'Site Level Financials - ''23 ''24'!S$2:S$1577) -> 92 | H13: =_xlfn.XLOOKUP($C13,'Site Level Financials - ''23 ''24'!$C$2:$C$1577,'Site Level Financials - ''23 ''24'!T$2:T$1577) -> 88 | I13: =_xlfn.XLOOKUP($C13,'Site Level Financials - ''23 ''24'!$C$2:$C$1577,'Site Level Financials - ''23 ''24'!U$2:U$1577) -> 88 | J13: =_xlfn.XLOOKUP($C13,'Site Level Financials - ''23 ''24'!$C$2:$C$1577,'Site Level Financials - ''23 ''24'!V$2:V$1577) -> 66 | K13: =_xlfn.XLOOKUP($C13,'Site Level Financials - ''23 ''24'!$C$2:$C$1577,'Site Level Financials - ''23 ''24'!W$2:W$1577) -> 72 | L13: =_xlfn.XLOOKUP($C13,'Site Level Financials - ''23 ''24'!$C$2:$C$1577,'Site Level Financials - ''23 ''24'!X$2:X$1577) -> 84 | M13: =_xlfn.XLOOKUP($C13,'Site Level Financials - ''23 ''24'!$C$2:$C$1577,'Site Level Financials - ''23 ''24'!Y$2:Y$1577) -> 92 | N13: =_xlfn.XLOOKUP($C13,'Site Level Financials - ''23 ''24'!$C$2:$C$1577,'Site Level Financials - ''23 ''24'!Z$2:Z$1577) -> 115 | ... R13: =_xlfn.XLOOKUP($C13,'Site Level Financials - ''23 ''24'!$C$2:$C$1577,'Site Level Financials - ''23 ''24'!AD$2:AD$1577) -> 88 | S13: =S11*S12 -> 92 | T13: =T11*T12 -> 88 | U13: =U11*U12 -> 88 | V13: =V11*V12 -> 88 | W13: =W11*W12 -> 96 | X13: =X11*X12 -> 84 | Y13: =Y11*Y12 -> 92 | Z13: =Z11*Z12 -> 92 | ... AD13: =AD11*AD12 -> 88 | AF13: =_xlfn.XLOOKUP($C13,'Site Level Financials - ''23 ''24'!$C$2:$C$1577,'Site Level Financials - ''23 ''24'!$AF$2:$AF$1577) -> 1234 | AG13: =SUM(G13:R13) -> 1120 | AH13: =SUM(S13:AD13) -> 1076
